Workbook

Sheet Unfiltered Data
A1: Verse Ref | B1: Phys Loc 1 | C1: Phys Loc 2 | D1: Autograph | E1: Apograph | F1: Exclusion Grounds | G1: Corrector Followed | H1: Apograph Corrected | I1: Detail | J1: Basic Type | K1: Phrase Length | L1: Words Length | M1: Letters Length | N1: Speech Part Add/Omitted | O1: Visual Cues | P1: Cue Regions | Q1: Cue Length | R1: Duplicate Material | S1: AO Word Frequency | T1: SUB Frequency Difference | U1: SUB_Aut_Freq | V1: SUB_Apog_Freq | W1: Harmonization - Context | X1: Parallel Present | Y1: Harmonization - Parallel | Z1: Singularity | AA1: Secondary | AB1: Minutiae | AC1: Orthographic - General | AD1: Mere Minutiae | AE1: Nonsense | AF1: Review | AG1: TR_Reading
A2: Matt.1.1 | D2: [lac] | E2: βιβλος | F2: Other | I2: Matt 1:1 - 1:19 are entirely missing in Bezae today | U2: =IF(ISNUMBER(T2),VALUE(MID(_xlfn.FORMULATEXT(T2),SEARCH("-",_xlfn.FORMULATEXT(T2))+1,LEN(_xlfn.FORMULATEXT(T2))-SEARCH("-",_xlfn.FORMULATEXT(T2)))), "") | V2: =IF(ISNUMBER(T2), VALUE(MID(_xlfn.FORMULATEXT(T2), 2, SEARCH("-", _xlfn.FORMULATEXT(T2)) - 2)), "") | AF2: Yes
A3: Matt.1.2 | D3: [lac] | E3: αβρααμ | F3: Other | U3: =IF(ISNUMBER(T3),VALUE(MID(_xlfn.FORMULATEXT(T3),SEARCH("-",_xlfn.FORMULATEXT(T3))+1,LEN(_xlfn.FORMULATEXT(T3))-SEARCH("-",_xlfn.FORMULATEXT(T3)))), "") | V3: =IF(ISNUMBER(T3), VALUE(MID(_xlfn.FORMULATEXT(T3), 2, SEARCH("-", _xlfn.FORMULATEXT(T3)) - 2)), "")
A4: Matt.1.3 | D4: [lac] | E4: ιουδας | F4: Other | U4: =IF(ISNUMBER(T4),VALUE(MID(_xlfn.FORMULATEXT(T4),SEARCH("-",_xlfn.FORMULATEXT(T4))+1,LEN(_xlfn.FORMULATEXT(T4))-SEARCH("-",_xlfn.FORMULATEXT(T4)))), "") | V4: =IF(ISNUMBER(T4), VALUE(MID(_xlfn.FORMULATEXT(T4), 2, SEARCH("-", _xlfn.FORMULATEXT(T4)) - 2)), "")
A5: Matt.1.4 | D5: [lac] | E5: αραμ | F5: Other | U5: =IF(ISNUMBER(T5),VALUE(MID(_xlfn.FORMULATEXT(T5),SEARCH("-",_xlfn.FORMULATEXT(T5))+1,LEN(_xlfn.FORMULATEXT(T5))-SEARCH("-",_xlfn.FORMULATEXT(T5)))), "") | V5: =IF(ISNUMBER(T5), VALUE(MID(_xlfn.FORMULATEXT(T5), 2, SEARCH("-", _xlfn.FORMULATEXT(T5)) - 2)), "")
A6: Matt.1.5 | D6: [lac] | E6: σαλμων | F6: Other | U6: =IF(ISNUMBER(T6),VALUE(MID(_xlfn.FORMULATEXT(T6),SEARCH("-",_xlfn.FORMULATEXT(T6))+1,LEN(_xlfn.FORMULATEXT(T6))-SEARCH("-",_xlfn.FORMULATEXT(T6)))), "") | V6: =IF(ISNUMBER(T6), VALUE(MID(_xlfn.FORMULATEXT(T6), 2, SEARCH("-", _xlfn.FORMULATEXT(T6)) - 2)), "")
A7: Matt.1.6 | D7: [lac] | E7: ιεσσαι | F7: Other | U7: =IF(ISNUMBER(T7),VALUE(MID(_xlfn.FORMULATEXT(T7),SEARCH("-",_xlfn.FORMULATEXT(T7))+1,LEN(_xlfn.FORMULATEXT(T7))-SEARCH("-",_xlfn.FORMULATEXT(T7)))), "") | V7: =IF(ISNUMBER(T7), VALUE(MID(_xlfn.FORMULATEXT(T7), 2, SEARCH("-", _xlfn.FORMULATEXT(T7)) - 2)), "")
A8: Matt.1.7 | D8: [lac] | E8: σολομων | F8: Other | U8: =IF(ISNUMBER(T8),VALUE(MID(_xlfn.FORMULATEXT(T8),SEARCH("-",_xlfn.FORMULATEXT(T8))+1,LEN(_xlfn.FORMULATEXT(T8))-SEARCH("-",_xlfn.FORMULATEXT(T8)))), "") | V8: =IF(ISNUMBER(T8), VALUE(MID(_xlfn.FORMULATEXT(T8), 2, SEARCH("-", _xlfn.FORMULATEXT(T8)) - 2)), "")
A9: Matt.1.8 | D9: [lac] | E9: ασα | F9: Other | U9: =IF(ISNUMBER(T9),VALUE(MID(_xlfn.FORMULATEXT(T9),SEARCH("-",_xlfn.FORMULATEXT(T9))+1,LEN(_xlfn.FORMULATEXT(T9))-SEARCH("-",_xlfn.FORMULATEXT(T9)))), "") | V9: =IF(ISNUMBER(T9), VALUE(MID(_xlfn.FORMULATEXT(T9), 2, SEARCH("-", _xlfn.FORMULATEXT(T9)) - 2)), "")
A10: Matt.1.9 | D10: [lac] | E10: οζιας | F10: Other | U10: =IF(ISNUMBER(T10),VALUE(MID(_xlfn.FORMULATEXT(T10),SEARCH("-",_xlfn.FORMULATEXT(T10))+1,LEN(_xlfn.FORMULATEXT(T10))-SEARCH("-",_xlfn.FORMULATEXT(T10)))), "") | V10: =IF(ISNUMBER(T10), VALUE(MID(_xlfn.FORMULATEXT(T10), 2, SEARCH("-", _xlfn.FORMULATEXT(T10)) - 2)), "")
A11: Matt.1.10 | D11: [lac] | E11: εζεκιας | F11: Other | U11: =IF(ISNUMBER(T11),VALUE(MID(_xlfn.FORMULATEXT(T11),SEARCH("-",_xlfn.FORMULATEXT(T11))+1,LEN(_xlfn.FORMULATEXT(T11))-SEARCH("-",_xlfn.FORMULATEXT(T11)))), "") | V11: =IF(ISNUMBER(T11), VALUE(MID(_xlfn.FORMULATEXT(T11), 2, SEARCH("-", _xlfn.FORMULATEXT(T11)) - 2)), "")
A12: Matt.1.11 | D12: [lac] | E12: ιωσιας | F12: Other | U12: =IF(ISNUMBER(T12),VALUE(MID(_xlfn.FORMULATEXT(T12),SEARCH("-",_xlfn.FORMULATEXT(T12))+1,LEN(_xlfn.FORMULATEXT(T12))-SEARCH("-",_xlfn.FORMULATEXT(T12)))), "") | V12: =IF(ISNUMBER(T12), VALUE(MID(_xlfn.FORMULATEXT(T12), 2, SEARCH("-", _xlfn.FORMULATEXT(T12)) - 2)), "")
A13: Matt.1.12 | D13: [lac] | E13: μετα | F13: Other | U13: =IF(ISNUMBER(T13),VALUE(MID(_xlfn.FORMULATEXT(T13),SEARCH("-",_xlfn.FORMULATEXT(T13))+1,LEN(_xlfn.FORMULATEXT(T13))-SEARCH("-",_xlfn.FORMULATEXT(T13)))), "") | V13: =IF(ISNUMBER(T13), VALUE(MID(_xlfn.FORMULATEXT(T13), 2, SEARCH("-", _xlfn.FORMULATEXT(T13)) - 2)), "")
A14: Matt.1.13 | D14: [lac] | E14: ζοροβαβελ | F14: Other | U14: =IF(ISNUMBER(T14),VALUE(MID(_xlfn.FORMULATEXT(T14),SEARCH("-",_xlfn.FORMULATEXT(T14))+1,LEN(_xlfn.FORMULATEXT(T14))-SEARCH("-",_xlfn.FORMULATEXT(T14)))), "") | V14: =IF(ISNUMBER(T14), VALUE(MID(_xlfn.FORMULATEXT(T14), 2, SEARCH("-", _xlfn.FORMULATEXT(T14)) - 2)), "")
... A20: Matt.1.19 | D20: [lac] | E20: ιωσηφ | F20: Other | U20: =IF(ISNUMBER(T20),VALUE(MID(_xlfn.FORMULATEXT(T20),SEARCH("-",_xlfn.FORMULATEXT(T20))+1,LEN(_xlfn.FORMULATEXT(T20))-SEARCH("-",_xlfn.FORMULATEXT(T20)))), "") | V20: =IF(ISNUMBER(T20), VALUE(MID(_xlfn.FORMULATEXT(T20), 2, SEARCH("-", _xlfn.FORMULATEXT(T20)) - 2)), "")
A21: Matt.1.23 | D21: τεξετε υιον | E21: τεξεται υιον | J21: Substitution - Form | U21: =IF(ISNUMBER(T21),VALUE(MID(_xlfn.FORMULATEXT(T21),SEARCH("-",_xlfn.FORMULATEXT(T21))+1,LEN(_xlfn.FORMULATEXT(T21))-SEARCH("-",_xlfn.FORMULATEXT(T21)))), "") | V21: =IF(ISNUMBER(T21), VALUE(MID(_xlfn.FORMULATEXT(T21), 2, SEARCH("-", _xlfn.FORMULATEXT(T21)) - 2)), "") | AC21: ε-αι | AD21: Yes
A22: Matt.1.23 | D22: ενμανουηλ | E22: ενμαννουηλ | J22: Substitution - Word | T22: NA | U22: =IF(ISNUMBER(T22),VALUE(MID(_xlfn.FORMULATEXT(T22),SEARCH("-",_xlfn.FORMULATEXT(T22))+1,LEN(_xlfn.FORMULATEXT(T22))-SEARCH("-",_xlfn.FORMULATEXT(T22)))), "") | V22: =IF(ISNUMBER(T22), VALUE(MID(_xlfn.FORMULATEXT(T22), 2, SEARCH("-", _xlfn.FORMULATEXT(T22)) - 2)), "") | AB22: Name Spelling | AC22: SimGem | AD22: Yes
A23: Matt.1.25 | D23: υιον αυτης τον πρωτοτοκον | E23: υιον αυτης τον πρωτοτοκον | G23: No | U23: =IF(ISNUMBER(T23),VALUE(MID(_xlfn.FORMULATEXT(T23),SEARCH("-",_xlfn.FORMULATEXT(T23))+1,LEN(_xlfn.FORMULATEXT(T23))-SEARCH("-",_xlfn.FORMULATEXT(T23)))), "") | V23: =IF(ISNUMBER(T23), VALUE(MID(_xlfn.FORMULATEXT(T23), 2, SEARCH("-", _xlfn.FORMULATEXT(T23)) - 2)), "")
A24: Matt.1.25 | D24: εκαλεσεν το ονομα | E24: ελαλησεν το ονομα | I24: autograph matches pattern in 1:21,23 (και καλεσεις το ονομα αυτου); apograph disharmonizes | J24: Substitution - Word | T24: =196-93 -> 103 | U24: =IF(ISNUMBER(T24),VALUE(MID(_xlfn.FORMULATEXT(T24),SEARCH("-",_xlfn.FORMULATEXT(T24))+1,LEN(_xlfn.FORMULATEXT(T24))-SEARCH("-",_xlfn.FORMULATEXT(T24)))), "") -> 93 | V24: =IF(ISNUMBER(T24), VALUE(MID(_xlfn.FORMULATEXT(T24), 2, SEARCH("-", _xlfn.FORMULATEXT(T24)) - 2)), "") -> 196 | W24: Disharmonizing | AG24: No
A25: Matt.2.3 | D25: εταραχθη κα ιεροσολυμα | E25: εταραχθη και ιεροσολυμα | G25: Yes | I25: freq = και - αν (he came) | J25: Substitution - Both | T25: =5676-0 -> 5676 | U25: =IF(ISNUMBER(T25),VALUE(MID(_xlfn.FORMULATEXT(T25),SEARCH("-",_xlfn.FORMULATEXT(T25))+1,LEN(_xlfn.FORMULATEXT(T25))-SEARCH("-",_xlfn.FORMULATEXT(T25)))), "") -> 0 | V25: =IF(ISNUMBER(T25), VALUE(MID(_xlfn.FORMULATEXT(T25), 2, SEARCH("-", _xlfn.FORMULATEXT(T25)) - 2)), "") -> 5676 | AE25: Removed - contextual
A26: Matt.2.6 | D26: ιουδα εξ ου γαρ | E26: ιουδα εκ ου γαρ | F26: Autograph unclear | G26: Yes | J26: Substitution - Form | U26: =IF(ISNUMBER(T26),VALUE(MID(_xlfn.FORMULATEXT(T26),SEARCH("-",_xlfn.FORMULATEXT(T26))+1,LEN(_xlfn.FORMULATEXT(T26))-SEARCH("-",_xlfn.FORMULATEXT(T26)))), "") | V26: =IF(ISNUMBER(T26), VALUE(MID(_xlfn.FORMULATEXT(T26), 2, SEARCH("-", _xlfn.FORMULATEXT(T26)) - 2)), "") | AB26: AltForm | AD26: Yes
A27: Matt.2.8 | D27: πορευθεντες εξετασαται ακρειβως περι | E27: πορευθεντες ακριβως εξετασαται περι | I27: 1.0.1 transposition | J27: Transposition | U27: =IF(ISNUMBER(T27),VALUE(MID(_xlfn.FORMULATEXT(T27),SEARCH("-",_xlfn.FORMULATEXT(T27))+1,LEN(_xlfn.FORMULATEXT(T27))-SEARCH("-",_xlfn.FORMULATEXT(T27)))), "") | V27: =IF(ISNUMBER(T27), VALUE(MID(_xlfn.FORMULATEXT(T27), 2, SEARCH("-", _xlfn.FORMULATEXT(T27)) - 2)), "") | AG27: Yes
A28: Matt.2.8 | D28: πορευθεντες εξετασαται ακρειβως περι | E28: πορευθεντες ακριβως εξετασαται περι | J28: Substitution - Word | T28: NA | U28: =IF(ISNUMBER(T28),VALUE(MID(_xlfn.FORMULATEXT(T28),SEARCH("-",_xlfn.FORMULATEXT(T28))+1,LEN(_xlfn.FORMULATEXT(T28))-SEARCH("-",_xlfn.FORMULATEXT(T28)))), "") | V28: =IF(ISNUMBER(T28), VALUE(MID(_xlfn.FORMULATEXT(T28), 2, SEARCH("-", _xlfn.FORMULATEXT(T28)) - 2)), "") | AC28: ει-ι | AD28: Yes | AE28: Removed - strict
A29: Matt.2.8 | D29: ευρητε επαγγειλαται | E29: ευρητε απαγγειλαται | G29: Yes | J29: Substitution - Word | T29: =40-2 -> 38 | U29: =IF(ISNUMBER(T29),VALUE(MID(_xlfn.FORMULATEXT(T29),SEARCH("-",_xlfn.FORMULATEXT(T29))+1,LEN(_xlfn.FORMULATEXT(T29))-SEARCH("-",_xlfn.FORMULATEXT(T29)))), "") -> 2 | V29: =IF(ISNUMBER(T29), VALUE(MID(_xlfn.FORMULATEXT(T29), 2, SEARCH("-", _xlfn.FORMULATEXT(T29)) - 2)), "") -> 40
A30: Matt.2.9 | D30: οι δε ακουσαν του βασιλεως | E30: οι δε ακουσαντες του βασιλεως | G30: Yes | J30: Substitution - Form | U30: =IF(ISNUMBER(T30),VALUE(MID(_xlfn.FORMULATEXT(T30),SEARCH("-",_xlfn.FORMULATEXT(T30))+1,LEN(_xlfn.FORMULATEXT(T30))-SEARCH("-",_xlfn.FORMULATEXT(T30)))), "") | V30: =IF(ISNUMBER(T30), VALUE(MID(_xlfn.FORMULATEXT(T30), 2, SEARCH("-", _xlfn.FORMULATEXT(T30)) - 2)), "")
A31: Matt.2.11 | D31: οικειαν | E31: οικιαν | J31: Substitution - Word | T31: =84-0 -> 84 | U31: =IF(ISNUMBER(T31),VALUE(MID(_xlfn.FORMULATEXT(T31),SEARCH("-",_xlfn.FORMULATEXT(T31))+1,LEN(_xlfn.FORMULATEXT(T31))-SEARCH("-",_xlfn.FORMULATEXT(T31)))), "") -> 0 | V31: =IF(ISNUMBER(T31), VALUE(MID(_xlfn.FORMULATEXT(T31), 2, SEARCH("-", _xlfn.FORMULATEXT(T31)) - 2)), "") -> 84 | AC31: ει-ι | AD31: Yes
A32: Matt.2.11 | D32: ζμυρναν | E32: σμυρναν | J32: Substitution - Form | U32: =IF(ISNUMBER(T32),VALUE(MID(_xlfn.FORMULATEXT(T32),SEARCH("-",_xlfn.FORMULATEXT(T32))+1,LEN(_xlfn.FORMULATEXT(T32))-SEARCH("-",_xlfn.FORMULATEXT(T32)))), "") | V32: =IF(ISNUMBER(T32), VALUE(MID(_xlfn.FORMULATEXT(T32), 2, SEARCH("-", _xlfn.FORMULATEXT(T32)) - 2)), "") | AG32: Yes
A33: Matt.2.13 | D33: ειδου | E33: ιδου | J33: Substitution - Form | U33: =IF(ISNUMBER(T33),VALUE(MID(_xlfn.FORMULATEXT(T33),SEARCH("-",_xlfn.FORMULATEXT(T33))+1,LEN(_xlfn.FORMULATEXT(T33))-SEARCH("-",_xlfn.FORMULATEXT(T33)))), "") | V33: =IF(ISNUMBER(T33), VALUE(MID(_xlfn.FORMULATEXT(T33), 2, SEARCH("-", _xlfn.FORMULATEXT(T33)) - 2)), "") | AC33: ει-ι | AD33: Yes
A34: Matt.2.13 | D34: παραλαβε τον παιδα | E34: παρελαβε τον παιδα | J34: Substitution - Form | U34: =IF(ISNUMBER(T34),VALUE(MID(_xlfn.FORMULATEXT(T34),SEARCH("-",_xlfn.FORMULATEXT(T34))+1,LEN(_xlfn.FORMULATEXT(T34))-SEARCH("-",_xlfn.FORMULATEXT(T34)))), "") | V34: =IF(ISNUMBER(T34), VALUE(MID(_xlfn.FORMULATEXT(T34), 2, SEARCH("-", _xlfn.FORMULATEXT(T34)) - 2)), "") | AG34: No
A35: Matt.2.14 | D35: ο δε διεγερθεις | E35: ο δε εγερθεις | I35: apograph matches verb in 2:13,20 (εγερθεις παραλαβε τον παιδα); apograph harmonizes | J35: Substitution - Word | T35: =99-4 -> 95 | U35: =IF(ISNUMBER(T35),VALUE(MID(_xlfn.FORMULATEXT(T35),SEARCH("-",_xlfn.FORMULATEXT(T35))+1,LEN(_xlfn.FORMULATEXT(T35))-SEARCH("-",_xlfn.FORMULATEXT(T35)))), "") -> 4 | V35: =IF(ISNUMBER(T35), VALUE(MID(_xlfn.FORMULATEXT(T35), 2, SEARCH("-", _xlfn.FORMULATEXT(T35)) - 2)), "") -> 99 | W35: Harmonizing | AG35: Yes
A36: Matt.2.16 | D36: βεθλεαιμ | E36: βηθλεεμ | G36: Yes | J36: Substitution - Word | T36: ΝΑ | U36: =IF(ISNUMBER(T36),VALUE(MID(_xlfn.FORMULATEXT(T36),SEARCH("-",_xlfn.FORMULATEXT(T36))+1,LEN(_xlfn.FORMULATEXT(T36))-SEARCH("-",_xlfn.FORMULATEXT(T36)))), "") | V36: =IF(ISNUMBER(T36), VALUE(MID(_xlfn.FORMULATEXT(T36), 2, SEARCH("-", _xlfn.FORMULATEXT(T36)) - 2)), "") | AB36: Name Spelling | AC36: ε-η; αι-ε | AD36: Yes
A37: Matt.2.16 | D37: απο διετειας και κατω | E37: απο διετους και κατω | G37: Yes | J37: Substitution - Word | T37: =1-2 -> -1 | U37: =IF(ISNUMBER(T37),VALUE(MID(_xlfn.FORMULATEXT(T37),SEARCH("-",_xlfn.FORMULATEXT(T37))+1,LEN(_xlfn.FORMULATEXT(T37))-SEARCH("-",_xlfn.FORMULATEXT(T37)))), "") -> 2 | V37: =IF(ISNUMBER(T37), VALUE(MID(_xlfn.FORMULATEXT(T37), 2, SEARCH("-", _xlfn.FORMULATEXT(T37)) - 2)), "") -> 1
A38: Matt.2.17 | D38: δια ηρεμιου | E38: δια ιερεμιου | G38: Yes, but still an error | I38: Corrected Bezae = δια ιηρεμιου | J38: Substitution - Word | T38: ΝΑ | U38: =IF(ISNUMBER(T38),VALUE(MID(_xlfn.FORMULATEXT(T38),SEARCH("-",_xlfn.FORMULATEXT(T38))+1,LEN(_xlfn.FORMULATEXT(T38))-SEARCH("-",_xlfn.FORMULATEXT(T38)))), "") | V38: =IF(ISNUMBER(T38), VALUE(MID(_xlfn.FORMULATEXT(T38), 2, SEARCH("-", _xlfn.FORMULATEXT(T38)) - 2)), "") | AB38: Name Spelling | AD38: Yes
A39: Matt.2.18 | D39: ουκ εισιν (19) τελευτησαντος | E39: ουκ εισι (19) τελευτησαντος | J39: Substitution - Form | U39: =IF(ISNUMBER(T39),VALUE(MID(_xlfn.FORMULATEXT(T39),SEARCH("-",_xlfn.FORMULATEXT(T39))+1,LEN(_xlfn.FORMULATEXT(T39))-SEARCH("-",_xlfn.FORMULATEXT(T39)))), "") | V39: =IF(ISNUMBER(T39), VALUE(MID(_xlfn.FORMULATEXT(T39), 2, SEARCH("-", _xlfn.FORMULATEXT(T39)) - 2)), "") | AB39: Movable ν | AD39: Yes
A40: Matt.2.20 | D40: γαρ οι ζητουντες | E40: γαρ ζητουντες | H40: Yes | J40: Omission | L40: 1 | M40: 2 | N40: Article | O40: NA | S40: 11843 | U40: =IF(ISNUMBER(T40),VALUE(MID(_xlfn.FORMULATEXT(T40),SEARCH("-",_xlfn.FORMULATEXT(T40))+1,LEN(_xlfn.FORMULATEXT(T40))-SEARCH("-",_xlfn.FORMULATEXT(T40)))), "") | V40: =IF(ISNUMBER(T40), VALUE(MID(_xlfn.FORMULATEXT(T40), 2, SEARCH("-", _xlfn.FORMULATEXT(T40)) - 2)), "") | AG40: No
A41: Matt.2.21 | D41: εις την ισραηλ | E41: εις γην ισραηλ | G41: Yes | I41: apograph matches pattern from 2:20 (πορευου εις γην ισραηλ); apograph harmonizes | J41: Substitution - Word | T41: =133-11843 -> -11710 | U41: =IF(ISNUMBER(T41),VALUE(MID(_xlfn.FORMULATEXT(T41),SEARCH("-",_xlfn.FORMULATEXT(T41))+1,LEN(_xlfn.FORMULATEXT(T41))-SEARCH("-",_xlfn.FORMULATEXT(T41)))), "") -> 11843 | V41: =IF(ISNUMBER(T41), VALUE(MID(_xlfn.FORMULATEXT(T41), 2, SEARCH("-", _xlfn.FORMULATEXT(T41)) - 2)), "") -> 133 | W41: Harmonizing
A42: Matt.2.22 | D42: αρχιλαος | E42: αρχελαος | J42: Substitution - Word | T42: ΝΑ | U42: =IF(ISNUMBER(T42),VALUE(MID(_xlfn.FORMULATEXT(T42),SEARCH("-",_xlfn.FORMULATEXT(T42))+1,LEN(_xlfn.FORMULATEXT(T42))-SEARCH("-",_xlfn.FORMULATEXT(T42)))), "") | V42: =IF(ISNUMBER(T42), VALUE(MID(_xlfn.FORMULATEXT(T42), 2, SEARCH("-", _xlfn.FORMULATEXT(T42)) - 2)), "") | AB42: Name Spelling | AD42: Yes
A43: Matt.2.22 | D43: ηρωδου του πατρος αυτου εφηθη εκει | E43: ηρωδους του πατρος αυτου εφοβηθη εκει | J43: Substitution - Form | U43: =IF(ISNUMBER(T43),VALUE(MID(_xlfn.FORMULATEXT(T43),SEARCH("-",_xlfn.FORMULATEXT(T43))+1,LEN(_xlfn.FORMULATEXT(T43))-SEARCH("-",_xlfn.FORMULATEXT(T43)))), "") | V43: =IF(ISNUMBER(T43), VALUE(MID(_xlfn.FORMULATEXT(T43), 2, SEARCH("-", _xlfn.FORMULATEXT(T43)) - 2)), "") | AB43: Name Spelling | AD43: Yes
A44: Matt.2.22 | D44: ηρωδου του πατρος αυτου εφηθη εκει | E44: ηρωδους του πατρος αυτου εφοβηθη εκει | G44: Yes | J44: Substitution - Word | T44: ΝΑ | U44: =IF(ISNUMBER(T44),VALUE(MID(_xlfn.FORMULATEXT(T44),SEARCH("-",_xlfn.FORMULATEXT(T44))+1,LEN(_xlfn.FORMULATEXT(T44))-SEARCH("-",_xlfn.FORMULATEXT(T44)))), "") | V44: =IF(ISNUMBER(T44), VALUE(MID(_xlfn.FORMULATEXT(T44), 2, SEARCH("-", _xlfn.FORMULATEXT(T44)) - 2)), "") | AE44: Removed - strict
A45: Matt.3.1 | D45: εν ταις ημεραις | E45: εν δε ταις ημεραις | J45: Addition | L45: 1 | M45: 2 | N45: Conjunction | O45: NA | S45: 1966 | U45: =IF(ISNUMBER(T45),VALUE(MID(_xlfn.FORMULATEXT(T45),SEARCH("-",_xlfn.FORMULATEXT(T45))+1,LEN(_xlfn.FORMULATEXT(T45))-SEARCH("-",_xlfn.FORMULATEXT(T45)))), "") | V45: =IF(ISNUMBER(T45), VALUE(MID(_xlfn.FORMULATEXT(T45), 2, SEARCH("-", _xlfn.FORMULATEXT(T45)) - 2)), "") | AG45: Yes
...

Sheet Gen-filters
A1: Verse Ref | B1: Autograph | C1: Apograph | D1: Exclusion Grounds | E1: Corrector Followed | F1: Apograph Corrected | G1: Basic Type | H1: Phrase Length | I1: Words Length | J1: Letters Length | K1: Speech Part Add/Omitted | L1: Visual Cues | M1: Cue Regions | N1: Cue Length | O1: Duplicate Material | P1: AO Word Frequency | Q1: SUB Frequency Difference | R1: SUB_Aut_Freq | S1: SUB_Apog_Freq | T1: Harmonization - Context | U1: Parallel Present | V1: Harmonization - Parallel | W1: Singularity | X1: Secondary | Y1: Minutiae | Z1: Orthographic - General | AA1: Mere Minutiae | AB1: Nonsense | AC1: Review | AD1: TR_Reading
A2: Matt.1.25 | B2: εκαλεσεν το ονομα | C2: ελαλησεν το ονομα | G2: Substitution - Word | Q2: 103 | R2: 93 | S2: 196 | T2: Disharmonizing | AD2: No
A3: Matt.2.8 | B3: πορευθεντες εξετασαται ακρειβως περι | C3: πορευθεντες ακριβως εξετασαται περι | G3: Transposition | AD3: Yes
A4: Matt.2.11 | B4: ζμυρναν | C4: σμυρναν | G4: Substitution - Form | AD4: Yes
A5: Matt.2.13 | B5: παραλαβε τον παιδα | C5: παρελαβε τον παιδα | G5: Substitution - Form | AD5: No
A6: Matt.2.14 | B6: ο δε διεγερθεις | C6: ο δε εγερθεις | G6: Substitution - Word | Q6: 95 | R6: 4 | S6: 99 | T6: Harmonizing | AD6: Yes
A7: Matt.2.20 | B7: γαρ οι ζητουντες | C7: γαρ ζητουντες | F7: Yes | G7: Omission | I7: 1 | J7: 2 | K7: Article | L7: NA | P7: 11843 | AD7: No
A8: Matt.3.1 | B8: εν ταις ημεραις | C8: εν δε ταις ημεραις | G8: Addition | I8: 1 | J8: 2 | K8: Conjunction | L8: NA | P8: 1966 | AD8: Yes
A9: Matt.3.15 | B9: εστιν ημιν πληρωσαι | C9: εστιν ημας πληρωσαι | F9: Yes | G9: Substitution - Form | AD9: No
A10: Matt.3.16 | B10: ως περιστεραν και ερχομενον εις αυτον (17) και ιδου | C10: ωσπερ ιστεραν (17) και ιδου | G10: Omission | I10: 4 | J10: 20 | L10: Present | M10: BD | N10: 3 | P10: 507 | AD10: No
A11: Matt.3.17 | B11: ει ο υιος μου | C11: ει υιος μου | G11: Omission | I11: 1 | J11: 1 | K11: Article | L11: NA | P11: 11843 | AD11: Yes
A12: Matt.4.1 | B12: υπο του διαβολου | C12: υπο διαβολου | G12: Omission | I12: 1 | J12: 3 | K12: Article | L12: Absent | P12: 11843 | AD12: No
A13: Matt.4.3 | B13: ειπεν αυτω ει υιος | C13: ειπεν ει υιος | G13: Omission | I13: 1 | J13: 4 | K13: Pronoun | L13: Absent | P13: 4240 | T13: Harmonizing | AD13: Yes
A14: Matt.4.22 | B14: πατερα αυτων ηκολουθησαν αυτω (23) και περιηγεν | C14: πατερα αυτων (23) και περιηγεν | G14: Omission | I14: 2 | J14: 15 | L14: Present | M14: AC | N14: 4 | P14: 83 | AD14: No
A15: Matt.4.24 | B15: δαιμονιζομενους και σεληνιαζομενους και παραλυτικους και παντας | C15: δαιμονιζομενους και παραλυτικους και σεληνιαζομενους και παντας | G15: Transposition | AD15: No
A16: Matt.5.12 | B16: εδιωξαν τους προφητας | C16: εδιωξαν προφητας | F16: Yes | G16: Omission | I16: 1 | J16: 4 | K16: Article | L16: Absent | P16: 11843 | AD16: No
A17: Matt.5.18 | B17: εως αν γενηται παντα | C17: εως γενηται αν παντα | G17: Transposition | I17: 1 | J17: 2 | K17: Particle | L17: NA | P17: 134 | AD17: No
A18: Matt.5.19 | B18: ος ουν λυσει | C18: ος δε ουν λυσει | E18: No | G18: Addition | I18: 1 | J18: 2 | K18: Conjunction | L18: NA | P18: 1966 | AD18: No
A19: Matt.5.23 | B19: (22) πυρος (23) εαν ουν | C19: (22) πυρος (23) επει ουν | G19: Substitution - Word | Q19: -141 | R19: 148 | S19: 7 | AD19: No
A20: Matt.5.42 | B20: σε δος και | C20: σε διδου και | G20: Substitution - Form | AD20: Yes
A21: Matt.6.4 | B21: οπως η ελεημοσυνη | C21: οπως ελεημοσυνη | G21: Omission | I21: 1 | J21: 1 | K21: Article | L21: NA | P21: 11843 | AD21: No
A22: Matt.6.5 | B22: ως οι υποκριται | C22: ως υποκριται | G22: Omission | I22: 1 | J22: 2 | K22: Article | L22: NA | P22: 11843 | T22: Disharmonizing | AD22: No
A23: Matt.6.6 | B23: πατρι σου εν τω | C23: πατρι τω εν τω | G23: Substitution - Word | Q23: 10102 | R23: 1741 | S23: 11843 | T23: Disharmonizing | AD23: No
A24: Matt.6.16 | B24: ως οι υποκρειται | C24: ωσπερ οι υποκριται | G24: Substitution - Word | Q24: -190 | R24: 207 | S24: 17 | AD24: Yes
A25: Matt.6.17 | B25: και το προσωπον | C25: και προσωπον | G25: Omission | I25: 1 | J25: 2 | K25: Article | L25: NA | P25: 11843 | AD25: No
A26: Matt.6.19 | B26: θησαυρισεται | C26: θησαυριζεται | G26: Substitution - Form | AD26: Partial
A27: Matt.9.17 | B27: παλαιους ει δε μη γε ρησσει ο οινος | C27: παλαιους ρησει ο οινος | G27: Omission | I27: 4 | J27: 8 | L27: Absent | P27: 16 | AD27: No
A28: Matt.9.30 | B28: αυτοις ιης | C28: αυτοις ο ις | G28: Addition | I28: 1 | J28: 1 | K28: Article | L28: NA | P28: 11843 | AD28: Yes
A29: Matt.9.36 | B29: ιδων δε τους οχλους | C29: ιδων δε οχλους | F29: Yes | G29: Omission | I29: 1 | J29: 4 | K29: Article | L29: Present | M29: BD:CD | N29: 3:3 | P29: 11843 | AD29: No
A30: Matt.9.37 | B30: οι δε εργαται | C30: οι εργαται | G30: Omission | I30: 1 | J30: 2 | K30: Conjunction | L30: NA | P30: 1966 | AD30: No
A31: Matt.10.2 | B31: των ιβ | C31: των δε ιβ | G31: Addition | I31: 1 | J31: 2 | K31: Conjunction | L31: NA | P31: 1966 | AD31: Yes
A32: Matt.10.8 | B32: εγειρατε | C32: εγειρετε | G32: Substitution - Form | AD32: Yes
A33: Matt.10.8 | B33: καθαρεισατε και δαιμονια εκβαλετε | C33: καθαριζετε δαιμονια εκβαλετε | G33: Substitution - Form | AD33: Yes
A34: Matt.10.8 | B34: καθαρεισατε και δαιμονια εκβαλετε | C34: καθαριζετε δαιμονια εκβαλετε | G34: Omission | I34: 1 | J34: 3 | K34: Conjunction | L34: Present | M34: AB:AC | N34: 3:3 | P34: 5676 | AD34: No
A35: Matt.10.9 | B35: χρυσον μητε αργυρον μητε χαλκον | C35: χρυσον μηδε αργυρον μηδε χαλκον | G35: Substitution - Word | Q35: 8 | R35: 20 | S35: 28 | AD35: Yes
A36: Matt.10.9 | B36: χρυσον μητε αργυρον μητε χαλκον | C36: χρυσον μηδε αργυρον μηδε χαλκον | G36: Substitution - Word | Q36: 8 | R36: 20 | S36: 28 | AD36: Yes
A37: Matt.10.16 | B37: ως αι περιστεραι | C37: ως περιστεραι | G37: Omission | I37: 1 | J37: 2 | K37: Article | L37: NA | P37: 11843 | AD37: No
A38: Matt.10.17 | B38: προσεχετε απο | C38: προσεχετε δε απο | G38: Addition | I38: 1 | J38: 2 | K38: Conjunction | L38: NA | P38: 1966 | AD38: Yes
A39: Matt.10.27 | B39: ο λεγω υμειν | C39: ο δε λεγω υμειν | G39: Addition | I39: 1 | J39: 2 | K39: Conjunction | L39: NA | P39: 1966 | AD39: No
A40: Matt.10.29 | B40: στρουθια του ασσαριου | C40: στρουθια ασσαριου | G40: Omission | I40: 1 | J40: 3 | K40: Article | L40: Present | M40: AB:AC | N40: 3:3 | P40: 11843 | AD40: Yes
...

Sheet AddOmits
A1: Verse Ref | B1: Autograph | C1: Apograph | D1: Exclusion Grounds | E1: Corrector Followed | F1: Apograph Corrected | G1: Basic Type | H1: Phrase Length | I1: Words Length | J1: Letters Length | K1: Speech Part Add/Omitted | L1: Visual Cues | M1: Cue Regions | N1: Cue Length | O1: Duplicate Material | P1: AO Word Frequency | Q1: Freq-per-10000 | R1: SUB Frequency Difference | S1: Harmonization - Context | T1: Parallel Present | U1: Harmonization - Parallel | V1: Singularity | W1: Secondary | X1: Minutiae | Y1: Orthographic - General | Z1: Mere Minutiae | AA1: Nonsense | AB1: Review
A2: Matt.2.20 | B2: γαρ οι ζητουντες | C2: γαρ ζητουντες | F2: Yes | G2: Omission | I2: 1 | J2: 2 | K2: Article | L2: NA | P2: 11843 | Q2: =IF(ISNUMBER(P2), (P2/$F$988)*10000, "") -> 1423.0954
A3: Matt.3.1 | B3: εν ταις ημεραις | C3: εν δε ταις ημεραις | G3: Addition | I3: 1 | J3: 2 | K3: Conjunction | L3: NA | P3: 1966 | Q3: =IF(ISNUMBER(P3), (P3/$F$988)*10000, "") -> 236.24129
A4: Matt.3.16 | B4: ως περιστεραν και ερχομενον εις αυτον (17) και ιδου | C4: ωσπερ ιστεραν (17) και ιδου | G4: Omission | I4: 4 | J4: 20 | L4: Present | M4: BD | N4: 3 | P4: 507 | Q4: =IF(ISNUMBER(P4), (P4/$F$988)*10000, "") -> 60.922855
A5: Matt.3.17 | B5: ει ο υιος μου | C5: ει υιος μου | G5: Omission | I5: 1 | J5: 1 | K5: Article | L5: NA | P5: 11843 | Q5: =IF(ISNUMBER(P5), (P5/$F$988)*10000, "") -> 1423.0954
A6: Matt.4.1 | B6: υπο του διαβολου | C6: υπο διαβολου | G6: Omission | I6: 1 | J6: 3 | K6: Article | L6: Absent | P6: 11843 | Q6: =IF(ISNUMBER(P6), (P6/$F$988)*10000, "") -> 1423.0954
A7: Matt.4.3 | B7: ειπεν αυτω ει υιος | C7: ειπεν ει υιος | G7: Omission | I7: 1 | J7: 4 | K7: Pronoun | L7: Absent | P7: 4240 | Q7: =IF(ISNUMBER(P7), (P7/$F$988)*10000, "") -> 509.49291 | U7: Harmonizing
A8: Matt.4.22 | B8: πατερα αυτων ηκολουθησαν αυτω (23) και περιηγεν | C8: πατερα αυτων (23) και περιηγεν | G8: Omission | I8: 2 | J8: 15 | L8: Present | M8: AC | N8: 4 | P8: 83 | Q8: =IF(ISNUMBER(P8), (P8/$F$988)*10000, "") -> 9.973564
A9: Matt.5.12 | B9: εδιωξαν τους προφητας | C9: εδιωξαν προφητας | F9: Yes | G9: Omission | I9: 1 | J9: 4 | K9: Article | L9: Absent | P9: 11843 | Q9: =IF(ISNUMBER(P9), (P9/$F$988)*10000, "") -> 1423.0954
A10: Matt.5.19 | B10: ος ουν λυσει | C10: ος δε ουν λυσει | E10: No | G10: Addition | I10: 1 | J10: 2 | K10: Conjunction | L10: NA | P10: 1966 | Q10: =IF(ISNUMBER(P10), (P10/$F$988)*10000, "") -> 236.24129
A11: Matt.6.4 | B11: οπως η ελεημοσυνη | C11: οπως ελεημοσυνη | G11: Omission | I11: 1 | J11: 1 | K11: Article | L11: NA | P11: 11843 | Q11: =IF(ISNUMBER(P11), (P11/$F$988)*10000, "") -> 1423.0954
A12: Matt.6.5 | B12: ως οι υποκριται | C12: ως υποκριται | G12: Omission | I12: 1 | J12: 2 | K12: Article | L12: NA | P12: 11843 | Q12: =IF(ISNUMBER(P12), (P12/$F$988)*10000, "") -> 1423.0954 | U12: Disharmonizing
A13: Matt.6.17 | B13: και το προσωπον | C13: και προσωπον | G13: Omission | I13: 1 | J13: 2 | K13: Article | L13: NA | P13: 11843 | Q13: =IF(ISNUMBER(P13), (P13/$F$988)*10000, "") -> 1423.0954
A14: Matt.9.17 | B14: παλαιους ει δε μη γε ρησσει ο οινος | C14: παλαιους ρησει ο οινος | G14: Omission | I14: 4 | J14: 8 | L14: Absent | P14: 16 | Q14: =IF(ISNUMBER(P14), (P14/$F$988)*10000, "") -> 1.9226148
A15: Matt.9.30 | B15: αυτοις ιης | C15: αυτοις ο ις | G15: Addition | I15: 1 | J15: 1 | K15: Article | L15: NA | P15: 11843 | Q15: =IF(ISNUMBER(P15), (P15/$F$988)*10000, "") -> 1423.0954
A16: Matt.9.36 | B16: ιδων δε τους οχλους | C16: ιδων δε οχλους | F16: Yes | G16: Omission | I16: 1 | J16: 4 | K16: Article | L16: Present | M16: BD:CD | N16: 3:3 | P16: 11843 | Q16: =IF(ISNUMBER(P16), (P16/$F$988)*10000, "") -> 1423.0954
A17: Matt.9.37 | B17: οι δε εργαται | C17: οι εργαται | G17: Omission | I17: 1 | J17: 2 | K17: Conjunction | L17: NA | P17: 1966 | Q17: =IF(ISNUMBER(P17), (P17/$F$988)*10000, "") -> 236.24129
A18: Matt.10.2 | B18: των ιβ | C18: των δε ιβ | G18: Addition | I18: 1 | J18: 2 | K18: Conjunction | L18: NA | P18: 1966 | Q18: =IF(ISNUMBER(P18), (P18/$F$988)*10000, "") -> 236.24129
A19: Matt.10.8 | B19: καθαρεισατε και δαιμονια εκβαλετε | C19: καθαριζετε δαιμονια εκβαλετε | G19: Omission | I19: 1 | J19: 3 | K19: Conjunction | L19: Present | M19: AB:AC | N19: 3:3 | P19: 5676 | Q19: =IF(ISNUMBER(P19), (P19/$F$988)*10000, "") -> 682.04758
A20: Matt.10.16 | B20: ως αι περιστεραι | C20: ως περιστεραι | G20: Omission | I20: 1 | J20: 2 | K20: Article | L20: NA | P20: 11843 | Q20: =IF(ISNUMBER(P20), (P20/$F$988)*10000, "") -> 1423.0954
A21: Matt.10.17 | B21: προσεχετε απο | C21: προσεχετε δε απο | G21: Addition | I21: 1 | J21: 2 | K21: Conjunction | L21: NA | P21: 1966 | Q21: =IF(ISNUMBER(P21), (P21/$F$988)*10000, "") -> 236.24129
A22: Matt.10.27 | B22: ο λεγω υμειν | C22: ο δε λεγω υμειν | G22: Addition | I22: 1 | J22: 2 | K22: Conjunction | L22: NA | P22: 1966 | Q22: =IF(ISNUMBER(P22), (P22/$F$988)*10000, "") -> 236.24129
A23: Matt.10.29 | B23: στρουθια του ασσαριου | C23: στρουθια ασσαριου | G23: Omission | I23: 1 | J23: 3 | K23: Article | L23: Present | M23: AB:AC | N23: 3:3 | P23: 11843 | Q23: =IF(ISNUMBER(P23), (P23/$F$988)*10000, "") -> 1423.0954
A24: Matt.10.33 | B24: οστις δ αν αρνησητε | C24: οστις δ αρνησητε | F24: Yes | G24: Omission | I24: 1 | J24: 2 | K24: Particle | L24: NA | P24: 134 | Q24: =IF(ISNUMBER(P24), (P24/$F$988)*10000, "") -> 16.101899
A25: Matt.10.35 | B25: κατα πατρος | C25: κατα του πατρος | G25: Addition | I25: 1 | J25: 3 | K25: Article | L25: Absent | P25: 11843 | Q25: =IF(ISNUMBER(P25), (P25/$F$988)*10000, "") -> 1423.0954 | U25: Harmonizing
A26: Matt.10.35 | B26: μητρος αυτης και νυμφην κατα της πενθερας αυτης (36) και εκθροι | C26: μητρος αυτης (36) και εκθροι | G26: Omission | I26: 6 | J26: 29 | L26: Present | M26: AC:BD | N26: 7:3 | P26: 4 | Q26: =IF(ISNUMBER(P26), (P26/$F$988)*10000, "") -> 0.48065369
A27: Matt.11.1 | B27: διατασσων τοις δωδεκα | C27: διατασσων δωδεκα | F27: Yes | G27: Omission | I27: 1 | J27: 4 | K27: Article | L27: Absent | P27: 11843 | Q27: =IF(ISNUMBER(P27), (P27/$F$988)*10000, "") -> 1423.0954
A28: Matt.11.4 | B28: απαγγειλατε ιωαννει | C28: απαγγειλατε τω ιωανει | G28: Addition | I28: 1 | J28: 2 | K28: Article | L28: NA | P28: 11843 | Q28: =IF(ISNUMBER(P28), (P28/$F$988)*10000, "") -> 1423.0954
A29: Matt.11.7 | B29: ηρξατο ιης | C29: ηρξατο ο ις | G29: Addition | I29: 1 | J29: 1 | K29: Article | L29: NA | P29: 11843 | Q29: =IF(ISNUMBER(P29), (P29/$F$988)*10000, "") -> 1423.0954
A30: Matt.11.16 | B30: προσφωνουντα τοις ετεροις | C30: προσφωνουντα ετεροις | G30: Omission | I30: 1 | J30: 4 | K30: Article | L30: Present | M30: BD:CD | N30: 4:4 | P30: 11843 | Q30: =IF(ISNUMBER(P30), (P30/$F$988)*10000, "") -> 1423.0954
A31: Matt.11.27 | B31: πατερα τις επιγεινωσκει ει μη | C31: πατερα επιγεινωσκει ει μη | G31: Omission | I31: 1 | J31: 3 | K31: Pronoun | L31: Absent | P31: 301 | Q31: =IF(ISNUMBER(P31), (P31/$F$988)*10000, "") -> 36.16919
A32: Matt.12.1 | B32: ηρξαντο του σταχυας τιλλειν | C32: ηρξαντο σταχυας τιλλειν | G32: Omission | I32: 1 | J32: 3 | K32: Article | L32: Absent | P32: 11843 | Q32: =IF(ISNUMBER(P32), (P32/$F$988)*10000, "") -> 1423.0954
A33: Matt.12.5 | B33: η ουκ ανεγνωτε | C33: η μεν ουκ ανεγνωτε | G33: Addition | I33: 1 | J33: 3 | K33: Particle | L33: Absent | P33: 92 | Q33: =IF(ISNUMBER(P33), (P33/$F$988)*10000, "") -> 11.055035
A34: Matt.12.6 | B34: ιερου μειζον εστιν | C34: ιερου ο μειζων εστιν | G34: Addition | I34: 1 | J34: 1 | K34: Article | L34: NA | P34: 11843 | Q34: =IF(ISNUMBER(P34), (P34/$F$988)*10000, "") -> 1423.0954
A35: Matt.12.10 | B35: ην εκει την χειρα | C35: ην την χειρα | G35: Omission | I35: 1 | J35: 4 | K35: Adverb | L35: Absent | P35: 10 | Q35: =IF(ISNUMBER(P35), (P35/$F$988)*10000, "") -> 1.2016342
A36: Matt.12.22 | B36: ωστε τον κωφον | C36: ωστε κωφον | G36: Omission | I36: 1 | J36: 3 | K36: Article | L36: Absent | P36: 11843 | Q36: =IF(ISNUMBER(P36), (P36/$F$988)*10000, "") -> 1423.0954
A37: Matt.12.23 | B37: μητι οτι ουτος | C37: μητι ουτος | G37: Omission | I37: 1 | J37: 3 | K37: Conjunction | L37: Absent | P37: 810 | Q37: =IF(ISNUMBER(P37), (P37/$F$988)*10000, "") -> 97.332372
A38: Matt.12.23 | B38: υιος δαυειδ | C38: υιος του δαβειδ | G38: Addition | I38: 1 | J38: 3 | K38: Article | L38: Absent | P38: 11843 | Q38: =IF(ISNUMBER(P38), (P38/$F$988)*10000, "") -> 1423.0954
A39: Matt.12.28 | B39: πνι θυ εγω | C39: πνευματι εγω | G39: Omission | I39: 1 | J39: 2 | K39: Noun | L39: NA | P39: 472 | Q39: =IF(ISNUMBER(P39), (P39/$F$988)*10000, "") -> 56.717135
A40: Matt.12.41 | B40: κηρυγμα ιωνα | C40: κηρυγμα του ιωνα | F40: Yes | G40: Addition | I40: 1 | J40: 3 | K40: Article | L40: Absent | P40: 11843 | Q40: =IF(ISNUMBER(P40), (P40/$F$988)*10000, "") -> 1423.0954
...

Sheet WF_AO_LM
A1: Verse Ref | B1: Autograph | C1: Apograph | D1: Exclusion Grounds | E1: Corrector Followed | F1: Apograph Corrected | G1: Basic Type | H1: Phrase Length | I1: Words Length | J1: Letters Length | K1: Speech Part Add/Omitted | L1: Visual Cues | M1: Cue Regions | N1: Cue Length | O1: Duplicate Material | P1: AO Word Frequency | Q1: Freq-per-10000 | R1: SUB Frequency Difference | S1: Harmonization - Context | T1: Parallel Present | U1: Harmonization - Parallel | V1: Singularity | W1: Secondary | X1: Minutiae | Y1: Orthographic - General | Z1: Mere Minutiae | AA1: Nonsense | AB1: Review
A2: Matt.2.20 | B2: γαρ οι ζητουντες | C2: γαρ ζητουντες | F2: Yes | G2: Omission | I2: 1 | J2: 2 | K2: Article | L2: NA | P2: 11843 | Q2: 1423.0954
A3: Matt.3.1 | B3: εν ταις ημεραις | C3: εν δε ταις ημεραις | G3: Addition | I3: 1 | J3: 2 | K3: Conjunction | L3: NA | P3: 1966 | Q3: 236.24129
A4: Matt.3.17 | B4: ει ο υιος μου | C4: ει υιος μου | G4: Omission | I4: 1 | J4: 1 | K4: Article | L4: NA | P4: 11843 | Q4: 1423.0954
A5: Matt.4.1 | B5: υπο του διαβολου | C5: υπο διαβολου | G5: Omission | I5: 1 | J5: 3 | K5: Article | L5: Absent | P5: 11843 | Q5: 1423.0954
A6: Matt.4.3 | B6: ειπεν αυτω ει υιος | C6: ειπεν ει υιος | G6: Omission | I6: 1 | J6: 4 | K6: Pronoun | L6: Absent | P6: 4240 | Q6: 509.49291 | U6: Harmonizing
A7: Matt.5.12 | B7: εδιωξαν τους προφητας | C7: εδιωξαν προφητας | F7: Yes | G7: Omission | I7: 1 | J7: 4 | K7: Article | L7: Absent | P7: 11843 | Q7: 1423.0954
A8: Matt.5.19 | B8: ος ουν λυσει | C8: ος δε ουν λυσει | E8: No | G8: Addition | I8: 1 | J8: 2 | K8: Conjunction | L8: NA | P8: 1966 | Q8: 236.24129
A9: Matt.6.4 | B9: οπως η ελεημοσυνη | C9: οπως ελεημοσυνη | G9: Omission | I9: 1 | J9: 1 | K9: Article | L9: NA | P9: 11843 | Q9: 1423.0954
A10: Matt.6.5 | B10: ως οι υποκριται | C10: ως υποκριται | G10: Omission | I10: 1 | J10: 2 | K10: Article | L10: NA | P10: 11843 | Q10: 1423.0954 | U10: Disharmonizing
A11: Matt.6.17 | B11: και το προσωπον | C11: και προσωπον | G11: Omission | I11: 1 | J11: 2 | K11: Article | L11: NA | P11: 11843 | Q11: 1423.0954
A12: Matt.9.30 | B12: αυτοις ιης | C12: αυτοις ο ις | G12: Addition | I12: 1 | J12: 1 | K12: Article | L12: NA | P12: 11843 | Q12: 1423.0954
A13: Matt.9.36 | B13: ιδων δε τους οχλους | C13: ιδων δε οχλους | F13: Yes | G13: Omission | I13: 1 | J13: 4 | K13: Article | L13: Present | M13: BD:CD | N13: 3:3 | P13: 11843 | Q13: 1423.0954
A14: Matt.9.37 | B14: οι δε εργαται | C14: οι εργαται | G14: Omission | I14: 1 | J14: 2 | K14: Conjunction | L14: NA | P14: 1966 | Q14: 236.24129
A15: Matt.10.2 | B15: των ιβ | C15: των δε ιβ | G15: Addition | I15: 1 | J15: 2 | K15: Conjunction | L15: NA | P15: 1966 | Q15: 236.24129
A16: Matt.10.8 | B16: καθαρεισατε και δαιμονια εκβαλετε | C16: καθαριζετε δαιμονια εκβαλετε | G16: Omission | I16: 1 | J16: 3 | K16: Conjunction | L16: Present | M16: AB:AC | N16: 3:3 | P16: 5676 | Q16: 682.04758
A17: Matt.10.16 | B17: ως αι περιστεραι | C17: ως περιστεραι | G17: Omission | I17: 1 | J17: 2 | K17: Article | L17: NA | P17: 11843 | Q17: 1423.0954
A18: Matt.10.17 | B18: προσεχετε απο | C18: προσεχετε δε απο | G18: Addition | I18: 1 | J18: 2 | K18: Conjunction | L18: NA | P18: 1966 | Q18: 236.24129
A19: Matt.10.27 | B19: ο λεγω υμειν | C19: ο δε λεγω υμειν | G19: Addition | I19: 1 | J19: 2 | K19: Conjunction | L19: NA | P19: 1966 | Q19: 236.24129
A20: Matt.10.29 | B20: στρουθια του ασσαριου | C20: στρουθια ασσαριου | G20: Omission | I20: 1 | J20: 3 | K20: Article | L20: Present | M20: AB:AC | N20: 3:3 | P20: 11843 | Q20: 1423.0954
A21: Matt.10.33 | B21: οστις δ αν αρνησητε | C21: οστις δ αρνησητε | F21: Yes | G21: Omission | I21: 1 | J21: 2 | K21: Particle | L21: NA | P21: 134 | Q21: 16.101899
A22: Matt.10.35 | B22: κατα πατρος | C22: κατα του πατρος | G22: Addition | I22: 1 | J22: 3 | K22: Article | L22: Absent | P22: 11843 | Q22: 1423.0954 | U22: Harmonizing
A23: Matt.11.1 | B23: διατασσων τοις δωδεκα | C23: διατασσων δωδεκα | F23: Yes | G23: Omission | I23: 1 | J23: 4 | K23: Article | L23: Absent | P23: 11843 | Q23: 1423.0954
A24: Matt.11.4 | B24: απαγγειλατε ιωαννει | C24: απαγγειλατε τω ιωανει | G24: Addition | I24: 1 | J24: 2 | K24: Article | L24: NA | P24: 11843 | Q24: 1423.0954
A25: Matt.11.7 | B25: ηρξατο ιης | C25: ηρξατο ο ις | G25: Addition | I25: 1 | J25: 1 | K25: Article | L25: NA | P25: 11843 | Q25: 1423.0954
A26: Matt.11.16 | B26: προσφωνουντα τοις ετεροις | C26: προσφωνουντα ετεροις | G26: Omission | I26: 1 | J26: 4 | K26: Article | L26: Present | M26: BD:CD | N26: 4:4 | P26: 11843 | Q26: 1423.0954
A27: Matt.11.27 | B27: πατερα τις επιγεινωσκει ει μη | C27: πατερα επιγεινωσκει ει μη | G27: Omission | I27: 1 | J27: 3 | K27: Pronoun | L27: Absent | P27: 301 | Q27: 36.16919
A28: Matt.12.1 | B28: ηρξαντο του σταχυας τιλλειν | C28: ηρξαντο σταχυας τιλλειν | G28: Omission | I28: 1 | J28: 3 | K28: Article | L28: Absent | P28: 11843 | Q28: 1423.0954
A29: Matt.12.5 | B29: η ουκ ανεγνωτε | C29: η μεν ουκ ανεγνωτε | G29: Addition | I29: 1 | J29: 3 | K29: Particle | L29: Absent | P29: 92 | Q29: 11.055035
A30: Matt.12.6 | B30: ιερου μειζον εστιν | C30: ιερου ο μειζων εστιν | G30: Addition | I30: 1 | J30: 1 | K30: Article | L30: NA | P30: 11843 | Q30: 1423.0954
A31: Matt.12.22 | B31: ωστε τον κωφον | C31: ωστε κωφον | G31: Omission | I31: 1 | J31: 3 | K31: Article | L31: Absent | P31: 11843 | Q31: 1423.0954
A32: Matt.12.23 | B32: μητι οτι ουτος | C32: μητι ουτος | G32: Omission | I32: 1 | J32: 3 | K32: Conjunction | L32: Absent | P32: 810 | Q32: 97.332372
A33: Matt.12.23 | B33: υιος δαυειδ | C33: υιος του δαβειδ | G33: Addition | I33: 1 | J33: 3 | K33: Article | L33: Absent | P33: 11843 | Q33: 1423.0954
A34: Matt.12.41 | B34: κηρυγμα ιωνα | C34: κηρυγμα του ιωνα | F34: Yes | G34: Addition | I34: 1 | J34: 3 | K34: Article | L34: Absent | P34: 11843 | Q34: 1423.0954
A35: Matt.12.50 | B35: οστις γαρ ποιει | C35: οστις γαρ αν ποιει | G35: Addition | I35: 1 | J35: 2 | K35: Particle | L35: NA | P35: 134 | Q35: 16.101899
A36: Matt.13.3 | B36: σπειρων σπειραι | C36: σπειρων του σπειραι | G36: Addition | I36: 1 | J36: 3 | K36: Article | L36: Absent | P36: 11843 | Q36: 1423.0954
A37: Matt.13.14 | B37: και ου μη συνηται | C37: και μη συνηται | G37: Omission | I37: 1 | J37: 2 | K37: Particle | L37: NA | P37: 887 | Q37: 106.58496
A38: Matt.13.16 | B38: μακαριοι οφθαλμοι | C38: μακαριοι οιοφθαλμοι | G38: Addition | I38: 1 | J38: 2 | K38: Article | L38: NA | P38: 11843 | Q38: 1423.0954
A39: Matt.13.22 | B39: αιωνος και η απατη | C39: αιωνος τουτου και η απατη | G39: Addition | I39: 1 | J39: 6 | K39: Preposition | L39: Absent | P39: 930 | Q39: 111.75198
A40: Matt.13.40 | B40: του αιωνος (41) αποστελει | C40: του αιωνος τουτου (41) αποστελει | G40: Addition | I40: 1 | J40: 6 | K40: Pronoun | L40: Absent | P40: 930 | Q40: 111.75198
...

Sheet WF_AO_HM
A1: Verse Ref | B1: Autograph | C1: Apograph | D1: Exclusion Grounds | E1: Corrector Followed | F1: Apograph Corrected | G1: Basic Type | H1: Phrase Length | I1: Words Length | J1: Letters Length | K1: Speech Part Add/Omitted | L1: Visual Cues | M1: Cue Regions | N1: Cue Length | O1: Duplicate Material | P1: AO Word Frequency | Q1: Freq-per-10000 | R1: SUB Frequency Difference | S1: Harmonization - Context | T1: Parallel Present | U1: Harmonization - Parallel | V1: Singularity | W1: Secondary | X1: Minutiae | Y1: Orthographic - General | Z1: Mere Minutiae | AA1: Nonsense | AB1: Review
A2: Matt.12.10 | B2: ην εκει την χειρα | C2: ην την χειρα | G2: Omission | I2: 1 | J2: 4 | K2: Adverb | L2: Absent | P2: 10 | Q2: 1.2016342
A3: Matt.12.28 | B3: πνι θυ εγω | C3: πνευματι εγω | G3: Omission | I3: 1 | J3: 2 | K3: Noun | L3: NA | P3: 472 | Q3: 56.717135
A4: Matt.14.8 | B4: ωδε κεφαλην ιωαννου του βαπτιστου | C4: ωδε την κεφαλην του βαπτιστου | G4: Omission | I4: 1 | J4: 7 | K4: Noun | L4: Absent | P4: 131 | Q4: 15.741408
A5: Matt.16.16 | B5: αποκριθεις δε σιμων πετρος | C5: αποκριθεις δε πετρος σιμων πετρος | F5: Yes | G5: Addition | I5: 1 | J5: 6 | K5: Noun | L5: Absent | P5: 152 | Q5: 18.26484
A6: Matt.16.27 | B6: των αγιων αγγελων | C6: των αγγελων | G6: Omission | I6: 1 | J6: 5 | K6: Adjective | L6: Present | M6: BD:CD | N6: 4:4 | P6: 95 | Q6: 11.415525
A7: Matt.17.15 | B7: και ενιοτε εις το υδωρ | C7: και εις το υδωρ | G7: Omission | I7: 1 | J7: 6 | K7: Adverb | L7: Absent | P7: 0 | Q7: 0
A8: Matt.19.5 | B8: καταλειψει ανθρωπος τον πατερα | C8: καταλειψει τον πατερα | G8: Omission | I8: 1 | J8: 8 | K8: Noun | L8: Absent | P8: 371 | Q8: 44.58063
A9: Matt.25.29 | B9: εχοντι δοθησεται | C9: εχοντι παντι δοθησεται | G9: Addition | I9: 1 | J9: 5 | K9: Adjective | L9: Present | M9: AB:AC | N9: 3:3 | P9: 591 | Q9: 71.016583
A10: Matt.25.30 | B10: δουλον βαλεται εξω εις το σκοτος | C10: δουλον εκβαλλεται εις το σκοτος | G10: Omission | I10: 1 | J10: 3 | K10: Adverb | L10: Absent | P10: 52 | Q10: 6.248498
A11: Matt.25.40 | B11: αποκρειθεις ερει αυτοις | C11: αποκριθεις αυτοις | G11: Omission | I11: 1 | J11: 4 | K11: Verb | L11: Present | M11: AB:AC | N11: 3:3 | P11: 2042 | Q11: 245.37371
A12: Matt.26.63 | B12: ειπης ει συ ει ο χρς | C12: ειπης ει συ ο χριστος | G12: Omission | I12: 1 | J12: 2 | K12: Verb | L12: NA | P12: 1565 | Q12: 188.05576
A13: Matt.27.55 | B13: ησαν δε και γυναικες | C13: ησαν δε εκει και γυναικες | F13: Yes | G13: Addition | I13: 1 | J13: 4 | K13: Adverb | L13: Absent | P13: 10 | Q13: 1.2016342
A14: Mark.1.7 | B14: ικανος λυσαι | C14: ικανος κυψας λυσαι | F14: Yes | G14: Addition | I14: 1 | J14: 5 | K14: Participle | L14: Present | M14: AB:AC | N14: 3:3 | P14: 2 | Q14: 0.24032684
A15: Mark.1.17 | B15: γενεσθαι αλιεις ανθρωπων | C15: γενεσθαι αλιεις αλιεις ανθρωπων | G15: Addition | I15: 1 | J15: 6 | K15: Noun | L15: Present | M15: AB:AC | N15: 6:6 | O15: Dittography | P15: 5 | Q15: 0.60081711
A16: Mark.1.31 | B16: χειρα κρατησας ηγειρεν αυτην και ευθεως αφηκεν αυτην | C16: χειρα ηγειρεν και αφηκεν αυτην | F16: Yes | G16: Omission | I16: 1 | J16: 8 | K16: Participle | L16: Absent | P16: 35 | Q16: 4.2057198
A17: Mark.1.31 | B17: χειρα κρατησας ηγειρεν αυτην και ευθεως αφηκεν αυτην | C17: χειρα ηγειρεν και αφηκεν αυτην | F17: Yes | G17: Omission | I17: 1 | J17: 6 | K17: Adverb | L17: Absent | P17: 32 | Q17: 3.8452295
A18: Mark.2.7 | B18: ει μη ο θς | C18: ει μη εις ο θεος | G18: Addition | I18: 1 | J18: 3 | K18: Adjective | L18: Absent | P18: 214 | Q18: 25.714972
A19: Mark.3.6 | B19: φαρισαιοι μετα των | C19: φαρισαιοι ευθεως μετα των | G19: Addition | I19: 1 | J19: 6 | K19: Adverb | L19: Absent | P19: 32 | Q19: 3.8452295
A20: Mark.3.9 | B20: αυτον πολλοι (10) πολλους | C20: αυτον (10) πολλους | G20: Omission | I20: 1 | J20: 6 | K20: Adjective | L20: Present | M20: BD:CD | N20: 5:5 | P20: 287 | Q20: 34.486902
A21: Mark.4.4 | B21: σπειρων (4) και εν τω τ σπειραι ο μεν | C21: σπειρων του σπειραι (4) και εγενετο εν τω σπειρειν ο μεν | G21: Addition | I21: 1 | J21: 7 | K21: Verb | L21: Present | M21: BD:CD | N21: 3:3 | P21: 437 | Q21: 52.511416
A22: Mark.4.16 | B22: λογον μετα χαρας | C22: λογον ευθεως μετα χαρας | G22: Addition | I22: 1 | J22: 6 | K22: Adverb | L22: Absent | P22: 32 | Q22: 3.8452295
A23: Mark.4.31 | B23: ομοια εστιν κοκκω | C23: ομοια κοκκω | G23: Omission | I23: 1 | J23: 5 | K23: Verb | L23: Absent | P23: 1565 | Q23: 188.05576
A24: Mark.5.9 | B24: ονομα εστιν και | C24: ονομα και | G24: Omission | I24: 1 | J24: 5 | K24: Verb | L24: Absent | P24: 1565 | Q24: 188.05576
A25: Mark.5.11 | B25: χοιρων βοσκομενη | C25: χοιρων μεγαλη βοσκομενη | G25: Addition | I25: 1 | J25: 6 | K25: Adjective | L25: Absent | P25: 130 | Q25: 15.621245
A26: Mark.5.40 | B26: μετ αυτου οντας και εισεπορευετο οπου | C26: μετ αυτου και εισεπορευεται οπου | G26: Omission | I26: 1 | J26: 5 | K26: Participle | L26: Absent | P26: 1565 | Q26: 188.05576
A27: Mark.6.41 | B27: λαβων ε αρτους | C27: λαβων αρτους | G27: Omission | I27: 1 | J27: 1 | K27: Adjective | L27: NA | P27: 34 | Q27: 4.0855564
A28: Mark.6.45 | B28: ευθεως εξεγερθεις ηναγκασεν | C28: ευθεως ηναγκασεν | G28: Omission | I28: 1 | J28: 10 | K28: Participle | L28: Present | M28: AB:AC | N28: 3:3 | P28: 0 | Q28: 0
A29: Mark.7.28 | B29: λεγουσα κυ αλλα και τα κυναρια | C29: λεγουσα ναι κε και γαρ τα κυναρια | G29: Addition | I29: 1 | J29: 3 | K29: Adverb | L29: Absent | P29: 18 | Q29: 2.1629416
A30: Mark.8.1 | B30: ημεραις παλιν πολλου | C30: ημεραις πολλου | G30: Omission | I30: 1 | J30: 5 | K30: Adverb | L30: Absent | P30: 98 | Q30: 11.776015
A31: Mark.9.22 | B31: ημειν κε σπλαγχνισθεις | C31: ημειν σπλαγχνισθεις | G31: Omission | I31: 1 | J31: 2 | K31: Noun | L31: NA | P31: 361 | Q31: 43.378995
A32: Mark.10.41 | B32: λοιποι ι ηρξαντο | C32: λοιποι ηρξαντο | G32: Omission | I32: 1 | J32: 1 | K32: Adjective | L32: NA | O32: Dittography | P32: 16 | Q32: 1.9226148
A33: Mark.12.14 | B33: ημειν ει εξεστιν ημας δουναι επικαιφαλαιον καισαρι η ου (15) ο δε | C33: ημειν εξεστι δουναι καισαρι επικεφαλαιον καισαρος η ου (15) ο δε | G33: Addition | I33: 1 | J33: 8 | K33: Noun | L33: Present | M33: AB:AC | N33: 4:4 | P33: 28 | Q33: 3.3645758
A34: Mark.12.24 | B34: θυ οιδατε (25) οταν | C34: θεου (25) οταν | G34: Omission | I34: 1 | J34: 6 | K34: Verb | L34: Absent | P34: 173 | Q34: 20.788272
A35: Mark.12.26 | B35: βυβλω μωυσεως επι | C35: βυβλω επι | G35: Omission | I35: 1 | J35: 7 | K35: Noun | L35: Absent | P35: 57 | Q35: 6.8493151
A36: Mark.12.28 | B36: λεγων διδασκαλε ποια | C36: λεγων ποια | G36: Omission | I36: 1 | J36: 9 | K36: Noun | L36: Absent | P36: 50 | Q36: 6.0081711
A37: Mark.14.56 | B37: εψευδομαρτυρουν ελεγον κατ αυτου | C37: εψευδομαρτυρουν κατ αυτου | E37: No | G37: Omission | I37: 1 | J37: 6 | K37: Verb | L37: Present | M37: AB:AC | N37: 4:4 | P37: 2042 | Q37: 245.37371 | U37: Disharmonizing
A38: Mark.14.62 | B38: ιης αποκριθεις λεγει αυτω εγω ειμι | C38: ις ειπεν εγω ειμι | G38: Omission | I38: 1 | J38: 10 | K38: Participle | L38: Absent | P38: 229 | Q38: 27.517424
A39: Mark.15.6 | B39: απεαυεν αυτοις ενα δεσμειον | C39: απελυεν αυτοις δεσμειον | G39: Omission | I39: 1 | J39: 3 | K39: Adjective | L39: Absent | P39: 214 | Q39: 25.714972
A40: Mark.15.13 | B40: παλιν λεγοντες στρν | C40: παλιν σταυρωσον | G40: Omission | I40: 1 | J40: 8 | K40: Participle | L40: Absent | P40: 2042 | Q40: 245.37371
...

Sheet WF_SUB
A1: Verse Ref | B1: Autograph | C1: Apograph | D1: Exclusion Grounds | E1: Corrector Followed | F1: Apograph Corrected | G1: Basic Type | H1: Phrase Length | I1: Words Length | J1: Letters Length | K1: Speech Part Add/Omitted | L1: Visual Cues | M1: Cue Regions | N1: Cue Length | O1: Duplicate Material | P1: AO Word Frequency | Q1: SUB Frequency Difference | R1: SUB_Aut_Freq | S1: SUB_Apog_Freq | T1: Aut_P10K_Freq | U1: Apog_P10K_Freq | V1: P10K_Freq_Diff | W1: Harmonization - Context | X1: Parallel Present | Y1: Harmonization - Parallel | Z1: Singularity | AA1: Secondary | AB1: Minutiae | AC1: Orthographic - General | AD1: Mere Minutiae | AE1: Nonsense | AF1: Review
A2: Matt.1.25 | B2: εκαλεσεν το ονομα | C2: ελαλησεν το ονομα | G2: Substitution - Word | Q2: 103 | R2: 93 | S2: 196 | T2: =IF(ISNUMBER(R2), (R2/$E$353)*10000, "") -> 11.175198 | U2: =IF(ISNUMBER(S2), (S2/$E$353)*10000, "") -> 23.552031 | V2: =IF(ISNUMBER(Q2), U2-T2, "") -> 12.376832 | W2: Disharmonizing
A3: Matt.2.14 | B3: ο δε διεγερθεις | C3: ο δε εγερθεις | G3: Substitution - Word | Q3: 95 | R3: 4 | S3: 99 | T3: =IF(ISNUMBER(R3), (R3/$E$353)*10000, "") -> 0.48065369 | U3: =IF(ISNUMBER(S3), (S3/$E$353)*10000, "") -> 11.896179 | V3: =IF(ISNUMBER(Q3), U3-T3, "") -> 11.415525 | W3: Harmonizing
A4: Matt.5.23 | B4: (22) πυρος (23) εαν ουν | C4: (22) πυρος (23) επει ουν | G4: Substitution - Word | Q4: -141 | R4: 148 | S4: 7 | T4: =IF(ISNUMBER(R4), (R4/$E$353)*10000, "") -> 17.784186 | U4: =IF(ISNUMBER(S4), (S4/$E$353)*10000, "") -> 0.84114396 | V4: =IF(ISNUMBER(Q4), U4-T4, "") -> -16.943043
A5: Matt.6.6 | B5: πατρι σου εν τω | C5: πατρι τω εν τω | G5: Substitution - Word | Q5: 10102 | R5: 1741 | S5: 11843 | T5: =IF(ISNUMBER(R5), (R5/$E$353)*10000, "") -> 209.20452 | U5: =IF(ISNUMBER(S5), (S5/$E$353)*10000, "") -> 1423.0954 | V5: =IF(ISNUMBER(Q5), U5-T5, "") -> 1213.8909 | W5: Disharmonizing
A6: Matt.6.16 | B6: ως οι υποκρειται | C6: ωσπερ οι υποκριται | G6: Substitution - Word | Q6: -190 | R6: 207 | S6: 17 | T6: =IF(ISNUMBER(R6), (R6/$E$353)*10000, "") -> 24.873828 | U6: =IF(ISNUMBER(S6), (S6/$E$353)*10000, "") -> 2.0427782 | V6: =IF(ISNUMBER(Q6), U6-T6, "") -> -22.83105
A7: Matt.10.9 | B7: χρυσον μητε αργυρον μητε χαλκον | C7: χρυσον μηδε αργυρον μηδε χαλκον | G7: Substitution - Word | Q7: 8 | R7: 20 | S7: 28 | T7: =IF(ISNUMBER(R7), (R7/$E$353)*10000, "") -> 2.4032684 | U7: =IF(ISNUMBER(S7), (S7/$E$353)*10000, "") -> 3.3645758 | V7: =IF(ISNUMBER(Q7), U7-T7, "") -> 0.96130738
A8: Matt.10.9 | B8: χρυσον μητε αργυρον μητε χαλκον | C8: χρυσον μηδε αργυρον μηδε χαλκον | G8: Substitution - Word | Q8: 8 | R8: 20 | S8: 28 | T8: =IF(ISNUMBER(R8), (R8/$E$353)*10000, "") -> 2.4032684 | U8: =IF(ISNUMBER(S8), (S8/$E$353)*10000, "") -> 3.3645758 | V8: =IF(ISNUMBER(Q8), U8-T8, "") -> 0.96130738
A9: Matt.11.18 | B9: εσθιων μητε πεινων | C9: εσθιων μητε πιων | G9: Substitution - Word | Q9: 37 | R9: 17 | S9: 54 | T9: =IF(ISNUMBER(R9), (R9/$E$353)*10000, "") -> 2.0427782 | U9: =IF(ISNUMBER(S9), (S9/$E$353)*10000, "") -> 6.4888248 | V9: =IF(ISNUMBER(Q9), U9-T9, "") -> 4.4460466 | W9: Disharmonizing
A10: Matt.12.18 | B10: απαγγελλει | C10: αναγγελλει | G10: Substitution - Word | Q10: -30 | R10: 40 | S10: 10 | T10: =IF(ISNUMBER(R10), (R10/$E$353)*10000, "") -> 4.8065369 | U10: =IF(ISNUMBER(S10), (S10/$E$353)*10000, "") -> 1.2016342 | V10: =IF(ISNUMBER(Q10), U10-T10, "") -> -3.6049027
A11: Matt.12.29 | B11: τις εισελθειν | C11: τις εξελθειν | G11: Substitution - Word | Q11: 21 | R11: 165 | S11: 186 | T11: =IF(ISNUMBER(R11), (R11/$E$353)*10000, "") -> 19.826965 | U11: =IF(ISNUMBER(S11), (S11/$E$353)*10000, "") -> 22.350397 | V11: =IF(ISNUMBER(Q11), U11-T11, "") -> 2.5234319
A12: Matt.12.37 | B12: δικαιωθηση η εκ των | C12: δικαιωθηση και εκ των | G12: Substitution - Word | Q12: 5483 | R12: 193 | S12: 5676 | T12: =IF(ISNUMBER(R12), (R12/$E$353)*10000, "") -> 23.19154 | U12: =IF(ISNUMBER(S12), (S12/$E$353)*10000, "") -> 682.04758 | V12: =IF(ISNUMBER(Q12), U12-T12, "") -> 658.85604
A13: Matt.12.48 | B13: μου η τινες | C13: μου και τινες | G13: Substitution - Word | Q13: 5483 | R13: 193 | S13: 5676 | T13: =IF(ISNUMBER(R13), (R13/$E$353)*10000, "") -> 23.19154 | U13: =IF(ISNUMBER(S13), (S13/$E$353)*10000, "") -> 682.04758 | V13: =IF(ISNUMBER(Q13), U13-T13, "") -> 658.85604
A14: Matt.13.5 | B14: α δε επεσεν | C14: α μεν επεσεν | G14: Substitution - Word | Q14: -1874 | R14: 1966 | S14: 92 | T14: =IF(ISNUMBER(R14), (R14/$E$353)*10000, "") -> 236.24129 | U14: =IF(ISNUMBER(S14), (S14/$E$353)*10000, "") -> 11.055035 | V14: =IF(ISNUMBER(Q14), U14-T14, "") -> -225.18625
A15: Matt.13.19 | B15: συνιοντος | C15: συνιεντος | G15: Substitution - Word | Q15: 19 | R15: 3 | S15: 22 | T15: =IF(ISNUMBER(R15), (R15/$E$353)*10000, "") -> 0.36049027 | U15: =IF(ISNUMBER(S15), (S15/$E$353)*10000, "") -> 2.6435953 | V15: =IF(ISNUMBER(Q15), U15-T15, "") -> 2.283105
A16: Matt.14.5 | B16: τον οχλον οτι | C16: τον λαον οτι | G16: Substitution - Word | Q16: -68 | R16: 171 | S16: 103 | T16: =IF(ISNUMBER(R16), (R16/$E$353)*10000, "") -> 20.547945 | U16: =IF(ISNUMBER(S16), (S16/$E$353)*10000, "") -> 12.376832 | V16: =IF(ISNUMBER(Q16), U16-T16, "") -> -8.1711127
A17: Matt.14.34 | B17: διαπερασαντες | C17: διαπρασαντες | G17: Substitution - Word | Q17: -6 | R17: 6 | S17: 0 | T17: =IF(ISNUMBER(R17), (R17/$E$353)*10000, "") -> 0.72098053 | U17: =IF(ISNUMBER(S17), (S17/$E$353)*10000, "") -> 0 | V17: =IF(ISNUMBER(Q17), U17-T17, "") -> -0.72098053
A18: Matt.15.27 | B18: τραπεζης των κυναριων αυτων | C18: τραπεζης κυριων αυτων | G18: Substitution - Word | Q18: 357 | R18: 4 | S18: 361 | T18: =IF(ISNUMBER(R18), (R18/$E$353)*10000, "") -> 0.48065369 | U18: =IF(ISNUMBER(S18), (S18/$E$353)*10000, "") -> 43.378995 | V18: =IF(ISNUMBER(Q18), U18-T18, "") -> 42.898342
A19: Matt.16.9 | B19: ουδε | C19: ουτε | G19: Substitution - Word | Q19: -50 | R19: 87 | S19: 37 | T19: =IF(ISNUMBER(R19), (R19/$E$353)*10000, "") -> 10.454218 | U19: =IF(ISNUMBER(S19), (S19/$E$353)*10000, "") -> 4.4460466 | V19: =IF(ISNUMBER(Q19), U19-T19, "") -> -6.0081711
A20: Matt.16.16 | B20: θυ το σωζοντος | C20: θυ του ζωντος | G20: Substitution - Word | Q20: -19 | R20: 66 | S20: 47 | T20: =IF(ISNUMBER(R20), (R20/$E$353)*10000, "") -> 7.9307859 | U20: =IF(ISNUMBER(S20), (S20/$E$353)*10000, "") -> 5.6476808 | V20: =IF(ISNUMBER(Q20), U20-T20, "") -> -2.283105
A21: Matt.16.21 | B21: παθειν υπο των πρεσβυτερων | C21: παθειν απο των πρεσβυτερων | G21: Substitution - Word | Q21: 330 | R21: 114 | S21: 444 | T21: =IF(ISNUMBER(R21), (R21/$E$353)*10000, "") -> 13.69863 | U21: =IF(ISNUMBER(S21), (S21/$E$353)*10000, "") -> 53.352559 | V21: =IF(ISNUMBER(Q21), U21-T21, "") -> 39.653929
... A24: Matt.18.31 | B24: ιδοντες ουν οι συνδουλοι αυτου | C24: ιδοντες δε οι συνδουλος αυτου | G24: Substitution - Word | Q24: 1610 | R24: 356 | S24: 1966 | T24: =IF(ISNUMBER(R24), (R24/$E$353)*10000, "") -> 42.778178 | U24: =IF(ISNUMBER(S24), (S24/$E$353)*10000, "") -> 236.24129 | V24: =IF(ISNUMBER(Q24), U24-T24, "") -> 193.46311
A25: Matt.19.24 | B25: βασιλειαν του θυ | C25: βασιλειαν των ουρανων | G25: Substitution - Word | Q25: -293 | R25: 472 | S25: 179 | T25: =IF(ISNUMBER(R25), (R25/$E$353)*10000, "") -> 56.717135 | U25: =IF(ISNUMBER(S25), (S25/$E$353)*10000, "") -> 21.509253 | V25: =IF(ISNUMBER(Q25), U25-T25, "") -> -35.207883 | W25: Harmonizing
A26: Matt.20.3 | B26: και διεξελθων | C26: και εξελθων | G26: Substitution - Word | Q26: 186 | R26: 0 | S26: 186 | T26: =IF(ISNUMBER(R26), (R26/$E$353)*10000, "") -> 0 | U26: =IF(ISNUMBER(S26), (S26/$E$353)*10000, "") -> 22.350397 | V26: =IF(ISNUMBER(Q26), U26-T26, "") -> 22.350397
A27: Matt.20.15 | B27: εμοις η ο οφθαλμος | C27: εμοις ει ο οφθαλμος | G27: Substitution - Word | Q27: -34 | R27: 227 | S27: 193 | T27: =IF(ISNUMBER(R27), (R27/$E$353)*10000, "") -> 27.277097 | U27: =IF(ISNUMBER(S27), (S27/$E$353)*10000, "") -> 23.19154 | V27: =IF(ISNUMBER(Q27), U27-T27, "") -> -4.0855564
A28: Matt.20.34 | B28: των ομματων αυτων | C28: των οφθαλμων αυτων | G28: Substitution - Word | Q28: 71 | R28: 2 | S28: 73 | T28: =IF(ISNUMBER(R28), (R28/$E$353)*10000, "") -> 0.24032684 | U28: =IF(ISNUMBER(S28), (S28/$E$353)*10000, "") -> 8.7719298 | V28: =IF(ISNUMBER(Q28), U28-T28, "") -> 8.531603
A29: Matt.22.5 | B29: οι δε επι την εμπορειαν | C29: οι δε εις την εμπορειαν | G29: Substitution - Word | Q29: 541 | R29: 560 | S29: 1101 | T29: =IF(ISNUMBER(R29), (R29/$E$353)*10000, "") -> 67.291516 | U29: =IF(ISNUMBER(S29), (S29/$E$353)*10000, "") -> 132.29993 | V29: =IF(ISNUMBER(Q29), U29-T29, "") -> 65.008411
A30: Matt.23.6 | B30: φιλουσιν δε την την πρωκλεισιαν | C30: φιλουσιν τε την πρωκλεισιαν | G30: Substitution - Word | Q30: -1800 | R30: 1966 | S30: 166 | T30: =IF(ISNUMBER(R30), (R30/$E$353)*10000, "") -> 236.24129 | U30: =IF(ISNUMBER(S30), (S30/$E$353)*10000, "") -> 19.947128 | V30: =IF(ISNUMBER(Q30), U30-T30, "") -> -216.29416
A31: Matt.23.37 | B31: νοσσεια αυτης | C31: νοσσεια εαυτης | G31: Substitution - Word | Q31: -4080 | R31: 4240 | S31: 160 | T31: =IF(ISNUMBER(R31), (R31/$E$353)*10000, "") -> 509.49291 | U31: =IF(ISNUMBER(S31), (S31/$E$353)*10000, "") -> 19.226148 | V31: =IF(ISNUMBER(Q31), U31-T31, "") -> -490.26676
A32: Matt.24.45 | B32: τις γαρ εστιν | C32: τις αρα εστιν | G32: Substitution - Word | Q32: -409 | R32: 431 | S32: 22 | T32: =IF(ISNUMBER(R32), (R32/$E$353)*10000, "") -> 51.790435 | U32: =IF(ISNUMBER(S32), (S32/$E$353)*10000, "") -> 2.6435953 | V32: =IF(ISNUMBER(Q32), U32-T32, "") -> -49.14684
A33: Matt.24.50 | B33: εν ωρα η ου | C33: εν ημερα η ου | G33: Substitution - Word | Q33: 193 | R33: 87 | S33: 280 | T33: =IF(ISNUMBER(R33), (R33/$E$353)*10000, "") -> 10.454218 | U33: =IF(ISNUMBER(S33), (S33/$E$353)*10000, "") -> 33.645758 | V33: =IF(ISNUMBER(Q33), U33-T33, "") -> 23.19154
A34: Matt.25.1 | B34: λαβουσαι τας λαμπαδας εαυτων | C34: λαβουσαι ται λαμπαδας αυτων | G34: Substitution - Word | Q34: 4080 | R34: 160 | S34: 4240 | T34: =IF(ISNUMBER(R34), (R34/$E$353)*10000, "") -> 19.226148 | U34: =IF(ISNUMBER(S34), (S34/$E$353)*10000, "") -> 509.49291 | V34: =IF(ISNUMBER(Q34), U34-T34, "") -> 490.26676 | W34: Harmonizing
A35: Matt.25.22 | B35: ταλαντα επεκερδησα (23) εφη | C35: ταλαντα εκερδησα επ αυτοις (23) εφη | G35: Substitution - Word | Q35: 9 | R35: 0 | S35: 9 | T35: =IF(ISNUMBER(R35), (R35/$E$353)*10000, "") -> 0 | U35: =IF(ISNUMBER(S35), (S35/$E$353)*10000, "") -> 1.0814708 | V35: =IF(ISNUMBER(Q35), U35-T35, "") -> 1.0814708 | W35: Disharmonizing
A36: Matt.25.24 | B36: συναγων οπου ου διεσκορπισας | C36: συναγων οθεν ου διεσκορπισας | G36: Substitution - Word | Q36: -57 | R36: 65 | S36: 8 | T36: =IF(ISNUMBER(R36), (R36/$E$353)*10000, "") -> 7.8106224 | U36: =IF(ISNUMBER(S36), (S36/$E$353)*10000, "") -> 0.96130738 | V36: =IF(ISNUMBER(Q36), U36-T36, "") -> -6.8493151
A37: Matt.25.26 | B37: συναγω οθεν ου διεσκορπισα | C37: συναγω οπου ου διεσκορπισα | G37: Substitution - Word | Q37: 57 | R37: 8 | S37: 65 | T37: =IF(ISNUMBER(R37), (R37/$E$353)*10000, "") -> 0.96130738 | U37: =IF(ISNUMBER(S37), (S37/$E$353)*10000, "") -> 7.8106224 | V37: =IF(ISNUMBER(Q37), U37-T37, "") -> 6.8493151
A38: Matt.25.30 | B38: δουλον βαλεται εξω εις το σκοτος | C38: δουλον εκβαλλεται εις το σκοτος | G38: Substitution - Both | Q38: -15 | R38: 92 | S38: 77 | T38: =IF(ISNUMBER(R38), (R38/$E$353)*10000, "") -> 11.055035 | U38: =IF(ISNUMBER(S38), (S38/$E$353)*10000, "") -> 9.2525835 | V38: =IF(ISNUMBER(Q38), U38-T38, "") -> -1.8024513
A39: Matt.25.30 | B39: το εξωτερον εκει | C39: το εξω εκει | G39: Substitution - Word | Q39: 49 | R39: 3 | S39: 52 | T39: =IF(ISNUMBER(R39), (R39/$E$353)*10000, "") -> 0.36049027 | U39: =IF(ISNUMBER(S39), (S39/$E$353)*10000, "") -> 6.248498 | V39: =IF(ISNUMBER(Q39), U39-T39, "") -> 5.8880077
A40: Matt.25.39 | B40: ασθενουντα η εν φυλακη | C40: ασθενουντα και εν φυλακη | G40: Substitution - Word | Q40: 5483 | R40: 193 | S40: 5676 | T40: =IF(ISNUMBER(R40), (R40/$E$353)*10000, "") -> 23.19154 | U40: =IF(ISNUMBER(S40), (S40/$E$353)*10000, "") -> 682.04758 | V40: =IF(ISNUMBER(Q40), U40-T40, "") -> 658.85604
A41: Matt.26.2 | B41: (1) μαθηταις (2) οτι μετα δυο | C41: (1) μαθηταις αυτου (2) οιδατε οτε μετα δυο | G41: Substitution - Word | Q41: -743 | R41: 810 | S41: 67 | T41: =IF(ISNUMBER(R41), (R41/$E$353)*10000, "") -> 97.332372 | U41: =IF(ISNUMBER(S41), (S41/$E$353)*10000, "") -> 8.0509493 | V41: =IF(ISNUMBER(Q41), U41-T41, "") -> -89.281423
A42: Matt.26.26 | B42: και ευλογησας εκλασεν | C42: και ευχαριστησας εκλασεν | G42: Substitution - Word | Q42: -12 | R42: 25 | S42: 13 | T42: =IF(ISNUMBER(R42), (R42/$E$353)*10000, "") -> 3.0040856 | U42: =IF(ISNUMBER(S42), (S42/$E$353)*10000, "") -> 1.5621245 | V42: =IF(ISNUMBER(Q42), U42-T42, "") -> -1.4419611
...

Sheet Harmonization
A1: Verse Ref | B1: Autograph | C1: Apograph | D1: Exclusion Grounds | E1: Corrector Followed | F1: Apograph Corrected | G1: Detail | H1: Basic Type | I1: Phrase Length | J1: Words Length | K1: Letters Length | L1: Speech Part Add/Omitted | M1: Visual Cues | N1: Cue Regions | O1: Cue Length | P1: Duplicate Material | Q1: AO Word Frequency | R1: SUB Frequency Difference | S1: SUB_Aut_Freq | T1: SUB_Apog_Freq | U1: Harmonization - Context | V1: Harmonization_Direction | W1: Parallel Present | X1: Harmonization - Parallel | Y1: Singularity | Z1: Secondary | AA1: Minutiae | AB1: Orthographic - General | AC1: Mere Minutiae | AD1: Nonsense | AE1: Review | AF1: TR_Reading
A2: Matt.1.25 | B2: εκαλεσεν το ονομα | C2: ελαλησεν το ονομα | G2: autograph matches pattern in 1:21,23 (και καλεσεις το ονομα αυτου); apograph disharmonizes | H2: Substitution - Word | R2: 103 | S2: 93 | T2: 196 | U2: Disharmonizing | V2: Forward | AF2: No
A3: Matt.2.14 | B3: ο δε διεγερθεις | C3: ο δε εγερθεις | G3: apograph matches verb in 2:13,20 (εγερθεις παραλαβε τον παιδα); apograph harmonizes | H3: Substitution - Word | R3: 95 | S3: 4 | T3: 99 | U3: Harmonizing | V3: Both | AF3: Yes
A4: Matt.4.3 | B4: ειπεν αυτω ει υιος | C4: ειπεν ει υιος | G4: autograph matches pattern in 4:6 (λεγει αυτω ει υιος ει θεου); apograph disharmonizes | H4: Omission | J4: 1 | K4: 4 | L4: Pronoun | M4: Absent | Q4: 4240 | U4: Harmonizing | V4: Backward | AF4: Yes
A5: Matt.6.5 | B5: ως οι υποκριται | C5: ως υποκριται | G5: autograph matches pattern in 6:2,16 (ως(περ) οι υποκριται); apograph disharmonizes | H5: Omission | J5: 1 | K5: 2 | L5: Article | M5: NA | Q5: 11843 | U5: Disharmonizing | V5: Both | AF5: No
