Workbook

Sheet Unfiltered Data
A1: Verse Ref | B1: Phys Loc 1 | C1: Phys Loc 2 | D1: Autograph | E1: Apograph | F1: Exclusion Grounds | G1: Corrector Followed | H1: Apograph Corrected | I1: Detail | J1: Basic Type | K1: Phrase Length | L1: Words Length | M1: Letters Length | N1: Speech Part Add/Omitted | O1: Visual Cues | P1: Cue Regions | Q1: Cue Length | R1: Duplicate Material | S1: AO Word Frequency | T1: SUB Frequency Difference | U1: SUB_Aut_Freq | V1: SUB_Apog_Freq | W1: Harmonization - Context | X1: Parallel Present | Y1: Harmonization - Parallel | Z1: Singularity | AA1: Singular Type | AB1: Secondary | AC1: Minutiae | AD1: Orthographic - General | AE1: Mere Minutiae | AF1: Nonsense | AG1: Review
A2: TReub.1.4 | D2: τη καρδια μου κρυπτα εκλιπων | E2: τη καρδια μου κρυτα εκλιπων | H2: Yes | J2: Substitution - Word | T2: NA | U2: =IF(ISNUMBER(T2),VALUE(MID(_xlfn.FORMULATEXT(T2),SEARCH("-",_xlfn.FORMULATEXT(T2))+1,LEN(_xlfn.FORMULATEXT(T2))-SEARCH("-",_xlfn.FORMULATEXT(T2)))), "") | V2: =IF(ISNUMBER(T2), VALUE(MID(_xlfn.FORMULATEXT(T2), 2, SEARCH("-", _xlfn.FORMULATEXT(T2)) - 2)), "") | AB2: Yes | AF2: Generated - strict
A3: TReub.1.7 | D3: ει μη ιακωβ ο πηρ ημων προσηυξατο | E3: ει μη ιακωβ προσηυξατο | H3: Yes | J3: Omission | K3: 0 | L3: 3 | M3: 8 | O3: Absent | S3: 146 | U3: =IF(ISNUMBER(T3),VALUE(MID(_xlfn.FORMULATEXT(T3),SEARCH("-",_xlfn.FORMULATEXT(T3))+1,LEN(_xlfn.FORMULATEXT(T3))-SEARCH("-",_xlfn.FORMULATEXT(T3)))), "") | V3: =IF(ISNUMBER(T3), VALUE(MID(_xlfn.FORMULATEXT(T3), 2, SEARCH("-", _xlfn.FORMULATEXT(T3)) - 2)), "") | AB3: Yes
A4: TReub.1.10 | D4: και παν αρτον | E4: και παντα αρτον | J4: Substitution - Form | U4: =IF(ISNUMBER(T4),VALUE(MID(_xlfn.FORMULATEXT(T4),SEARCH("-",_xlfn.FORMULATEXT(T4))+1,LEN(_xlfn.FORMULATEXT(T4))-SEARCH("-",_xlfn.FORMULATEXT(T4)))), "") | V4: =IF(ISNUMBER(T4), VALUE(MID(_xlfn.FORMULATEXT(T4), 2, SEARCH("-", _xlfn.FORMULATEXT(T4)) - 2)), "") | AB4: Yes
A5: TReub.2.8 | D5: φιληδονιας | E5: φιληδηνιας | H5: Yes | J5: Substitution - Word | T5: NA | U5: =IF(ISNUMBER(T5),VALUE(MID(_xlfn.FORMULATEXT(T5),SEARCH("-",_xlfn.FORMULATEXT(T5))+1,LEN(_xlfn.FORMULATEXT(T5))-SEARCH("-",_xlfn.FORMULATEXT(T5)))), "") | V5: =IF(ISNUMBER(T5), VALUE(MID(_xlfn.FORMULATEXT(T5), 2, SEARCH("-", _xlfn.FORMULATEXT(T5)) - 2)), "") | AB5: Yes | AF5: Generated - strict
A6: TReub.3.1 | D6: και εικων του θανατου | E6: και εικη εικων του θανατου | H6: Yes | I6: Frequency based on εικω | J6: Addition | K6: 0 | L6: 1 | M6: 4 | N6: Verb | O6: Present | P6: BD | Q6: 3 | S6: 0 | U6: =IF(ISNUMBER(T6),VALUE(MID(_xlfn.FORMULATEXT(T6),SEARCH("-",_xlfn.FORMULATEXT(T6))+1,LEN(_xlfn.FORMULATEXT(T6))-SEARCH("-",_xlfn.FORMULATEXT(T6)))), "") | V6: =IF(ISNUMBER(T6), VALUE(MID(_xlfn.FORMULATEXT(T6), 2, SEARCH("-", _xlfn.FORMULATEXT(T6)) - 2)), "") | AB6: Yes
A7: TReub.3.5 | D7: (4) ωφθη (5) πεμπτον πνα υπερηφανειας | E7: (4) ωφθη (5) πνε πεμπτον πνευμα υπερηφανειας | H7: Yes | J7: Addition | K7: 0 | L7: 1 | M7: 3 | N7: Noun | O7: Absent | S7: NA | U7: =IF(ISNUMBER(T7),VALUE(MID(_xlfn.FORMULATEXT(T7),SEARCH("-",_xlfn.FORMULATEXT(T7))+1,LEN(_xlfn.FORMULATEXT(T7))-SEARCH("-",_xlfn.FORMULATEXT(T7)))), "") | V7: =IF(ISNUMBER(T7), VALUE(MID(_xlfn.FORMULATEXT(T7), 2, SEARCH("-", _xlfn.FORMULATEXT(T7)) - 2)), "") | AB7: Yes | AF7: Generated - strict
A8: TReub.3.6 | D8: κλοπη και | E8: κλοπη και | F8: Not a variant, but correction is | I8: O.4.24 corrects κλοπη -> κλοπαι | U8: =IF(ISNUMBER(T8),VALUE(MID(_xlfn.FORMULATEXT(T8),SEARCH("-",_xlfn.FORMULATEXT(T8))+1,LEN(_xlfn.FORMULATEXT(T8))-SEARCH("-",_xlfn.FORMULATEXT(T8)))), "") | V8: =IF(ISNUMBER(T8), VALUE(MID(_xlfn.FORMULATEXT(T8), 2, SEARCH("-", _xlfn.FORMULATEXT(T8)) - 2)), "")
A9: TReub.3.6 | D9: δολολειψιας | E9: δολολειψιας | F9: Not a variant, but correction is | I9: O.4.24 corrects to δοσοληψιας | U9: =IF(ISNUMBER(T9),VALUE(MID(_xlfn.FORMULATEXT(T9),SEARCH("-",_xlfn.FORMULATEXT(T9))+1,LEN(_xlfn.FORMULATEXT(T9))-SEARCH("-",_xlfn.FORMULATEXT(T9)))), "") | V9: =IF(ISNUMBER(T9), VALUE(MID(_xlfn.FORMULATEXT(T9), 2, SEARCH("-", _xlfn.FORMULATEXT(T9)) - 2)), "")
A10: TReub.3.7 | D10: το πνα του υπνου | E10: το πνευμα το υπνου | I10: Autograph corresponds to structure used at T. Reub. 3:1 το πνα του υπνου; apograph disharmonizes | J10: Substitution - Form | U10: =IF(ISNUMBER(T10),VALUE(MID(_xlfn.FORMULATEXT(T10),SEARCH("-",_xlfn.FORMULATEXT(T10))+1,LEN(_xlfn.FORMULATEXT(T10))-SEARCH("-",_xlfn.FORMULATEXT(T10)))), "") | V10: =IF(ISNUMBER(T10), VALUE(MID(_xlfn.FORMULATEXT(T10), 2, SEARCH("-", _xlfn.FORMULATEXT(T10)) - 2)), "") | W10: Disharmonizing | AB10: Yes
A11: TReub.3.7 | D11: συναπτεται πλανη και φαντασια (8) και ουτως | E11: συναπτεται πλανη και φαντασιας (8) και ουτως | J11: Substitution - Form | U11: =IF(ISNUMBER(T11),VALUE(MID(_xlfn.FORMULATEXT(T11),SEARCH("-",_xlfn.FORMULATEXT(T11))+1,LEN(_xlfn.FORMULATEXT(T11))-SEARCH("-",_xlfn.FORMULATEXT(T11)))), "") | V11: =IF(ISNUMBER(T11), VALUE(MID(_xlfn.FORMULATEXT(T11), 2, SEARCH("-", _xlfn.FORMULATEXT(T11)) - 2)), "") | AB11: Yes | AF11: Generated - contextual
A12: TReub.3.11 | D12: σκεπινω | E12: σκεπινω | F12: Not a variant, but correction is | I12: O.4.24 corrects to σκεπηνω | U12: =IF(ISNUMBER(T12),VALUE(MID(_xlfn.FORMULATEXT(T12),SEARCH("-",_xlfn.FORMULATEXT(T12))+1,LEN(_xlfn.FORMULATEXT(T12))-SEARCH("-",_xlfn.FORMULATEXT(T12)))), "") | V12: =IF(ISNUMBER(T12), VALUE(MID(_xlfn.FORMULATEXT(T12), 2, SEARCH("-", _xlfn.FORMULATEXT(T12)) - 2)), "")
A13: TReub.4.1 | D13: καλλος γυναικων | E13: καλλος γυναικων | F13: Not a variant, but correction is | I13: O.4.24 corrects καλλος -> καλλει | U13: =IF(ISNUMBER(T13),VALUE(MID(_xlfn.FORMULATEXT(T13),SEARCH("-",_xlfn.FORMULATEXT(T13))+1,LEN(_xlfn.FORMULATEXT(T13))-SEARCH("-",_xlfn.FORMULATEXT(T13)))), "") | V13: =IF(ISNUMBER(T13), VALUE(MID(_xlfn.FORMULATEXT(T13), 2, SEARCH("-", _xlfn.FORMULATEXT(T13)) - 2)), "")
A14: TReub.4.1 | D14: μοχθωντες | E14: μοχθωντες | F14: Not a variant, but correction is | I14: O.4.24 corrects to μοχθουντες | U14: =IF(ISNUMBER(T14),VALUE(MID(_xlfn.FORMULATEXT(T14),SEARCH("-",_xlfn.FORMULATEXT(T14))+1,LEN(_xlfn.FORMULATEXT(T14))-SEARCH("-",_xlfn.FORMULATEXT(T14)))), "") | V14: =IF(ISNUMBER(T14), VALUE(MID(_xlfn.FORMULATEXT(T14), 2, SEARCH("-", _xlfn.FORMULATEXT(T14)) - 2)), "")
A15: TReub.4.3 | D15: εως νυν | E15: εως νυν | F15: Not a variant, but correction is | I15: O.4.24 corrects to εως του νυν | U15: =IF(ISNUMBER(T15),VALUE(MID(_xlfn.FORMULATEXT(T15),SEARCH("-",_xlfn.FORMULATEXT(T15))+1,LEN(_xlfn.FORMULATEXT(T15))-SEARCH("-",_xlfn.FORMULATEXT(T15)))), "") | V15: =IF(ISNUMBER(T15), VALUE(MID(_xlfn.FORMULATEXT(T15), 2, SEARCH("-", _xlfn.FORMULATEXT(T15)) - 2)), "")
A16: TReub.4.4 | D16: παρελθη | E16: παρεθη | H16: Yes | I16: Frequency = παραθεω - παρερχομαι | J16: Substitution - Word | T16: =0-4 -> -4 | U16: =IF(ISNUMBER(T16),VALUE(MID(_xlfn.FORMULATEXT(T16),SEARCH("-",_xlfn.FORMULATEXT(T16))+1,LEN(_xlfn.FORMULATEXT(T16))-SEARCH("-",_xlfn.FORMULATEXT(T16)))), "") -> 4 | V16: =IF(ISNUMBER(T16), VALUE(MID(_xlfn.FORMULATEXT(T16), 2, SEARCH("-", _xlfn.FORMULATEXT(T16)) - 2)), "") -> 0 | AB16: Yes
A17: TReub.4.6 | D17: εστιν η πορνεια | E17: εστιν πορνεια | H17: Yes | J17: Omission | K17: 0 | L17: 1 | M17: 1 | N17: Article | O17: NA | S17: 2475 | U17: =IF(ISNUMBER(T17),VALUE(MID(_xlfn.FORMULATEXT(T17),SEARCH("-",_xlfn.FORMULATEXT(T17))+1,LEN(_xlfn.FORMULATEXT(T17))-SEARCH("-",_xlfn.FORMULATEXT(T17)))), "") | V17: =IF(ISNUMBER(T17), VALUE(MID(_xlfn.FORMULATEXT(T17), 2, SEARCH("-", _xlfn.FORMULATEXT(T17)) - 2)), "") | AB17: Yes
A18: TReub.4.6 | D18: εστι πλανωσα | E18: εστι πλανωσα | F18: Not a variant, but correction is | I18: O.4.24 corrects to εστι η πλανωσα | U18: =IF(ISNUMBER(T18),VALUE(MID(_xlfn.FORMULATEXT(T18),SEARCH("-",_xlfn.FORMULATEXT(T18))+1,LEN(_xlfn.FORMULATEXT(T18))-SEARCH("-",_xlfn.FORMULATEXT(T18)))), "") | V18: =IF(ISNUMBER(T18), VALUE(MID(_xlfn.FORMULATEXT(T18), 2, SEARCH("-", _xlfn.FORMULATEXT(T18)) - 2)), "")
A19: TReub.4.8 | D19: εννοιας | E19: ενναιας | H19: Yes | J19: Substitution - Word | T19: NA | U19: =IF(ISNUMBER(T19),VALUE(MID(_xlfn.FORMULATEXT(T19),SEARCH("-",_xlfn.FORMULATEXT(T19))+1,LEN(_xlfn.FORMULATEXT(T19))-SEARCH("-",_xlfn.FORMULATEXT(T19)))), "") | V19: =IF(ISNUMBER(T19), VALUE(MID(_xlfn.FORMULATEXT(T19), 2, SEARCH("-", _xlfn.FORMULATEXT(T19)) - 2)), "") | AB19: Yes | AF19: Generated - strict
A20: TReub.4.8 | D20: εκαθαιρισεν | E20: εκαθαρισεν | J20: Substitution - Word | T20: NA | U20: =IF(ISNUMBER(T20),VALUE(MID(_xlfn.FORMULATEXT(T20),SEARCH("-",_xlfn.FORMULATEXT(T20))+1,LEN(_xlfn.FORMULATEXT(T20))-SEARCH("-",_xlfn.FORMULATEXT(T20)))), "") | V20: =IF(ISNUMBER(T20), VALUE(MID(_xlfn.FORMULATEXT(T20), 2, SEARCH("-", _xlfn.FORMULATEXT(T20)) - 2)), "") | AB20: Yes | AF20: Removed - strict
A21: TReub.4.10 | D21: των πρων μου | E21: των παρων πατερων μου | H21: Yes | I21: Frequency = παρειμι; contextual nonsense since the apparent participle would have to be singular and nominative | J21: Addition | K21: 0 | L21: 1 | M21: 5 | N21: Participle | O21: Present | P21: BD | Q21: 5 | S21: 3 | U21: =IF(ISNUMBER(T21),VALUE(MID(_xlfn.FORMULATEXT(T21),SEARCH("-",_xlfn.FORMULATEXT(T21))+1,LEN(_xlfn.FORMULATEXT(T21))-SEARCH("-",_xlfn.FORMULATEXT(T21)))), "") | V21: =IF(ISNUMBER(T21), VALUE(MID(_xlfn.FORMULATEXT(T21), 2, SEARCH("-", _xlfn.FORMULATEXT(T21)) - 2)), "") | AB21: Yes | AF21: Generated - contextual
A22: TReub.4.11 | D22: πορνεια την εννοιαν | E22: πορνεια την εννοιαν | F22: Not a variant, but correction is | H22: Yes | U22: =IF(ISNUMBER(T22),VALUE(MID(_xlfn.FORMULATEXT(T22),SEARCH("-",_xlfn.FORMULATEXT(T22))+1,LEN(_xlfn.FORMULATEXT(T22))-SEARCH("-",_xlfn.FORMULATEXT(T22)))), "") | V22: =IF(ISNUMBER(T22), VALUE(MID(_xlfn.FORMULATEXT(T22), 2, SEARCH("-", _xlfn.FORMULATEXT(T22)) - 2)), "")
A23: TReub.5.3 | D23: γυναικες ηττωνται τω πνι | E23: γυναικες τω πνευματι | J23: Omission | K23: 0 | L23: 1 | M23: 8 | N23: Verb | O23: Absent | S23: 3 | U23: =IF(ISNUMBER(T23),VALUE(MID(_xlfn.FORMULATEXT(T23),SEARCH("-",_xlfn.FORMULATEXT(T23))+1,LEN(_xlfn.FORMULATEXT(T23))-SEARCH("-",_xlfn.FORMULATEXT(T23)))), "") | V23: =IF(ISNUMBER(T23), VALUE(MID(_xlfn.FORMULATEXT(T23), 2, SEARCH("-", _xlfn.FORMULATEXT(T23)) - 2)), "") | AB23: Yes
A24: TReub.5.6 | D24: συνεχως ορωντες | E24: συνεχωςς ορωντες | J24: Substitution - Word | R24: Dittography | T24: ΝΑ | U24: =IF(ISNUMBER(T24),VALUE(MID(_xlfn.FORMULATEXT(T24),SEARCH("-",_xlfn.FORMULATEXT(T24))+1,LEN(_xlfn.FORMULATEXT(T24))-SEARCH("-",_xlfn.FORMULATEXT(T24)))), "") | V24: =IF(ISNUMBER(T24), VALUE(MID(_xlfn.FORMULATEXT(T24), 2, SEARCH("-", _xlfn.FORMULATEXT(T24)) - 2)), "") | AB24: Yes | AF24: Generated - strict
A25: TReub.5.7 | D25: κακεινοι επιθυμουσαι | E25: κακειναι επιθυμουσαι | H25: Yes | J25: Substitution - Form | U25: =IF(ISNUMBER(T25),VALUE(MID(_xlfn.FORMULATEXT(T25),SEARCH("-",_xlfn.FORMULATEXT(T25))+1,LEN(_xlfn.FORMULATEXT(T25))-SEARCH("-",_xlfn.FORMULATEXT(T25)))), "") | V25: =IF(ISNUMBER(T25), VALUE(MID(_xlfn.FORMULATEXT(T25), 2, SEARCH("-", _xlfn.FORMULATEXT(T25)) - 2)), "") | AB25: Yes | AF25: Removed - contextual
A26: TReub.5.7 | D26: διανοια τας φαντασιας | E26: διανοια τας φαντασιας | F26: Not a variant, but correction is | I26: O.4.24 corrects τας -> της | U26: =IF(ISNUMBER(T26),VALUE(MID(_xlfn.FORMULATEXT(T26),SEARCH("-",_xlfn.FORMULATEXT(T26))+1,LEN(_xlfn.FORMULATEXT(T26))-SEARCH("-",_xlfn.FORMULATEXT(T26)))), "") | V26: =IF(ISNUMBER(T26), VALUE(MID(_xlfn.FORMULATEXT(T26), 2, SEARCH("-", _xlfn.FORMULATEXT(T26)) - 2)), "")
A27: TReub.6.2 | D27: συνδυαζειν | E27: συνδυαζειν | F27: Not a variant, but correction is | I27: O.4.24 corrects to συνδοιαζειν | U27: =IF(ISNUMBER(T27),VALUE(MID(_xlfn.FORMULATEXT(T27),SEARCH("-",_xlfn.FORMULATEXT(T27))+1,LEN(_xlfn.FORMULATEXT(T27))-SEARCH("-",_xlfn.FORMULATEXT(T27)))), "") | V27: =IF(ISNUMBER(T27), VALUE(MID(_xlfn.FORMULATEXT(T27), 2, SEARCH("-", _xlfn.FORMULATEXT(T27)) - 2)), "")
A28: TReub.6.3 | D28: πραχθη | E28: πρασχθη | H28: Yes | J28: Substitution - Word | T28: NA | U28: =IF(ISNUMBER(T28),VALUE(MID(_xlfn.FORMULATEXT(T28),SEARCH("-",_xlfn.FORMULATEXT(T28))+1,LEN(_xlfn.FORMULATEXT(T28))-SEARCH("-",_xlfn.FORMULATEXT(T28)))), "") | V28: =IF(ISNUMBER(T28), VALUE(MID(_xlfn.FORMULATEXT(T28), 2, SEARCH("-", _xlfn.FORMULATEXT(T28)) - 2)), "") | AB28: Yes | AF28: Generated - strict
A29: TReub.6.5 | D29: δυνησεσθε | E29: δυνησασθε | H29: Yes | J29: Substitution - Form | U29: =IF(ISNUMBER(T29),VALUE(MID(_xlfn.FORMULATEXT(T29),SEARCH("-",_xlfn.FORMULATEXT(T29))+1,LEN(_xlfn.FORMULATEXT(T29))-SEARCH("-",_xlfn.FORMULATEXT(T29)))), "") | V29: =IF(ISNUMBER(T29), VALUE(MID(_xlfn.FORMULATEXT(T29), 2, SEARCH("-", _xlfn.FORMULATEXT(T29)) - 2)), "") | AB29: Yes | AF29: Generated - strict
A30: TReub.6.6 | D30: ο γαρ θς | E30: ου γαρ θεος | H30: Yes | J30: Substitution - Word | T30: =204-2475 -> -2271 | U30: =IF(ISNUMBER(T30),VALUE(MID(_xlfn.FORMULATEXT(T30),SEARCH("-",_xlfn.FORMULATEXT(T30))+1,LEN(_xlfn.FORMULATEXT(T30))-SEARCH("-",_xlfn.FORMULATEXT(T30)))), "") -> 2475 | V30: =IF(ISNUMBER(T30), VALUE(MID(_xlfn.FORMULATEXT(T30), 2, SEARCH("-", _xlfn.FORMULATEXT(T30)) - 2)), "") -> 204 | AB30: Yes
A31: TReub.6.6 | D31: πονρω | E31: πονρω | F31: Not a variant, but correction is | I31: O.4.24 corrects to πονηρω | U31: =IF(ISNUMBER(T31),VALUE(MID(_xlfn.FORMULATEXT(T31),SEARCH("-",_xlfn.FORMULATEXT(T31))+1,LEN(_xlfn.FORMULATEXT(T31))-SEARCH("-",_xlfn.FORMULATEXT(T31)))), "") | V31: =IF(ISNUMBER(T31), VALUE(MID(_xlfn.FORMULATEXT(T31), 2, SEARCH("-", _xlfn.FORMULATEXT(T31)) - 2)), "")
A32: TReub.6.7 | D32: μετ αυτων | E32: μετ αυτων | F32: Not a variant, but correction is | I32: O.4.24 corrects to μετ αυτον | U32: =IF(ISNUMBER(T32),VALUE(MID(_xlfn.FORMULATEXT(T32),SEARCH("-",_xlfn.FORMULATEXT(T32))+1,LEN(_xlfn.FORMULATEXT(T32))-SEARCH("-",_xlfn.FORMULATEXT(T32)))), "") | V32: =IF(ISNUMBER(T32), VALUE(MID(_xlfn.FORMULATEXT(T32), 2, SEARCH("-", _xlfn.FORMULATEXT(T32)) - 2)), "")
A33: TReub.6.7 | D33: καμοι | E33: καεμοι | H33: Yes | J33: Substitution - Form | U33: =IF(ISNUMBER(T33),VALUE(MID(_xlfn.FORMULATEXT(T33),SEARCH("-",_xlfn.FORMULATEXT(T33))+1,LEN(_xlfn.FORMULATEXT(T33))-SEARCH("-",_xlfn.FORMULATEXT(T33)))), "") | V33: =IF(ISNUMBER(T33), VALUE(MID(_xlfn.FORMULATEXT(T33), 2, SEARCH("-", _xlfn.FORMULATEXT(T33)) - 2)), "") | AB33: Yes
A34: TReub.6.7 | D34: ειναι επι αρχοντας | E34: ειναι επι αρχοντας | F34: Not a variant, but correction is | I34: O.4.24 corrects επι -> εις | U34: =IF(ISNUMBER(T34),VALUE(MID(_xlfn.FORMULATEXT(T34),SEARCH("-",_xlfn.FORMULATEXT(T34))+1,LEN(_xlfn.FORMULATEXT(T34))-SEARCH("-",_xlfn.FORMULATEXT(T34)))), "") | V34: =IF(ISNUMBER(T34), VALUE(MID(_xlfn.FORMULATEXT(T34), 2, SEARCH("-", _xlfn.FORMULATEXT(T34)) - 2)), "")
A35: TReub.6.8 | D35: διαστελλει | E35: διαστελλει | F35: Not a variant, but correction is | I35: O.4.24 corrects to διαστελει | U35: =IF(ISNUMBER(T35),VALUE(MID(_xlfn.FORMULATEXT(T35),SEARCH("-",_xlfn.FORMULATEXT(T35))+1,LEN(_xlfn.FORMULATEXT(T35))-SEARCH("-",_xlfn.FORMULATEXT(T35)))), "") | V35: =IF(ISNUMBER(T35), VALUE(MID(_xlfn.FORMULATEXT(T35), 2, SEARCH("-", _xlfn.FORMULATEXT(T35)) - 2)), "")
A36: TReub.6.8 | D36: και θυσιας υπερ | E36: και θυσιας υπερ | F36: Not a variant, but correction is | I36: O.4.24 corrects θυσιας -> θυμιασει | U36: =IF(ISNUMBER(T36),VALUE(MID(_xlfn.FORMULATEXT(T36),SEARCH("-",_xlfn.FORMULATEXT(T36))+1,LEN(_xlfn.FORMULATEXT(T36))-SEARCH("-",_xlfn.FORMULATEXT(T36)))), "") | V36: =IF(ISNUMBER(T36), VALUE(MID(_xlfn.FORMULATEXT(T36), 2, SEARCH("-", _xlfn.FORMULATEXT(T36)) - 2)), "")
A37: TReub.6.8 | D37: τελειωσεως | E37: τελεωσεως | H37: Yes | I37: LSJ indicates both spellings as alternatives | J37: Substitution - Form | U37: =IF(ISNUMBER(T37),VALUE(MID(_xlfn.FORMULATEXT(T37),SEARCH("-",_xlfn.FORMULATEXT(T37))+1,LEN(_xlfn.FORMULATEXT(T37))-SEARCH("-",_xlfn.FORMULATEXT(T37)))), "") | V37: =IF(ISNUMBER(T37), VALUE(MID(_xlfn.FORMULATEXT(T37), 2, SEARCH("-", _xlfn.FORMULATEXT(T37)) - 2)), "") | AB37: Yes
A38: TReub.6.9 | D38: εκαστος προς | E38: εκαστος προς | F38: Not a variant, but correction is | I38: O.4.24 corrects εκαστος -> εκαστον | U38: =IF(ISNUMBER(T38),VALUE(MID(_xlfn.FORMULATEXT(T38),SEARCH("-",_xlfn.FORMULATEXT(T38))+1,LEN(_xlfn.FORMULATEXT(T38))-SEARCH("-",_xlfn.FORMULATEXT(T38)))), "") | V38: =IF(ISNUMBER(T38), VALUE(MID(_xlfn.FORMULATEXT(T38), 2, SEARCH("-", _xlfn.FORMULATEXT(T38)) - 2)), "")
A39: TSim.1.1 | D39: συμεων α ελαλησε | E39: συμεων α ελαλησε | F39: Not a variant, but correction is | I39: O.4.24 corrects α -> ων | U39: =IF(ISNUMBER(T39),VALUE(MID(_xlfn.FORMULATEXT(T39),SEARCH("-",_xlfn.FORMULATEXT(T39))+1,LEN(_xlfn.FORMULATEXT(T39))-SEARCH("-",_xlfn.FORMULATEXT(T39)))), "") | V39: =IF(ISNUMBER(T39), VALUE(MID(_xlfn.FORMULATEXT(T39), 2, SEARCH("-", _xlfn.FORMULATEXT(T39)) - 2)), "")
A40: TSim.1.1 | D40: εικοστω επι της ζωης | E40: εικοστω ετει της ζωης | F40: Apograph transcript error, but still a variant | G40: Yes | I40: O.4.24 firsthand = ετι; Ff 1.24 corrects/gives an alternate reading ετει | J40: Substitution - Word | T40: =52-166 -> -114 | U40: =IF(ISNUMBER(T40),VALUE(MID(_xlfn.FORMULATEXT(T40),SEARCH("-",_xlfn.FORMULATEXT(T40))+1,LEN(_xlfn.FORMULATEXT(T40))-SEARCH("-",_xlfn.FORMULATEXT(T40)))), "") -> 166 | V40: =IF(ISNUMBER(T40), VALUE(MID(_xlfn.FORMULATEXT(T40), 2, SEARCH("-", _xlfn.FORMULATEXT(T40)) - 2)), "") -> 52 | AB40: Yes
...

Sheet Gen-filters
A1: Verse Ref | B1: Autograph | C1: Apograph | D1: Exclusion Grounds | E1: Corrector Followed | F1: Apograph Corrected | G1: Basic Type | H1: Phrase Length | I1: Words Length | J1: Letters Length | K1: Speech Part Add/Omitted | L1: Visual Cues | M1: Cue Regions | N1: Cue Length | O1: Duplicate Material | P1: AO Word Frequency | Q1: SUB Frequency Difference | R1: SUB_Aut_Freq | S1: SUB_Apog_Freq | T1: Harmonization - Context | U1: Parallel Present | V1: Harmonization - Parallel | W1: Singularity | X1: Singular Type | Y1: Secondary | Z1: Minutiae | AA1: Orthographic - General | AB1: Mere Minutiae | AC1: Nonsense | AD1: Review | AE1: Oo.VI.91.8 Dual?
A2: TReub.1.7 | B2: ει μη ιακωβ ο πηρ ημων προσηυξατο | C2: ει μη ιακωβ προσηυξατο | F2: Yes | G2: Omission | H2: 0 | I2: 3 | J2: 8 | L2: Absent | P2: 146 | Y2: Yes
A3: TReub.1.10 | B3: και παν αρτον | C3: και παντα αρτον | G3: Substitution - Form | Y3: Yes
A4: TReub.3.1 | B4: και εικων του θανατου | C4: και εικη εικων του θανατου | F4: Yes | G4: Addition | H4: 0 | I4: 1 | J4: 4 | K4: Verb | L4: Present | M4: BD | N4: 3 | P4: 0 | Y4: Yes
A5: TReub.3.7 | B5: το πνα του υπνου | C5: το πνευμα το υπνου | G5: Substitution - Form | T5: Disharmonizing | Y5: Yes
A6: TReub.4.4 | B6: παρελθη | C6: παρεθη | F6: Yes | G6: Substitution - Word | Q6: -4 | R6: 4 | S6: 0 | Y6: Yes
A7: TReub.4.6 | B7: εστιν η πορνεια | C7: εστιν πορνεια | F7: Yes | G7: Omission | H7: 0 | I7: 1 | J7: 1 | K7: Article | L7: NA | P7: 2475 | Y7: Yes
A8: TReub.5.3 | B8: γυναικες ηττωνται τω πνι | C8: γυναικες τω πνευματι | G8: Omission | H8: 0 | I8: 1 | J8: 8 | K8: Verb | L8: Absent | P8: 3 | Y8: Yes
A9: TReub.6.6 | B9: ο γαρ θς | C9: ου γαρ θεος | F9: Yes | G9: Substitution - Word | Q9: -2271 | R9: 2475 | S9: 204 | Y9: Yes
A10: TReub.6.7 | B10: καμοι | C10: καεμοι | F10: Yes | G10: Substitution - Form | Y10: Yes
A11: TReub.6.8 | B11: τελειωσεως | C11: τελεωσεως | F11: Yes | G11: Substitution - Form | Y11: Yes
A12: TSim.4.8 | B12: ανοις ενεργειν | C12: ανθρωποις συνεργειν | F12: Yes | G12: Substitution - Word | Q12: 3 | R12: 3 | S12: 6 | Y12: Yes
A13: TSim.6.2 | B13: αφ υμων τον φθονον | C13: αφ υμων φθονον | G13: Omission | H13: 0 | I13: 1 | J13: 3 | K13: Article | L13: Absent | P13: 2475 | Y13: Yes
A14: TLev.2.5 | B14: αβελμαουλ | C14: αβελβαουλ | G14: Substitution - Word | Q14: -2 | R14: 2 | S14: 0 | Y14: Yes
A15: TLev.4.2 | B15: ουν ο υψιστος | C15: ουν υψιστος | G15: Omission | H15: 0 | I15: 1 | J15: 1 | K15: Article | L15: NA | P15: 2475 | Y15: Yes
A16: TLev.5.1 | B16: επι θρονου δοξης | C16: επι θρονον δοξης | F16: Yes | G16: Substitution - Form | Y16: Yes
A17: TLev.5.2 | B17: παροικησω εμμεσω | C17: παροικηση εμμεσω | F17: Yes | G17: Substitution - Form | Y17: Yes
A18: TLev.7.2 | B18: ωσει τις χλευασαι | C18: ως εις τις χλευασει | F18: Yes | G18: Substitution - Word | Q18: -28 | R18: 31 | S18: 3 | Y18: Yes
A19: TLev.14.8 | B19: αγια εν καταφρονησει | C19: αγια και εν καταφρονησει | F19: Yes | G19: Addition | H19: 0 | I19: 1 | J19: 3 | K19: Conjunction | L19: Absent | P19: 1701 | Y19: Yes
A20: TLev.18.6 | B20: φωνης πρικης | C20: φωνης πνευματικης | F20: Yes | G20: Substitution - Word | Q20: 0 | R20: 0 | S20: 0 | Y20: Yes
A21: TLev.18.7 | B21: δοξα υψιστου επ αυτον ρηθησεται | C21: δοξα υψιστω επ αυτον ρηθησεται | F21: Yes | G21: Substitution - Form | Y21: Yes
A22: TJud.1.5 | B22: αδελφην της μρς | C22: αδελφην μου της μρς | F22: Yes | G22: Addition | H22: 0 | I22: 1 | J22: 3 | K22: Pronoun | L22: Absent | P22: 743 | Y22: Yes
A23: TJud.2.7 | B23: και εν κυκλω συσσεισας και | C23: και εγκυκλωσις σεισας και | F23: Yes | G23: Substitution - Word | Q23: 0 | R23: 0 | S23: 0 | Y23: Yes
A24: TJud.3.1 | B24: κνιμιδας κρουσας κατεσπασα | C24: κνιμιδας κατεσπασα | F24: Yes | G24: Omission | H24: 0 | I24: 1 | J24: 7 | K24: Participle | L24: Present | M24: AB:AC | N24: 3:3 | P24: 0 | Y24: Yes
A25: TJud.3.3 | B25: λιθον λιτρων ξ | C25: λιθον ξ | F25: Yes | G25: Omission | H25: 0 | I25: 1 | J25: 6 | K25: Noun | L25: Present | M25: AB:AC | N25: 3:3 | P25: 0 | Y25: Yes
A26: TJud.3.3 | B26: ιππω και απεκτεινα αυτον | C26: ιππω απεκτεινα αυτον | F26: Yes | G26: Omission | H26: 0 | I26: 1 | J26: 3 | K26: Conjunction | L26: Absent | P26: 1700 | Y26: Yes
A27: TJud.3.5 | B27: εν δε τω εκδυειν με αυτου τον θωρακα | C27: εν δε τω εκδυειν με τον θωρακα | F27: Yes | G27: Omission | H27: 0 | I27: 1 | J27: 5 | K27: Pronoun | L27: Absent | P27: 829 | Y27: Yes
A28: TJud.3.6 | B28: χειρι μου λιθοις σφενδωνισας | C28: χειρι μου σφενδωνισας | G28: Omission | H28: 0 | I28: 1 | J28: 6 | K28: Noun | L28: Absent | P28: 6 | Y28: Yes
A29: TJud.5.7 | B29: ενεπρισαμεν παντα τα εν αυτη | C29: ενεπρησαμεν και παντα εν αυτη | G29: Omission | H29: 0 | I29: 1 | J29: 2 | K29: Article | L29: NA | P29: 2475 | Y29: Yes
A30: TJud.6.2 | B30: συνηψαμεν αυτους και | C30: συνηψαμεν αυτους αυτους και | F30: Yes | G30: Addition | H30: 0 | I30: 1 | J30: 6 | K30: Pronoun | L30: Present | M30: AB:AC | N30: 6:6 | O30: Dittography | P30: 830 | Y30: Yes
A31: TJud.9.2 | B31: πληρωθεντων δεκα οκτω | C31: πληρωθεντων των δεκαοκτω | G31: Addition | H31: 0 | I31: 1 | J31: 3 | K31: Article | L31: Present | M31: AB:AC | N31: 3:3 | O31: Dittography | P31: 2475 | Y31: Yes
A32: TJud.12.3 | B32: υδασι | C32: υδατι | F32: Yes | G32: Substitution - Form | Y32: Yes
A33: TJud.14.8 | B33: ποιει το πνα | C33: ποιει πνευμα | F33: Yes | G33: Omission | H33: 0 | I33: 1 | J33: 2 | K33: Article | L33: NA | P33: 2474 | Y33: Yes
A34: TJud.18.6 | B34: δυο γαρ παθη εναντια των εντολων | C34: δυσι γαρ παθη εναντια των εντελων | G34: Substitution - Word | Q34: -34 | R34: 34 | S34: 0 | Y34: Yes
A35: TJud.21.4 | B35: υπερεχει ουνος | C35: υπερεχει ο ουρανος | F35: Yes | G35: Addition | H35: 0 | I35: 1 | J35: 1 | K35: Article | L35: NA | O35: Dittography | P35: 2475 | Y35: Yes
A36: TJud.21.7 | B36: καταπινοντες ανους ως ιχθυας | C36: καταπινοντες ανους ανους ως ιχθυας | F36: Yes | G36: Addition | H36: 0 | I36: 1 | J36: 5 | K36: Noun | L36: Present | M36: AB:AC | N36: 5:5 | O36: Dittography | P36: 98 | Y36: Yes
A37: TJud.24.2 | B37: εκχεαι πνς ευλογιαν πρς | C37: εκχεαι πνα ευλογιας πρς | G37: Substitution - Form | Y37: Yes
A38: TJud.24.2 | B38: εκχεαι πνς ευλογιαν πρς | C38: εκχεαι πνα ευλογιας πρς | G38: Substitution - Form | Y38: Yes
A39: TIss.5.1 | B39: περιεργαζομενοι εντολας κυ | C39: περιεργαζομενοι νομον κυ | F39: Yes | G39: Substitution - Both | Q39: 4 | R39: 34 | S39: 38 | Y39: Yes
A40: TIss.6.3 | B40: οπως εαν | C40: οπως α εαν | F40: Yes | G40: Addition | H40: 0 | I40: 1 | J40: 1 | K40: Pronoun | L40: NA | P40: 99 | Y40: Yes
...

Sheet AddOmits
A1: Verse Ref | B1: Autograph | C1: Apograph | D1: Exclusion Grounds | E1: Corrector Followed | F1: Apograph Corrected | G1: Basic Type | H1: Phrase Length | I1: Words Length | J1: Letters Length | K1: Speech Part Add/Omitted | L1: Visual Cues | M1: Cue Regions | N1: Cue Length | O1: Duplicate Material | P1: AO Word Frequency | Q1: Freq-per-10000 | R1: SUB Frequency Difference | S1: Harmonization - Context | T1: Parallel Present | U1: Harmonization - Parallel | V1: Singularity | W1: Singular Type | X1: Secondary | Y1: Minutiae | Z1: Orthographic - General | AA1: Mere Minutiae | AB1: Nonsense | AC1: Review
A2: TReub.1.7 | B2: ει μη ιακωβ ο πηρ ημων προσηυξατο | C2: ει μη ιακωβ προσηυξατο | F2: Yes | G2: Omission | H2: 0 | I2: 3 | J2: 8 | L2: Absent | P2: 146 | Q2: =IF(ISNUMBER(P2), (P2/$F$82)*10000, "") -> 71.786803 | Z2: Yes
A3: TReub.3.1 | B3: και εικων του θανατου | C3: και εικη εικων του θανατου | F3: Yes | G3: Addition | H3: 0 | I3: 1 | J3: 4 | K3: Verb | L3: Present | M3: BD | N3: 3 | P3: 0 | Q3: =IF(ISNUMBER(P3), (P3/$F$82)*10000, "") -> 0 | Z3: Yes
A4: TReub.4.6 | B4: εστιν η πορνεια | C4: εστιν πορνεια | F4: Yes | G4: Omission | H4: 0 | I4: 1 | J4: 1 | K4: Article | L4: NA | P4: 2475 | Q4: =IF(ISNUMBER(P4), (P4/$F$82)*10000, "") -> 1216.9338 | Z4: Yes
A5: TReub.5.3 | B5: γυναικες ηττωνται τω πνι | C5: γυναικες τω πνευματι | G5: Omission | H5: 0 | I5: 1 | J5: 8 | K5: Verb | L5: Absent | P5: 3 | Q5: =IF(ISNUMBER(P5), (P5/$F$82)*10000, "") -> 1.4750713 | Z5: Yes
A6: TSim.6.2 | B6: αφ υμων τον φθονον | C6: αφ υμων φθονον | G6: Omission | H6: 0 | I6: 1 | J6: 3 | K6: Article | L6: Absent | P6: 2475 | Q6: =IF(ISNUMBER(P6), (P6/$F$82)*10000, "") -> 1216.9338 | Z6: Yes
A7: TLev.4.2 | B7: ουν ο υψιστος | C7: ουν υψιστος | G7: Omission | H7: 0 | I7: 1 | J7: 1 | K7: Article | L7: NA | P7: 2475 | Q7: =IF(ISNUMBER(P7), (P7/$F$82)*10000, "") -> 1216.9338 | Z7: Yes
A8: TLev.14.8 | B8: αγια εν καταφρονησει | C8: αγια και εν καταφρονησει | F8: Yes | G8: Addition | H8: 0 | I8: 1 | J8: 3 | K8: Conjunction | L8: Absent | P8: 1701 | Q8: =IF(ISNUMBER(P8), (P8/$F$82)*10000, "") -> 836.36542 | Z8: Yes
A9: TJud.1.5 | B9: αδελφην της μρς | C9: αδελφην μου της μρς | F9: Yes | G9: Addition | H9: 0 | I9: 1 | J9: 3 | K9: Pronoun | L9: Absent | P9: 743 | Q9: =IF(ISNUMBER(P9), (P9/$F$82)*10000, "") -> 365.32599 | Z9: Yes
A10: TJud.3.1 | B10: κνιμιδας κρουσας κατεσπασα | C10: κνιμιδας κατεσπασα | F10: Yes | G10: Omission | H10: 0 | I10: 1 | J10: 7 | K10: Participle | L10: Present | M10: AB:AC | N10: 3:3 | P10: 0 | Q10: =IF(ISNUMBER(P10), (P10/$F$82)*10000, "") -> 0 | Z10: Yes
A11: TJud.3.3 | B11: λιθον λιτρων ξ | C11: λιθον ξ | F11: Yes | G11: Omission | H11: 0 | I11: 1 | J11: 6 | K11: Noun | L11: Present | M11: AB:AC | N11: 3:3 | P11: 0 | Q11: =IF(ISNUMBER(P11), (P11/$F$82)*10000, "") -> 0 | Z11: Yes
A12: TJud.3.3 | B12: ιππω και απεκτεινα αυτον | C12: ιππω απεκτεινα αυτον | F12: Yes | G12: Omission | H12: 0 | I12: 1 | J12: 3 | K12: Conjunction | L12: Absent | P12: 1700 | Q12: =IF(ISNUMBER(P12), (P12/$F$82)*10000, "") -> 835.87373 | Z12: Yes
A13: TJud.3.5 | B13: εν δε τω εκδυειν με αυτου τον θωρακα | C13: εν δε τω εκδυειν με τον θωρακα | F13: Yes | G13: Omission | H13: 0 | I13: 1 | J13: 5 | K13: Pronoun | L13: Absent | P13: 829 | Q13: =IF(ISNUMBER(P13), (P13/$F$82)*10000, "") -> 407.61137 | Z13: Yes
A14: TJud.3.6 | B14: χειρι μου λιθοις σφενδωνισας | C14: χειρι μου σφενδωνισας | G14: Omission | H14: 0 | I14: 1 | J14: 6 | K14: Noun | L14: Absent | P14: 6 | Q14: =IF(ISNUMBER(P14), (P14/$F$82)*10000, "") -> 2.9501426 | Z14: Yes
A15: TJud.5.7 | B15: ενεπρισαμεν παντα τα εν αυτη | C15: ενεπρησαμεν και παντα εν αυτη | G15: Omission | H15: 0 | I15: 1 | J15: 2 | K15: Article | L15: NA | P15: 2475 | Q15: =IF(ISNUMBER(P15), (P15/$F$82)*10000, "") -> 1216.9338 | Z15: Yes
A16: TJud.6.2 | B16: συνηψαμεν αυτους και | C16: συνηψαμεν αυτους αυτους και | F16: Yes | G16: Addition | H16: 0 | I16: 1 | J16: 6 | K16: Pronoun | L16: Present | M16: AB:AC | N16: 6:6 | O16: Dittography | P16: 830 | Q16: =IF(ISNUMBER(P16), (P16/$F$82)*10000, "") -> 408.10306 | Z16: Yes
A17: TJud.9.2 | B17: πληρωθεντων δεκα οκτω | C17: πληρωθεντων των δεκαοκτω | G17: Addition | H17: 0 | I17: 1 | J17: 3 | K17: Article | L17: Present | M17: AB:AC | N17: 3:3 | O17: Dittography | P17: 2475 | Q17: =IF(ISNUMBER(P17), (P17/$F$82)*10000, "") -> 1216.9338 | Z17: Yes
A18: TJud.14.8 | B18: ποιει το πνα | C18: ποιει πνευμα | F18: Yes | G18: Omission | H18: 0 | I18: 1 | J18: 2 | K18: Article | L18: NA | P18: 2474 | Q18: =IF(ISNUMBER(P18), (P18/$F$82)*10000, "") -> 1216.4421 | Z18: Yes
A19: TJud.21.4 | B19: υπερεχει ουνος | C19: υπερεχει ο ουρανος | F19: Yes | G19: Addition | H19: 0 | I19: 1 | J19: 1 | K19: Article | L19: NA | O19: Dittography | P19: 2475 | Q19: =IF(ISNUMBER(P19), (P19/$F$82)*10000, "") -> 1216.9338 | Z19: Yes
A20: TJud.21.7 | B20: καταπινοντες ανους ως ιχθυας | C20: καταπινοντες ανους ανους ως ιχθυας | F20: Yes | G20: Addition | H20: 0 | I20: 1 | J20: 5 | K20: Noun | L20: Present | M20: AB:AC | N20: 5:5 | O20: Dittography | P20: 98 | Q20: =IF(ISNUMBER(P20), (P20/$F$82)*10000, "") -> 48.185662 | Z20: Yes
A21: TIss.6.3 | B21: οπως εαν | C21: οπως α εαν | F21: Yes | G21: Addition | H21: 0 | I21: 1 | J21: 1 | K21: Pronoun | L21: NA | P21: 99 | Q21: =IF(ISNUMBER(P21), (P21/$F$82)*10000, "") -> 48.677353 | Z21: Yes
A22: TNaph.2.3 | B22: τριχος σταθμω | C22: τριχος και σταθμω | F22: Yes | G22: Addition | H22: 0 | I22: 1 | J22: 3 | K22: Conjunction | L22: Absent | P22: 1701 | Q22: =IF(ISNUMBER(P22), (P22/$F$82)*10000, "") -> 836.36542 | Z22: Yes
A23: TNaph.2.7 | B23: και ουκ εστιν | C23: και εστιν | G23: Omission | H23: 0 | I23: 1 | J23: 3 | K23: Particle | L23: Absent | P23: 204 | Q23: =IF(ISNUMBER(P23), (P23/$F$82)*10000, "") -> 100.30485 | Z23: Yes
A24: TNaph.7.2 | B24: αυτον μεθ υμων | C24: αυτον μεν μεθ υμων | F24: Yes | G24: Addition | H24: 0 | I24: 1 | J24: 3 | K24: Particle | L24: Absent | P24: 14 | Q24: =IF(ISNUMBER(P24), (P24/$F$82)*10000, "") -> 6.883666 | Z24: Yes
A25: TAsh.5.3 | B25: και ουκ εστιν | C25: και εστιν | F25: Yes | G25: Omission | H25: 0 | I25: 1 | J25: 3 | K25: Particle | L25: Absent | P25: 204 | Q25: =IF(ISNUMBER(P25), (P25/$F$82)*10000, "") -> 100.30485 | Z25: Yes
A26: TJos.7.1 | B26: ενεκειτο εις εμε | C26: ενεκειτο εμε | F26: Yes | G26: Omission | H26: 0 | I26: 1 | J26: 3 | K26: Preposition | L26: Absent | P26: 210 | Q26: =IF(ISNUMBER(P26), (P26/$F$82)*10000, "") -> 103.25499 | Z26: Yes
A27: TJos.19.12 | B27: βασιλεια αυτου βασιλεια αιωνος | C27: βασιλεια βασιλεια αιωνος | F27: Yes | G27: Omission | H27: 0 | I27: 1 | J27: 5 | K27: Pronoun | L27: Absent | P27: 830 | Q27: =IF(ISNUMBER(P27), (P27/$F$82)*10000, "") -> 408.10306 | Z27: Yes
A28: TBen.2.2 | B28: χιτωνα σου αιματι | C28: χιτωνα αιματι | G28: Omission | H28: 0 | I28: 1 | J28: 3 | K28: Pronoun | L28: Absent | P28: 312 | Q28: =IF(ISNUMBER(P28), (P28/$F$82)*10000, "") -> 153.40741 | Z28: Yes
A29: TBen.3.4 | B29: φοβου του θυ | C29: φοβου θυ | F29: Yes | G29: Omission | H29: 0 | I29: 1 | J29: 3 | K29: Article | L29: Absent | P29: 2475 | Q29: =IF(ISNUMBER(P29), (P29/$F$82)*10000, "") -> 1216.9338 | Z29: Yes
A30: TBen.12.1 | B30: και ως επληρωσε | C30: και επληρωσε | F30: Yes | G30: Omission | H30: 0 | I30: 1 | J30: 2 | K30: Adverb | L30: NA | P30: 129 | Q30: =IF(ISNUMBER(P30), (P30/$F$82)*10000, "") -> 63.428066 | Z30: Yes
E33: adds: | F33: =COUNTIF(G:G,"Addition") -> 10
B34: LM | C34: HM | E34: omits: | F34: =COUNTIF(G:G,"Omission") -> 19
B35: Article | C35: Adjective | E35: Add rate: | F35: =F33/(F33+F34) -> 0.34482759
B36: Conjunction | C36: Adverb
B37: Pronoun | C37: Noun
B38: Preposition | C38: Participle | E38: LM-adds: | F38: =COUNTIFS(G:G,"Addition", K:K,"Article")+COUNTIFS(G:G,"Addition", K:K,"Conjunction")+COUNTIFS(G:G,"Addition", K:K,"Pronoun")+COUNTIFS(G:G,"Addition", K:K,"Preposition")+COUNTIFS(G:G,"Addition", K:K,"Particle")+COUNTIFS(G:G,"Addition", K:K,"Vocative") -> 8
B39: Particle | C39: Verb | E39: LM-omits: | F39: =COUNTIFS(G:G,"Omission", K:K,"Article")+COUNTIFS(G:G,"Omission", K:K,"Conjunction")+COUNTIFS(G:G,"Omission", K:K,"Pronoun")+COUNTIFS(G:G,"Omission", K:K,"Preposition")+COUNTIFS(G:G,"Omission", K:K,"Particle")+COUNTIFS(G:G,"Omission", K:K,"Vocative") -> 13
B40: Vocative | E40: LM-add rate: | F40: =F38/(F38+F39) -> 0.38095238
E43: HM-adds: | F43: =COUNTIFS(G:G,"Addition", K:K,"Adjective")+COUNTIFS(G:G,"Addition", K:K,"Adverb")+COUNTIFS(G:G,"Addition", K:K,"Noun")+COUNTIFS(G:G,"Addition", K:K,"Participle")+COUNTIFS(G:G,"Addition", K:K,"Verb") -> 2
E44: HM-omits: | F44: =COUNTIFS(G:G,"Omission", K:K,"Adjective")+COUNTIFS(G:G,"Omission", K:K,"Adverb")+COUNTIFS(G:G,"Omission", K:K,"Noun")+COUNTIFS(G:G,"Omission", K:K,"Participle")+COUNTIFS(G:G,"Omission", K:K,"Verb") -> 5
...

Sheet WF_AO_LM
A1: Verse Ref | B1: Autograph | C1: Apograph | D1: Exclusion Grounds | E1: Corrector Followed | F1: Apograph Corrected | G1: Basic Type | H1: Phrase Length | I1: Words Length | J1: Letters Length | K1: Speech Part Add/Omitted | L1: Visual Cues | M1: Cue Regions | N1: Cue Length | O1: Duplicate Material | P1: AO Word Frequency | Q1: Freq-per-10000 | R1: SUB Frequency Difference | S1: Harmonization - Context | T1: Parallel Present | U1: Harmonization - Parallel | V1: Singularity | W1: Singular Type | X1: Secondary | Y1: Minutiae | Z1: Orthographic - General | AA1: Mere Minutiae | AB1: Nonsense | AC1: Review
A2: TReub.4.6 | B2: εστιν η πορνεια | C2: εστιν πορνεια | F2: Yes | G2: Omission | H2: 0 | I2: 1 | J2: 1 | K2: Article | L2: NA | P2: 2475 | Q2: 1216.9338 | Z2: Yes
A3: TSim.6.2 | B3: αφ υμων τον φθονον | C3: αφ υμων φθονον | G3: Omission | H3: 0 | I3: 1 | J3: 3 | K3: Article | L3: Absent | P3: 2475 | Q3: 1216.9338 | Z3: Yes
A4: TLev.4.2 | B4: ουν ο υψιστος | C4: ουν υψιστος | G4: Omission | H4: 0 | I4: 1 | J4: 1 | K4: Article | L4: NA | P4: 2475 | Q4: 1216.9338 | Z4: Yes
A5: TLev.14.8 | B5: αγια εν καταφρονησει | C5: αγια και εν καταφρονησει | F5: Yes | G5: Addition | H5: 0 | I5: 1 | J5: 3 | K5: Conjunction | L5: Absent | P5: 1701 | Q5: 836.36542 | Z5: Yes
A6: TJud.1.5 | B6: αδελφην της μρς | C6: αδελφην μου της μρς | F6: Yes | G6: Addition | H6: 0 | I6: 1 | J6: 3 | K6: Pronoun | L6: Absent | P6: 743 | Q6: 365.32599 | Z6: Yes
A7: TJud.3.3 | B7: ιππω και απεκτεινα αυτον | C7: ιππω απεκτεινα αυτον | F7: Yes | G7: Omission | H7: 0 | I7: 1 | J7: 3 | K7: Conjunction | L7: Absent | P7: 1700 | Q7: 835.87373 | Z7: Yes
A8: TJud.3.5 | B8: εν δε τω εκδυειν με αυτου τον θωρακα | C8: εν δε τω εκδυειν με τον θωρακα | F8: Yes | G8: Omission | H8: 0 | I8: 1 | J8: 5 | K8: Pronoun | L8: Absent | P8: 829 | Q8: 407.61137 | Z8: Yes
A9: TJud.5.7 | B9: ενεπρισαμεν παντα τα εν αυτη | C9: ενεπρησαμεν και παντα εν αυτη | G9: Omission | H9: 0 | I9: 1 | J9: 2 | K9: Article | L9: NA | P9: 2475 | Q9: 1216.9338 | Z9: Yes
A10: TJud.6.2 | B10: συνηψαμεν αυτους και | C10: συνηψαμεν αυτους αυτους και | F10: Yes | G10: Addition | H10: 0 | I10: 1 | J10: 6 | K10: Pronoun | L10: Present | M10: AB:AC | N10: 6:6 | O10: Dittography | P10: 830 | Q10: 408.10306 | Z10: Yes
A11: TJud.9.2 | B11: πληρωθεντων δεκα οκτω | C11: πληρωθεντων των δεκαοκτω | G11: Addition | H11: 0 | I11: 1 | J11: 3 | K11: Article | L11: Present | M11: AB:AC | N11: 3:3 | O11: Dittography | P11: 2475 | Q11: 1216.9338 | Z11: Yes
A12: TJud.14.8 | B12: ποιει το πνα | C12: ποιει πνευμα | F12: Yes | G12: Omission | H12: 0 | I12: 1 | J12: 2 | K12: Article | L12: NA | P12: 2474 | Q12: 1216.4421 | Z12: Yes
A13: TJud.21.4 | B13: υπερεχει ουνος | C13: υπερεχει ο ουρανος | F13: Yes | G13: Addition | H13: 0 | I13: 1 | J13: 1 | K13: Article | L13: NA | O13: Dittography | P13: 2475 | Q13: 1216.9338 | Z13: Yes
A14: TIss.6.3 | B14: οπως εαν | C14: οπως α εαν | F14: Yes | G14: Addition | H14: 0 | I14: 1 | J14: 1 | K14: Pronoun | L14: NA | P14: 99 | Q14: 48.677353 | Z14: Yes
A15: TNaph.2.3 | B15: τριχος σταθμω | C15: τριχος και σταθμω | F15: Yes | G15: Addition | H15: 0 | I15: 1 | J15: 3 | K15: Conjunction | L15: Absent | P15: 1701 | Q15: 836.36542 | Z15: Yes
A16: TNaph.2.7 | B16: και ουκ εστιν | C16: και εστιν | G16: Omission | H16: 0 | I16: 1 | J16: 3 | K16: Particle | L16: Absent | P16: 204 | Q16: 100.30485 | Z16: Yes
A17: TNaph.7.2 | B17: αυτον μεθ υμων | C17: αυτον μεν μεθ υμων | F17: Yes | G17: Addition | H17: 0 | I17: 1 | J17: 3 | K17: Particle | L17: Absent | P17: 14 | Q17: 6.883666 | Z17: Yes
A18: TAsh.5.3 | B18: και ουκ εστιν | C18: και εστιν | F18: Yes | G18: Omission | H18: 0 | I18: 1 | J18: 3 | K18: Particle | L18: Absent | P18: 204 | Q18: 100.30485 | Z18: Yes
A19: TJos.7.1 | B19: ενεκειτο εις εμε | C19: ενεκειτο εμε | F19: Yes | G19: Omission | H19: 0 | I19: 1 | J19: 3 | K19: Preposition | L19: Absent | P19: 210 | Q19: 103.25499 | Z19: Yes
A20: TJos.19.12 | B20: βασιλεια αυτου βασιλεια αιωνος | C20: βασιλεια βασιλεια αιωνος | F20: Yes | G20: Omission | H20: 0 | I20: 1 | J20: 5 | K20: Pronoun | L20: Absent | P20: 830 | Q20: 408.10306 | Z20: Yes
A21: TBen.2.2 | B21: χιτωνα σου αιματι | C21: χιτωνα αιματι | G21: Omission | H21: 0 | I21: 1 | J21: 3 | K21: Pronoun | L21: Absent | P21: 312 | Q21: 153.40741 | Z21: Yes
A22: TBen.3.4 | B22: φοβου του θυ | C22: φοβου θυ | F22: Yes | G22: Omission | H22: 0 | I22: 1 | J22: 3 | K22: Article | L22: Absent | P22: 2475 | Q22: 1216.9338 | Z22: Yes
D25: Words in corpus (Genesis - Deuteronomy) | E25: 20338
D26: Med-word-freq | E26: =MEDIAN(Q:Q) -> 835.87373
D29: HF-adds | E29: =COUNTIFS(G:G, "Addition", Q:Q, ">=" & $E$26) -> 4
D30: HF-omits | E30: =COUNTIFS(G:G, "Omission", Q:Q, ">=" & $E$26) -> 7
D31: HF-add-ratio | E31: =E29/(E29+E30) -> 0.36363636
D32: LF-adds | E32: =COUNTIFS(G:G, "Addition", Q:Q, "<" & $E$26) -> 4
D33: LF-omits | E33: =COUNTIFS(G:G, "Omission", Q:Q, "<" & $E$26) -> 6
D34: LF-add-ratio | E34: =E32/(E32+E33) -> 0.4
D37: art-adds | E37: =COUNTIFS(G:G, "Addition", K:K, "Article") -> 2
D38: art-omits | E38: =COUNTIFS(G:G, "Omission", K:K, "Article") -> 6
D39: art-add-rate | E39: =COUNTIFS(G:G, "Addition", K:K, "Article")/(COUNTIFS(G:G, "Addition", K:K, "Article") + COUNTIFS(G:G, "Omission", K:K, "Article")) -> 0.25

Sheet WF_AO_HM
A1: Verse Ref | B1: Autograph | C1: Apograph | D1: Exclusion Grounds | E1: Corrector Followed | F1: Apograph Corrected | G1: Detail | H1: Basic Type | I1: Phrase Length | J1: Words Length | K1: Letters Length | L1: Speech Part Add/Omitted | M1: Visual Cues | N1: Cue Regions | O1: Cue Length | P1: Duplicate Material | Q1: AO Word Frequency | R1: Freq-per-10000 | S1: SUB Frequency Difference | T1: Harmonization - Context | U1: Parallel Present | V1: Harmonization - Parallel | W1: Singularity | X1: Singular Type | Y1: Secondary | Z1: Minutiae | AA1: Orthographic - General | AB1: Mere Minutiae | AC1: Nonsense | AD1: Review
A2: TReub.3.1 | B2: και εικων του θανατου | C2: και εικη εικων του θανατου | F2: Yes | G2: Frequency based on εικω | H2: Addition | I2: 0 | J2: 1 | K2: 4 | L2: Verb | M2: Present | N2: BD | O2: 3 | Q2: 0 | R2: 0 | AA2: Yes
A3: TReub.5.3 | B3: γυναικες ηττωνται τω πνι | C3: γυναικες τω πνευματι | H3: Omission | I3: 0 | J3: 1 | K3: 8 | L3: Verb | M3: Absent | Q3: 3 | R3: 1.4750713 | AA3: Yes
A4: TJud.3.1 | B4: κνιμιδας κρουσας κατεσπασα | C4: κνιμιδας κατεσπασα | F4: Yes | G4: The verb κρουω occurs only here | H4: Omission | I4: 0 | J4: 1 | K4: 7 | L4: Participle | M4: Present | N4: AB:AC | O4: 3:3 | Q4: 0 | R4: 0 | AA4: Yes
A5: TJud.3.3 | B5: λιθον λιτρων ξ | C5: λιθον ξ | F5: Yes | G5: This is the only occurrence of this word | H5: Omission | I5: 0 | J5: 1 | K5: 6 | L5: Noun | M5: Present | N5: AB:AC | O5: 3:3 | Q5: 0 | R5: 0 | AA5: Yes
A6: TJud.3.6 | B6: χειρι μου λιθοις σφενδωνισας | C6: χειρι μου σφενδωνισας | H6: Omission | I6: 0 | J6: 1 | K6: 6 | L6: Noun | M6: Absent | Q6: 6 | R6: 2.9501426 | AA6: Yes
A7: TJud.21.7 | B7: καταπινοντες ανους ως ιχθυας | C7: καταπινοντες ανους ανους ως ιχθυας | F7: Yes | H7: Addition | I7: 0 | J7: 1 | K7: 5 | L7: Noun | M7: Present | N7: AB:AC | O7: 5:5 | P7: Dittography | Q7: 98 | R7: 48.185662 | AA7: Yes
A8: TBen.12.1 | B8: και ως επληρωσε | C8: και επληρωσε | F8: Yes | H8: Omission | I8: 0 | J8: 1 | K8: 2 | L8: Adverb | M8: NA | Q8: 129 | R8: 63.428066 | AA8: Yes
D11: Words in corpus (Genesis - Deuteronomy) | E11: 20338
D12: Med-word-freq | E12: =MEDIAN(R:R) -> 1.4750713
D15: HF-adds | E15: =COUNTIFS(H:H, "Addition", R:R, ">=" & $E$12) -> 1 | F15: not enough data
D16: HF-omits | E16: =COUNTIFS(H:H, "Omission", R:R, ">=" & $E$12) -> 3
D17: HF-add-ratio | E17: =E15/(E15+E16) -> 0.25
D18: LF-adds | E18: =COUNTIFS(H:H, "Addition", R:R, "<" & $E$12) -> 1
D19: LF-omits | E19: =COUNTIFS(H:H, "Omission", R:R, "<" & $E$12) -> 2
D20: LF-add-ratio | E20: =E18/(E18+E19) -> 0.33333333
D21: AddRatioDiff | E21: =E17-E20 -> -0.083333333

Sheet WF_SUB
A1: Verse Ref | B1: Autograph | C1: Apograph | D1: Exclusion Grounds | E1: Corrector Followed | F1: Apograph Corrected | G1: Detail | H1: Basic Type | I1: Phrase Length | J1: Words Length | K1: Letters Length | L1: Speech Part Add/Omitted | M1: Visual Cues | N1: Cue Regions | O1: Cue Length | P1: Duplicate Material | Q1: AO Word Frequency | R1: SUB Frequency Difference | S1: SUB_Aut_Freq | T1: SUB_Apog_Freq | U1: Aut_P10K_Freq | V1: Apog_P10K_Freq | W1: P10K_Freq_Diff | X1: Harmonization - Context | Y1: Parallel Present | Z1: Harmonization - Parallel | AA1: Singularity | AB1: Singular Type | AC1: Secondary | AD1: Minutiae | AE1: Orthographic - General | AF1: Mere Minutiae | AG1: Nonsense | AH1: Review
A2: TReub.4.4 | B2: παρελθη | C2: παρεθη | F2: Yes | G2: Frequency = παραθεω - παρερχομαι | H2: Substitution - Word | R2: -4 | S2: 4 | T2: 0 | U2: =IF(ISNUMBER(S2), (S2/$E$21)*10000, "") -> 1.9667617 | V2: =IF(ISNUMBER(T2), (T2/$E$21)*10000, "") -> 0 | W2: =IF(ISNUMBER(R2), V2-U2, "") -> -1.9667617 | AC2: Yes
A3: TReub.6.6 | B3: ο γαρ θς | C3: ου γαρ θεος | F3: Yes | H3: Substitution - Word | R3: -2271 | S3: 2475 | T3: 204 | U3: =IF(ISNUMBER(S3), (S3/$E$21)*10000, "") -> 1216.9338 | V3: =IF(ISNUMBER(T3), (T3/$E$21)*10000, "") -> 100.30485 | W3: =IF(ISNUMBER(R3), V3-U3, "") -> -1116.629 | AC3: Yes
A4: TSim.4.8 | B4: ανοις ενεργειν | C4: ανθρωποις συνεργειν | F4: Yes | H4: Substitution - Word | R4: 3 | S4: 3 | T4: 6 | U4: =IF(ISNUMBER(S4), (S4/$E$21)*10000, "") -> 1.4750713 | V4: =IF(ISNUMBER(T4), (T4/$E$21)*10000, "") -> 2.9501426 | W4: =IF(ISNUMBER(R4), V4-U4, "") -> 1.4750713 | AC4: Yes
A5: TLev.2.5 | B5: αβελμαουλ | C5: αβελβαουλ | H5: Substitution - Word | R5: -2 | S5: 2 | T5: 0 | U5: =IF(ISNUMBER(S5), (S5/$E$21)*10000, "") -> 0.98338086 | V5: =IF(ISNUMBER(T5), (T5/$E$21)*10000, "") -> 0 | W5: =IF(ISNUMBER(R5), V5-U5, "") -> -0.98338086 | AC5: Yes
A6: TLev.7.2 | B6: ωσει τις χλευασαι | C6: ως εις τις χλευασει | F6: Yes | G6: Frequency = ωσει - εις | H6: Substitution - Word | R6: -28 | S6: 31 | T6: 3 | U6: =IF(ISNUMBER(S6), (S6/$E$21)*10000, "") -> 15.242403 | V6: =IF(ISNUMBER(T6), (T6/$E$21)*10000, "") -> 1.4750713 | W6: =IF(ISNUMBER(R6), V6-U6, "") -> -13.767332 | AC6: Yes
A7: TLev.18.6 | B7: φωνης πρικης | C7: φωνης πνευματικης | F7: Yes | H7: Substitution - Word | R7: 0 | S7: 0 | T7: 0 | U7: =IF(ISNUMBER(S7), (S7/$E$21)*10000, "") -> 0 | V7: =IF(ISNUMBER(T7), (T7/$E$21)*10000, "") -> 0 | W7: =IF(ISNUMBER(R7), V7-U7, "") -> 0 | AC7: Yes
A8: TJud.2.7 | B8: και εν κυκλω συσσεισας και | C8: και εγκυκλωσις σεισας και | F8: Yes | G8: Frequency = εγκυκλωσις - κυκλος | H8: Substitution - Word | R8: 0 | S8: 0 | T8: 0 | U8: =IF(ISNUMBER(S8), (S8/$E$21)*10000, "") -> 0 | V8: =IF(ISNUMBER(T8), (T8/$E$21)*10000, "") -> 0 | W8: =IF(ISNUMBER(R8), V8-U8, "") -> 0 | AC8: Yes
A9: TJud.18.6 | B9: δυο γαρ παθη εναντια των εντολων | C9: δυσι γαρ παθη εναντια των εντελων | H9: Substitution - Word | R9: -34 | S9: 34 | T9: 0 | U9: =IF(ISNUMBER(S9), (S9/$E$21)*10000, "") -> 16.717475 | V9: =IF(ISNUMBER(T9), (T9/$E$21)*10000, "") -> 0 | W9: =IF(ISNUMBER(R9), V9-U9, "") -> -16.717475 | AC9: Yes
A10: TIss.5.1 | B10: περιεργαζομενοι εντολας κυ | C10: περιεργαζομενοι νομον κυ | F10: Yes | H10: Substitution - Both | R10: 4 | S10: 34 | T10: 38 | U10: =IF(ISNUMBER(S10), (S10/$E$21)*10000, "") -> 16.717475 | V10: =IF(ISNUMBER(T10), (T10/$E$21)*10000, "") -> 18.684236 | W10: =IF(ISNUMBER(R10), V10-U10, "") -> 1.9667617 | AC10: Yes
A11: TZeb.5.1 | B11: μου αναγγελω | C11: μου αγγελω | H11: Substitution - Word | R11: 6 | S11: 0 | T11: 6 | U11: =IF(ISNUMBER(S11), (S11/$E$21)*10000, "") -> 0 | V11: =IF(ISNUMBER(T11), (T11/$E$21)*10000, "") -> 2.9501426 | W11: =IF(ISNUMBER(R11), V11-U11, "") -> 2.9501426 | AC11: Yes
A12: TZeb.9.8 | B12: εκλεξηται | C12: εκλειψηται | F12: Yes | H12: Substitution - Word | R12: 0 | S12: 5 | T12: 5 | U12: =IF(ISNUMBER(S12), (S12/$E$21)*10000, "") -> 2.4584522 | V12: =IF(ISNUMBER(T12), (T12/$E$21)*10000, "") -> 2.4584522 | W12: =IF(ISNUMBER(R12), V12-U12, "") -> 0 | AC12: Yes
A13: TNaph.1.8 | B13: τας ευχας ραχηλ | C13: τας αρχας ραχηλ | F13: Yes | G13: Frequency = αρχη - ευχη | H13: Substitution - Word | R13: 0 | S13: 3 | T13: 3 | U13: =IF(ISNUMBER(S13), (S13/$E$21)*10000, "") -> 1.4750713 | V13: =IF(ISNUMBER(T13), (T13/$E$21)*10000, "") -> 1.4750713 | W13: =IF(ISNUMBER(R13), V13-U13, "") -> 0 | AC13: Yes
A14: TNaph.8.3 | B14: οφθησεται θς κατοικων | C14: οφθησεται κς κατοικων | H14: Substitution - Word | R14: 118 | S14: 132 | T14: 250 | U14: =IF(ISNUMBER(S14), (S14/$E$21)*10000, "") -> 64.903137 | V14: =IF(ISNUMBER(T14), (T14/$E$21)*10000, "") -> 122.92261 | W14: =IF(ISNUMBER(R14), V14-U14, "") -> 58.019471 | AC14: Yes
A15: TNaph.8.6 | B15: ο κς μισησει | C15: ο θς μισησει | H15: Substitution - Word | R15: -118 | S15: 250 | T15: 132 | U15: =IF(ISNUMBER(S15), (S15/$E$21)*10000, "") -> 122.92261 | V15: =IF(ISNUMBER(T15), (T15/$E$21)*10000, "") -> 64.903137 | W15: =IF(ISNUMBER(R15), V15-U15, "") -> -58.019471 | AC15: Yes
A16: TJos.12.3 | B16: μετ αυτου | C16: μετ εμου | F16: Yes | H16: Substitution - Word | R16: -87 | S16: 830 | T16: 743 | U16: =IF(ISNUMBER(S16), (S16/$E$21)*10000, "") -> 408.10306 | V16: =IF(ISNUMBER(T16), (T16/$E$21)*10000, "") -> 365.32599 | W16: =IF(ISNUMBER(R16), V16-U16, "") -> -42.777068 | AC16: Yes
A17: TBen.3.5 | B17: υπο επιβουλης | C17: υπο επιβολης | H17: Substitution - Word | R17: -1 | S17: 1 | T17: 0 | U17: =IF(ISNUMBER(S17), (S17/$E$21)*10000, "") -> 0.49169043 | V17: =IF(ISNUMBER(T17), (T17/$E$21)*10000, "") -> 0 | W17: =IF(ISNUMBER(R17), V17-U17, "") -> -0.49169043 | AC17: Yes
A18: TBen.8.3 | B18: ωσπερ γαρ ο ηλιος | C18: ωσπερ και ο ηλιος | F18: Yes | H18: Substitution - Word | R18: 1515 | S18: 186 | T18: 1701 | U18: =IF(ISNUMBER(S18), (S18/$E$21)*10000, "") -> 91.45442 | V18: =IF(ISNUMBER(T18), (T18/$E$21)*10000, "") -> 836.36542 | W18: =IF(ISNUMBER(R18), V18-U18, "") -> 744.911 | AC18: Yes
D21: Words in corpus (Genesis - Deuteronomy) | E21: 20338
D24: pos | E24: =COUNTIF(R:R, ">0") -> 5
D25: neg | E25: =COUNTIF(R:R, "<0") -> 8
D26: p = | E26: =_xlfn.BINOM.DIST(MIN(E24,E25),(E24+E25),0.5,TRUE)*2 -> 0.58105469
D28: avg_diff | E28: =AVERAGE(R:R) -> -52.882353
D29: stdv | E29: =_xlfn.STDEV.S(R:R) -> 682.02656
D32: avg_P10K_diff | E32: =AVERAGE(W:W) -> -26.001747
D33: P10K_stdv | E33: =_xlfn.STDEV.S(W:W) -> 335.34594
D36: total_subs | E36: =COUNT(W:W) -> 17
D37: std_dev | E37: =_xlfn.STDEV.P(W:W) -> 325.33334

Sheet Harmonization
A1: Verse Ref | B1: Autograph | C1: Apograph | D1: Exclusion Grounds | E1: Corrector Followed | F1: Apograph Corrected | G1: Detail | H1: Basic Type | I1: Phrase Length | J1: Words Length | K1: Letters Length | L1: Speech Part Add/Omitted | M1: Visual Cues | N1: Cue Regions | O1: Cue Length | P1: Duplicate Material | Q1: AO Word Frequency | R1: SUB Frequency Difference | S1: SUB_Aut_Freq | T1: SUB_Apog_Freq | U1: Harmonization - Context | V1: Harmonization_Direction | W1: Parallel Present | X1: Harmonization - Parallel | Y1: Singularity | Z1: Singular Type | AA1: Secondary | AB1: Minutiae | AC1: Orthographic - General | AD1: Mere Minutiae | AE1: Nonsense | AF1: Review
A2: TReub.3.7 | B2: το πνα του υπνου | C2: το πνευμα το υπνου | G2: Autograph corresponds to structure used at T. Reub. 3:1 το πνα του υπνου; apograph disharmonizes | H2: Substitution - Form | U2: Disharmonizing | V2: Forward | AA2: Yes
D5: Harmonizations | E5: =COUNTIF(U:U, "Harmonizing") -> 0
D6: Disharmonizations | E6: =COUNTIF(U:U, "Disharmonizing") -> 1
D7: Harm_Ratio | E7: =E5/(E5+E6) -> 0

Sheet Gen-Error-Rates
A1: Words copied | B1: 20272
A2: Raw Errors | B2: =COUNTA('Unfiltered Data'!A:A) - 1 -> 462
A3: Variants | B3: =COUNTA('Gen-filters'!A:A) - 1 -> 62
A5: Raw PKW Error Rate | B5: =(B2/B1)*1000 -> 22.790055
A6: PKW Meaningful Error Rate | B6: =(B3/B1)*1000 -> 3.0584057

Sheet Corrections
A2: Correction Readings Followed
A3: Yes | B3: =COUNTIF('Unfiltered Data'!G:G, "Yes") -> 11
A4: No | B4: =COUNTIF('Unfiltered Data'!G:G, "No") -> 0
A5: % Yes | B5: =B3/SUM(B3:B4) -> 1
A8: Variant Corrected
B9: Count | C9: % of Variants | D9: Proportion of "Corrections"
A10: Yes | B10: =COUNTIF('Unfiltered Data'!H:H, "Yes") -> 104 | C10: =B10/'Gen-Error-Rates'!$B$2 -> 0.22510823 | D10: =B10/SUM($B$10:$B$12) -> 0.97196262
A11: Partially | B11: =COUNTIF('Unfiltered Data'!H:H, "Yes, partially") -> 0 | C11: =B11/'Gen-Error-Rates'!$B$2 -> 0 | D11: =B11/SUM($B$10:$B$12) -> 0
A12: To Other Variant | B12: =COUNTIF('Unfiltered Data'!H:H, "Yes, to another error") -> 3 | C12: =B12/'Gen-Error-Rates'!$B$2 -> 0.0064935065 | D12: =B12/SUM($B$10:$B$12) -> 0.028037383

Sheet Singularity
A1: Verse Ref | B1: Autograph | C1: Apograph | D1: Exclusion Grounds | E1: Corrector Followed | F1: Apograph Corrected | G1: Detail | H1: Basic Type | I1: Phrase Length | J1: Words Length | K1: Letters Length | L1: Speech Part Add/Omitted | M1: Visual Cues | N1: Cue Regions | O1: Cue Length | P1: Duplicate Material | Q1: AO Word Frequency | R1: SUB Frequency Difference | S1: SUB_Aut_Freq | T1: SUB_Apog_Freq | U1: Harmonization - Context | V1: Parallel Present | W1: Harmonization - Parallel | X1: Singularity | Y1: Queens 214 Agreement | Z1: Secondary | AA1: Minutiae | AB1: Orthographic - General | AC1: Mere Minutiae | AD1: Nonsense | AE1: Review
A2: TReub.1.7 | B2: ει μη ιακωβ ο πηρ ημων προσηυξατο | C2: ει μη ιακωβ προσηυξατο | F2: Yes | H2: Omission | I2: 0 | J2: 3 | K2: 8 | M2: Absent | Q2: 146 | X2: Singular | Y2: Disagree | Z2: Yes
A3: TReub.1.10 | B3: και παν αρτον | C3: και παντα αρτον | H3: Substitution - Form | X3: Non-singular | Y3: Disagree | Z3: Yes
A4: TReub.3.1 | B4: και εικων του θανατου | C4: και εικη εικων του θανατου | F4: Yes | G4: Frequency based on εικω | H4: Addition | I4: 0 | J4: 1 | K4: 4 | L4: Verb | M4: Present | N4: BD | O4: 3 | Q4: 0 | X4: Singular | Y4: Disagree | Z4: Yes
A5: TReub.3.5 | B5: πλαττειν λογους αυτου | C5: πλαττειν λογους αυτου | G5: other MSS = πλαττειν λογους και κρυπτειν λογους αυτου, or another variant | H5: Omission | J5: 3 | K5: 17 | M5: Present | N5: AC | O5: 10 | Q5: 4 | X5: Pseudo-singular | Y5: Dual-agreement
A6: TReub.3.6 | B6: δια της δολολειψιας | C6: δια της δολολειψιας | G6: other MSS = δια της δωροληψιας | H6: Substitution - Word | R6: 0 | S6: 0 | T6: 0 | X6: Pseudo-singular | Y6: Dual-agreement
A7: TReub.3.7 | B7: το πνα του υπνου | C7: το πνευμα το υπνου | G7: Autograph corresponds to structure used at T. Reub. 3:1 το πνα του υπνου; apograph disharmonizes | H7: Substitution - Form | U7: Disharmonizing | X7: Singular | Y7: Disagree | Z7: Yes
A8: TReub.4.4 | B8: παρελθη | C8: παρεθη | F8: Yes | G8: Frequency = παραθεω - παρερχομαι | H8: Substitution - Word | R8: -4 | S8: 4 | T8: 0 | X8: Singular | Y8: Disagree | Z8: Yes
A9: TReub.4.4 | B9: απο τοτε ουν παρεφυλαξαμην | C9: απο τοτε ουν παρεφυλαξαμην | G9: other MSS = απο τοτε μετανοων παρεφυλαξαμην, or other variant | H9: Substitution - Word | R9: =86-11 -> 75 | S9: 11 | T9: 86 | X9: Pseudo-singular | Y9: Dual-agreement
A10: TReub.4.6 | B10: εστιν η πορνεια | C10: εστιν πορνεια | F10: Yes | H10: Addition | I10: 0 | J10: 1 | K10: 1 | L10: Article | M10: NA | Q10: 2475 | X10: Singular | Y10: Disagree | Z10: Yes
A11: TReub.5.3 | B11: γυναικες ηττωνται τω πνι | C11: γυναικες τω πνευματι | G11: page turn error | H11: Omission | I11: 0 | J11: 1 | K11: 8 | L11: Verb | M11: Present | N11: BD | O11: 5 | Q11: 3 | X11: Singular | Y11: Disagree | Z11: Yes
A12: TReub.6.6 | B12: ο γαρ θς | C12: ου γαρ θς | F12: Yes | H12: Substitution - Word | R12: -2271 | S12: 2475 | T12: 204 | X12: Singular | Y12: Disagree | Z12: Yes
A13: TReub.6.7 | B13: καμοι | C13: καεμοι | F13: Yes | H13: Substitution - Form | X13: Singular | Y13: Disagree | Z13: Yes
A14: TReub.6.8 | B14: τελειωσεως | C14: τελεωσεως | F14: Yes | G14: LSJ indicates both spellings as alternatives | H14: Substitution - Form | X14: Singular | Y14: Disagree | Z14: Yes
A15: TReub.6.9 | B15: αληθειαν εκαστος προς τον πλησιον αυτου (10) και προς | C15: αληθειαν εκαστος προς τον πλησιον αυτου (10) και προς | G15: other MSS = αληθειαν εκαστος προς τον πλησιον αυτου και αγαπην εκαστος προς τον αδελφον αυτου (10) και προς, or other variant; freq = αγαπη | H15: Omission | J15: 7 | K15: 35 | M15: Present | N15: AC;BD | O15: 22;3 | Q15: 10 | X15: Pseudo-singular | Y15: Dual-agreement
A16: TSim.2.6 | B16: εζηλωσα τω ιωσηφ | C16: εζηλωσα τω ιωσηφ | G16: other MSS = εζηλωσα τον ιωσηφ | H16: Substitution - Form | X16: Pseudo-singular | Y16: Disagree
A17: TSim.2.13 | B17: αποκαταστηση την χειρα μου και αποσχομαι | C17: αποκαταστηση την χειρα μου και αποσχομαι | G17: other MSS = αποκατασταθω και αποσχωμαι | H17: Substitution - Form | X17: Pseudo-singular | Y17: Dual-agreement
A18: TSim.2.13 | B18: αποκαταστηση την χειρα μου και αποσχομαι | C18: αποκαταστηση την χειρα μου και αποσχομαι | G18: other MSS = αποκατασταθω και αποσχωμαι; freq = χειρ | H18: Addition | J18: 3 | K18: 11 | M18: Absent | Q18: 25 | X18: Pseudo-singular | Y18: Dual-agreement
A19: TSim.2.14 | B19: ιακωβ του πατρος δια | C19: ιακωβ του πατρος δια | G19: other MSS = ιακωβ του πατρος μου δια | H19: Omission | J19: 1 | K19: 3 | L19: Pronoun | M19: Absent | Q19: 768 | X19: Pseudo-singular | Y19: Dual-agreement
A20: TSim.4.6 | B20: υπερ τους υιους αυτου και εδοξασεν | C20: υπερ τους υιους αυτου και εδοξασεν | G20: other MSS lack και | H20: Addition | J20: 1 | K20: 3 | L20: Conjunction | M20: Absent | Q20: 1759 | X20: Pseudo-singular | Y20: Dual-agreement
A21: TSim.4.8 | B21: την συνεσιν ανθρωποις | C21: την συνεσιν ανθρωποις | G21: other MSS = τη συνεσιν εν ανθρωποις | H21: Omission | J21: 1 | K21: 2 | L21: Preposition | M21: NA | Q21: 316 | X21: Pseudo-singular | Y21: Dual-agreement
A22: TSim.4.8 | B22: ανοις ενεργειν | C22: ανθρωποις συνεργειν | F22: Yes | H22: Substitution - Word | R22: 3 | S22: 3 | T22: 6 | X22: Singular | Y22: Disagree | Z22: Yes
A23: TSim.5.6 | B23: και εσται εξ υμων | C23: και εσται εξ υμων | G23: other MSS = και ουκ εσται εξ υμων | H23: Omission | J23: 1 | K23: 3 | L23: Particle | M23: Absent | Q23: 204 | X23: Pseudo-singular | Y23: Dual-agreement
A24: TSim.6.2 | B24: αφ υμων τον φθονον | C24: αφ υμων φθονον | H24: Omission | I24: 0 | J24: 1 | K24: 3 | L24: Article | M24: Absent | Q24: 2475 | X24: Singular | Y24: Disagree | Z24: Yes
A25: TSim.6.2 | B25: και πληθυνθησεται ως κεδροι | C25: και πληθυνθησεται ως κεδροι | G25: other MSS = και πληθυνθησονται ως κεδροι | H25: Substitution - Form | X25: Pseudo-singular | Y25: Dual-agreement
A26: TSim.8.4 | B26: εν παση τη αιγυπτω | C26: εν παση τη αιγυπτω | G26: other MSS = εν παση γη αιγυπτω | H26: Substitution - Word | R26: =T26-S26 -> 2400 | S26: 75 | T26: 2475 | X26: Pseudo-singular | Y26: Dual-agreement
A27: TLev.2.5 | B27: αβελμαουλ | C27: αβελβαουλ | H27: Substitution - Word | R27: -2 | S27: 2 | T27: 0 | X27: Singular | Y27: Disagree | Z27: Yes
A28: TLev.3.1 | B28: ουτος παρα πασας αδικιας | C28: ουτος παρα πασας αδικιας | G28: other MSS = ουτος ορα πασας αδικιας | H28: Substitution - Word | R28: =T28-S28 -> -52 | S28: 79 | T28: 27 | X28: Pseudo-singular | Y28: Dual-agreement
A29: TLev.4.2 | B29: ουν ο υψιστος | C29: ουν υψιστος | H29: Omission | I29: 0 | J29: 1 | K29: 1 | L29: Article | M29: NA | Q29: 2475 | X29: Singular | Y29: Disagree | Z29: Yes
A30: TLev.5.1 | B30: επι θρονου δοξης | C30: επι θρονον δοξης | F30: Yes | H30: Substitution - Form | X30: Singular | Y30: Disagree | Z30: Yes
A31: TLev.5.2 | B31: παροικησω εμμεσω | C31: παροικηση εμμεσω | F31: Yes | H31: Substitution - Form | X31: Singular | Y31: Disagree | Z31: Yes
A32: TLev.6.1 | B32: ασπις οτι εγγυς γεβαλ | C32: ασπις οτι εγγυς γεβαλ | G32: other MSS = ασπις ο εστιν εγγυς γεβαλ | H32: Substitution - Word | R32: =T32-S32 -> -2195 | S32: 2475 | T32: 280 | X32: Pseudo-singular | Y32: Dual-agreement
A33: TLev.6.8 | B33: ηθελον εις την σαρραν ποιησαι | C33: ηθελον εις την σαρραν ποιησαι | G33: other MSS = ηθελον και την σαρραν ποιησαι | H33: Substitution - Word | R33: =T33-S33 -> -1518 | S33: 1759 | T33: 241 | X33: Pseudo-singular | Y33: Dual-agreement
A34: TLev.7.2 | B34: ωσει τις χλευασαι | C34: ως εις τις χλευασει | F34: Yes | G34: Frequency = ωσει - εις | H34: Substitution - Word | R34: -28 | S34: 31 | T34: 3 | X34: Singular | Y34: Disagree | Z34: Yes
A35: TLev.9.1 | B35: μετα τον πατερα ημων | C35: μετα τον πατερα ημων | G35: other MSS = μετα του πατρος ημων | H35: Substitution - Form | X35: Pseudo-singular | Y35: Disagree
A36: TLev.9.9 | B36: και ελεγε μη προσεχε | C36: και ελεγε μη προσεχε | G36: other MSS lack μη | H36: Addition | J36: 1 | K36: 2 | L36: Particle | M36: NA | Q36: 124 | X36: Pseudo-singular | Y36: Disagree
A37: TLev.11.7 | B37: και τρεις ετεκε μοι | C37: και τρεις ετεκε μοι | G37: other MSS = και τριτον ετεκε μοι | H37: Substitution - Form | X37: Pseudo-singular | Y37: Dual-agreement
A38: TLev.12.6 | B38: και ιδου τεκνα μου εστε | C38: και ιδου τεκνα μου εστε | G38: other MSS lack τεκνα μου here | H38: Addition | J38: 2 | K38: 8 | M38: Absent | Q38: 115 | X38: Pseudo-singular | Y38: Dual-agreement
A39: TLev.13.1 | B39: τον νομων αυτων | C39: τον νομων αυτων | G39: other MSS = τον νομον αυτου | H39: Substitution - Form | X39: Pseudo-singular | Y39: Disagree
A40: TLev.14.8 | B40: αγια εν καταφρονησει | C40: αγια και εν καταφρονησει | F40: Yes | H40: Addition | I40: 0 | J40: 1 | K40: 3 | L40: Conjunction | M40: Absent | Q40: 1701 | X40: Non-singular | Y40: Disagree | Z40: Yes
...

Sheet Data Regularization
A1: Exclusion grounds | B1: Corrector followed | C1: Apograph corrected | D1: Basic Type | E1: Speech part add/omitted | F1: Visual Cues | G1: Duplicate Material | H1: Harmonization - Context | I1: Harmonization_Direction | J1: Parallel Present | K1: Harmonization - Parallel | L1: Singularity | M1: Crit-text-relation | N1: Secondary | O1: Minutiae | P1: Mere Minutiae | Q1: Nonsense | R1: Review | S1: Queens 214 Agreement
A3: Autograph unclear | B3: Yes | C3: Yes | D3: Addition | E3: Adjective | F3: Present | G3: Dittography | H3: Harmonizing | I3: Forward | J3: Yes | K3: Harmonizing | L3: Singular | M3: Non-deviating variant | N3: Yes | O3: Itacism | P3: Yes | Q3: Generated - strict | R3: Yes | S3: Disagree
A4: Autograph unclear (but clear enough) | B4: Yes, but still an error | C4: Yes, partially | D4: Omission | E4: Article | F4: Absent | G4: Repetition | H4: Disharmonizing | I4: Backward | J4: No | K4: Disharmonizing | L4: Pseudo-singular | M4: Deviating variant | N4: No | O4: Movable ν | P4: No | Q4: Generated - contextual | R4: No | S4: Agree
A5: Autograph unclear (Apograph reading likely) | B5: No | C5: Yes, to another error | D5: Substitution - Word | E5: Adverb | F5: NA | I5: Both | L5: Non-singular | M5: Deviating variant (type change) | O5: Iota Adscript | Q5: Removed - strict | S5: Dual-agreement
A6: Apograph unclear | C6: No | D6: Substitution - Form | E6: Conjunction | L6: NA | M6: Deviating non-variant | O6: Iota Subscript | Q6: Removed - contextual
A7: Apograph unclear (but clear enough) | D7: Substitution - Both | E7: Compound word | O7: Name Spelling
A8: Apograph unclear (Autograph reading likely) | D8: Transposition | E8: Noun | O8: Abbreviation
A9: Apograph corrected | D9: Multiple | E9: Pronoun | O9: Breathings
A10: Damage to autograph | D10: Unclear due to correction | E10: Preposition | O10: Accents
