Workbook

Sheet Unfiltered Data
A1: Verse Ref | B1: Phys Loc 1 | C1: Phys Loc 2 | D1: Autograph | E1: Apograph | F1: Exclusion Grounds | G1: Corrector Followed | H1: Apograph Corrected | I1: Detail | J1: Basic Type | K1: Phrase Length | L1: Words Length | M1: Letters Length | N1: Speech Part Add/Omitted | O1: Visual Cues | P1: Cue Regions | Q1: Cue Length | R1: Duplicate Material | S1: AO Word Frequency | T1: SUB Frequency Difference | U1: SUB_Aut_Freq | V1: SUB_Apog_Freq | W1: Harmonization - Context | X1: Parallel Present | Y1: Harmonization - Parallel | Z1: Singularity | AA1: Secondary | AB1: Minutiae | AC1: Orthographic - General | AD1: Mere Minutiae | AE1: Nonsense | AF1: Review | AG1: Oo.VI.9.8 | AH1: Barocci | AI1: Smith
A2: TLev.3.3 | D2: εκδικησιν εν τοις πνασι | E2: εκδικησιν τοις πνευμασι | J2: Omission | L2: 1 | M2: 2 | N2: Preposition | O2: NA | S2: 613 | U2: =IF(ISNUMBER(T2),VALUE(MID(_xlfn.FORMULATEXT(T2),SEARCH("-",_xlfn.FORMULATEXT(T2))+1,LEN(_xlfn.FORMULATEXT(T2))-SEARCH("-",_xlfn.FORMULATEXT(T2)))), "") | V2: =IF(ISNUMBER(T2), VALUE(MID(_xlfn.FORMULATEXT(T2), 2, SEARCH("-", _xlfn.FORMULATEXT(T2)) - 2)), "") | AG2: Yes | AJ2: {=_xlfn.IFS(AG2="Yes",1,AG2="No",0,AG2="","")} -> 1
A3: TLev.3.3 | D3: οι δε εις τον τεταρτον | E3: οι δε εις τεταρτον | J3: Omission | L3: 1 | M3: 3 | N3: Article | O3: Present | P3: BD:CD | Q3: 3:3 | S3: 2475 | U3: =IF(ISNUMBER(T3),VALUE(MID(_xlfn.FORMULATEXT(T3),SEARCH("-",_xlfn.FORMULATEXT(T3))+1,LEN(_xlfn.FORMULATEXT(T3))-SEARCH("-",_xlfn.FORMULATEXT(T3)))), "") | V3: =IF(ISNUMBER(T3), VALUE(MID(_xlfn.FORMULATEXT(T3), 2, SEARCH("-", _xlfn.FORMULATEXT(T3)) - 2)), "") | AG3: Yes | AJ3: {=_xlfn.IFS(AG3="Yes",1,AG3="No",0,AG3="","")} -> 1
A4: TLev.3.4 | D4: εν τω ανωτερω | E4: εν ανωτερω | J4: Omission | L4: 1 | M4: 2 | N4: Article | O4: NA | S4: 2475 | U4: =IF(ISNUMBER(T4),VALUE(MID(_xlfn.FORMULATEXT(T4),SEARCH("-",_xlfn.FORMULATEXT(T4))+1,LEN(_xlfn.FORMULATEXT(T4))-SEARCH("-",_xlfn.FORMULATEXT(T4)))), "") | V4: =IF(ISNUMBER(T4), VALUE(MID(_xlfn.FORMULATEXT(T4), 2, SEARCH("-", _xlfn.FORMULATEXT(T4)) - 2)), "") | AG4: Yes | AJ4: {=_xlfn.IFS(AG4="Yes",1,AG4="No",0,AG4="","")} -> 1
A5: TLev.3.4 | D5: η μεγαλη | E5: η μηγαλη | H5: Yes | J5: Substitution - Word | T5: NA | U5: =IF(ISNUMBER(T5),VALUE(MID(_xlfn.FORMULATEXT(T5),SEARCH("-",_xlfn.FORMULATEXT(T5))+1,LEN(_xlfn.FORMULATEXT(T5))-SEARCH("-",_xlfn.FORMULATEXT(T5)))), "") | V5: =IF(ISNUMBER(T5), VALUE(MID(_xlfn.FORMULATEXT(T5), 2, SEARCH("-", _xlfn.FORMULATEXT(T5)) - 2)), "") | AC5: ε-η | AD5: Yes | AE5: Generated - strict | AG5: No | AJ5: {=_xlfn.IFS(AG5="Yes",1,AG5="No",0,AG5="","")} -> 0
A6: TLev.3.6 | D6: ευωδιας | E6: ευοδιας | F6: Apograph unclear | H6: Yes | J6: Substitution - Word | T6: =0-1 -> -1 | U6: =IF(ISNUMBER(T6),VALUE(MID(_xlfn.FORMULATEXT(T6),SEARCH("-",_xlfn.FORMULATEXT(T6))+1,LEN(_xlfn.FORMULATEXT(T6))-SEARCH("-",_xlfn.FORMULATEXT(T6)))), "") -> 1 | V6: =IF(ISNUMBER(T6), VALUE(MID(_xlfn.FORMULATEXT(T6), 2, SEARCH("-", _xlfn.FORMULATEXT(T6)) - 2)), "") -> 0 | AC6: ω-ο | AD6: Yes | AG6: Yes | AJ6: {=_xlfn.IFS(AG6="Yes",1,AG6="No",0,AG6="","")} -> 1
A7: TLev.3.8 | D7: εν ω υμνοι αει τω θεω | E7: εν ω αει υμνοι τω θεω | I7: 1.0.1 transposition | J7: Transposition | U7: =IF(ISNUMBER(T7),VALUE(MID(_xlfn.FORMULATEXT(T7),SEARCH("-",_xlfn.FORMULATEXT(T7))+1,LEN(_xlfn.FORMULATEXT(T7))-SEARCH("-",_xlfn.FORMULATEXT(T7)))), "") | V7: =IF(ISNUMBER(T7), VALUE(MID(_xlfn.FORMULATEXT(T7), 2, SEARCH("-", _xlfn.FORMULATEXT(T7)) - 2)), "") | AG7: Yes | AJ7: {=_xlfn.IFS(AG7="Yes",1,AG7="No",0,AG7="","")} -> 1
A8: TLev.3.9 | D8: επιβλεψη κς | E8: επιβλεψη ο κυριος | J8: Addition | L8: 1 | M8: 1 | N8: Article | O8: NA | S8: 2475 | U8: =IF(ISNUMBER(T8),VALUE(MID(_xlfn.FORMULATEXT(T8),SEARCH("-",_xlfn.FORMULATEXT(T8))+1,LEN(_xlfn.FORMULATEXT(T8))-SEARCH("-",_xlfn.FORMULATEXT(T8)))), "") | V8: =IF(ISNUMBER(T8), VALUE(MID(_xlfn.FORMULATEXT(T8), 2, SEARCH("-", _xlfn.FORMULATEXT(T8)) - 2)), "") | AG8: Yes | AJ8: {=_xlfn.IFS(AG8="Yes",1,AG8="No",0,AG8="","")} -> 1
A9: TLev.3.9 | D9: και οι αβυσσοι | E9: και αι αβυσσοι | J9: Substitution - Form | U9: =IF(ISNUMBER(T9),VALUE(MID(_xlfn.FORMULATEXT(T9),SEARCH("-",_xlfn.FORMULATEXT(T9))+1,LEN(_xlfn.FORMULATEXT(T9))-SEARCH("-",_xlfn.FORMULATEXT(T9)))), "") | V9: =IF(ISNUMBER(T9), VALUE(MID(_xlfn.FORMULATEXT(T9), 2, SEARCH("-", _xlfn.FORMULATEXT(T9)) - 2)), "") | AE9: Removed - contextual | AG9: Yes | AJ9: {=_xlfn.IFS(AG9="Yes",1,AG9="No",0,AG9="","")} -> 1
A10: TLev.3.10 | D10: αναισθητουντες | E10: αναισθετουντες | H10: Yes | J10: Substitution - Word | T10: NA | U10: =IF(ISNUMBER(T10),VALUE(MID(_xlfn.FORMULATEXT(T10),SEARCH("-",_xlfn.FORMULATEXT(T10))+1,LEN(_xlfn.FORMULATEXT(T10))-SEARCH("-",_xlfn.FORMULATEXT(T10)))), "") | V10: =IF(ISNUMBER(T10), VALUE(MID(_xlfn.FORMULATEXT(T10), 2, SEARCH("-", _xlfn.FORMULATEXT(T10)) - 2)), "") | AC10: η-ε | AD10: Yes | AE10: Generated - strict | AG10: No | AJ10: {=_xlfn.IFS(AG10="Yes",1,AG10="No",0,AG10="","")} -> 0
A11: TLev.4.1 | D11: οτι των πετρων | E11: οτε των πετρων | J11: Substitution - Word | T11: =31-280 -> -249 | U11: =IF(ISNUMBER(T11),VALUE(MID(_xlfn.FORMULATEXT(T11),SEARCH("-",_xlfn.FORMULATEXT(T11))+1,LEN(_xlfn.FORMULATEXT(T11))-SEARCH("-",_xlfn.FORMULATEXT(T11)))), "") -> 280 | V11: =IF(ISNUMBER(T11), VALUE(MID(_xlfn.FORMULATEXT(T11), 2, SEARCH("-", _xlfn.FORMULATEXT(T11)) - 2)), "") -> 31 | AG11: Yes | AJ11: {=_xlfn.IFS(AG11="Yes",1,AG11="No",0,AG11="","")} -> 1
A12: TLev.18.11 | D12: αγιωσυνης | E12: αγιoσυνης | H12: Yes | J12: Substitution - Word | T12: ΝΑ | U12: =IF(ISNUMBER(T12),VALUE(MID(_xlfn.FORMULATEXT(T12),SEARCH("-",_xlfn.FORMULATEXT(T12))+1,LEN(_xlfn.FORMULATEXT(T12))-SEARCH("-",_xlfn.FORMULATEXT(T12)))), "") | V12: =IF(ISNUMBER(T12), VALUE(MID(_xlfn.FORMULATEXT(T12), 2, SEARCH("-", _xlfn.FORMULATEXT(T12)) - 2)), "") | AC12: ω-ο | AD12: Yes | AE12: Generated - strict | AG12: No | AJ12: {=_xlfn.IFS(AG12="Yes",1,AG12="No",0,AG12="","")} -> 0
A13: TLev.18.12 | D13: δεθησεται | E13: δεθεσεται | H13: Yes | J13: Substitution - Word | T13: ΝΑ | U13: =IF(ISNUMBER(T13),VALUE(MID(_xlfn.FORMULATEXT(T13),SEARCH("-",_xlfn.FORMULATEXT(T13))+1,LEN(_xlfn.FORMULATEXT(T13))-SEARCH("-",_xlfn.FORMULATEXT(T13)))), "") | V13: =IF(ISNUMBER(T13), VALUE(MID(_xlfn.FORMULATEXT(T13), 2, SEARCH("-", _xlfn.FORMULATEXT(T13)) - 2)), "") | AC13: η-ε | AD13: Yes | AE13: Generated - strict | AG13: No | AJ13: {=_xlfn.IFS(AG13="Yes",1,AG13="No",0,AG13="","")} -> 0
A14: TLev.18.12 | D14: τεκνοις αυτου του πατειν | E14: τεκνοις αυτου πατειν | J14: Omission | L14: 1 | M14: 3 | N14: Article | O14: Present | P14: AB:AC | Q14: 3:3 | S14: 2475 | U14: =IF(ISNUMBER(T14),VALUE(MID(_xlfn.FORMULATEXT(T14),SEARCH("-",_xlfn.FORMULATEXT(T14))+1,LEN(_xlfn.FORMULATEXT(T14))-SEARCH("-",_xlfn.FORMULATEXT(T14)))), "") | V14: =IF(ISNUMBER(T14), VALUE(MID(_xlfn.FORMULATEXT(T14), 2, SEARCH("-", _xlfn.FORMULATEXT(T14)) - 2)), "") | AG14: Yes | AJ14: {=_xlfn.IFS(AG14="Yes",1,AG14="No",0,AG14="","")} -> 1
A15: TLev.18.13 | D15: τοις τεκνοις | E15: τοις αγαπητοις τεκνοις | H15: Yes | J15: Addition | L15: 1 | M15: 9 | N15: Adjective | O15: Present | P15: AB:AC:BD:CD | Q15: 4:4:4:4 | S15: 4 | U15: =IF(ISNUMBER(T15),VALUE(MID(_xlfn.FORMULATEXT(T15),SEARCH("-",_xlfn.FORMULATEXT(T15))+1,LEN(_xlfn.FORMULATEXT(T15))-SEARCH("-",_xlfn.FORMULATEXT(T15)))), "") | V15: =IF(ISNUMBER(T15), VALUE(MID(_xlfn.FORMULATEXT(T15), 2, SEARCH("-", _xlfn.FORMULATEXT(T15)) - 2)), "") | AG15: No | AJ15: {=_xlfn.IFS(AG15="Yes",1,AG15="No",0,AG15="","")} -> 0
A16: TLev.18.14 | D16: αγαλλιασεται | E16: αγαλλιαζεται | H16: Yes | J16: Substitution - Word | T16: ΝΑ | U16: =IF(ISNUMBER(T16),VALUE(MID(_xlfn.FORMULATEXT(T16),SEARCH("-",_xlfn.FORMULATEXT(T16))+1,LEN(_xlfn.FORMULATEXT(T16))-SEARCH("-",_xlfn.FORMULATEXT(T16)))), "") | V16: =IF(ISNUMBER(T16), VALUE(MID(_xlfn.FORMULATEXT(T16), 2, SEARCH("-", _xlfn.FORMULATEXT(T16)) - 2)), "") | AE16: Generated - strict | AG16: No | AJ16: {=_xlfn.IFS(AG16="Yes",1,AG16="No",0,AG16="","")} -> 0
A17: TLev.18.14 | D17: χαρισομαι | E17: χαρησομαι | J17: Substitution - Word | T17: =8-1 -> 7 | U17: =IF(ISNUMBER(T17),VALUE(MID(_xlfn.FORMULATEXT(T17),SEARCH("-",_xlfn.FORMULATEXT(T17))+1,LEN(_xlfn.FORMULATEXT(T17))-SEARCH("-",_xlfn.FORMULATEXT(T17)))), "") -> 1 | V17: =IF(ISNUMBER(T17), VALUE(MID(_xlfn.FORMULATEXT(T17), 2, SEARCH("-", _xlfn.FORMULATEXT(T17)) - 2)), "") -> 8 | AG17: No | AJ17: {=_xlfn.IFS(AG17="Yes",1,AG17="No",0,AG17="","")} -> 0
A18: TLev.19.1 | D18: ηκουσατε | E18: ησουσατε | J18: Substitution - Word | T18: ΝΑ | U18: =IF(ISNUMBER(T18),VALUE(MID(_xlfn.FORMULATEXT(T18),SEARCH("-",_xlfn.FORMULATEXT(T18))+1,LEN(_xlfn.FORMULATEXT(T18))-SEARCH("-",_xlfn.FORMULATEXT(T18)))), "") | V18: =IF(ISNUMBER(T18), VALUE(MID(_xlfn.FORMULATEXT(T18), 2, SEARCH("-", _xlfn.FORMULATEXT(T18)) - 2)), "") | AE18: Generated - strict | AG18: No | AJ18: {=_xlfn.IFS(AG18="Yes",1,AG18="No",0,AG18="","")} -> 0
A19: TLev.19.1 | D19: η νομον κυ | E19: η τον νομον του κυριου | J19: Addition | L19: 1 | M19: 3 | N19: Article | O19: Absent | S19: 2475 | U19: =IF(ISNUMBER(T19),VALUE(MID(_xlfn.FORMULATEXT(T19),SEARCH("-",_xlfn.FORMULATEXT(T19))+1,LEN(_xlfn.FORMULATEXT(T19))-SEARCH("-",_xlfn.FORMULATEXT(T19)))), "") | V19: =IF(ISNUMBER(T19), VALUE(MID(_xlfn.FORMULATEXT(T19), 2, SEARCH("-", _xlfn.FORMULATEXT(T19)) - 2)), "") | AG19: Yes | AJ19: {=_xlfn.IFS(AG19="Yes",1,AG19="No",0,AG19="","")} -> 1
A20: TLev.19.1 | D20: η νομον κυ | E20: η τον νομον του κυριου | J20: Addition | L20: 1 | M20: 3 | N20: Article | O20: Absent | S20: 2475 | U20: =IF(ISNUMBER(T20),VALUE(MID(_xlfn.FORMULATEXT(T20),SEARCH("-",_xlfn.FORMULATEXT(T20))+1,LEN(_xlfn.FORMULATEXT(T20))-SEARCH("-",_xlfn.FORMULATEXT(T20)))), "") | V20: =IF(ISNUMBER(T20), VALUE(MID(_xlfn.FORMULATEXT(T20), 2, SEARCH("-", _xlfn.FORMULATEXT(T20)) - 2)), "") | AG20: Yes | AJ20: {=_xlfn.IFS(AG20="Yes",1,AG20="No",0,AG20="","")} -> 1
A21: TLev.19.1 | D21: εργα βελιαρ | E21: εργα του βελιαρ | J21: Addition | L21: 1 | M21: 3 | N21: Article | O21: Absent | S21: 2475 | U21: =IF(ISNUMBER(T21),VALUE(MID(_xlfn.FORMULATEXT(T21),SEARCH("-",_xlfn.FORMULATEXT(T21))+1,LEN(_xlfn.FORMULATEXT(T21))-SEARCH("-",_xlfn.FORMULATEXT(T21)))), "") | V21: =IF(ISNUMBER(T21), VALUE(MID(_xlfn.FORMULATEXT(T21), 2, SEARCH("-", _xlfn.FORMULATEXT(T21)) - 2)), "") | AG21: Yes | AJ21: {=_xlfn.IFS(AG21="Yes",1,AG21="No",0,AG21="","")} -> 1
A22: TLev.19.2 | D22: απεκριθημεν | E22: απεκριθομεν | J22: Substitution - Form | U22: =IF(ISNUMBER(T22),VALUE(MID(_xlfn.FORMULATEXT(T22),SEARCH("-",_xlfn.FORMULATEXT(T22))+1,LEN(_xlfn.FORMULATEXT(T22))-SEARCH("-",_xlfn.FORMULATEXT(T22)))), "") | V22: =IF(ISNUMBER(T22), VALUE(MID(_xlfn.FORMULATEXT(T22), 2, SEARCH("-", _xlfn.FORMULATEXT(T22)) - 2)), "") | AE22: Generated - strict | AG22: Yes | AJ22: {=_xlfn.IFS(AG22="Yes",1,AG22="No",0,AG22="","")} -> 1
A23: TLev.19.2 | D23: πορευσωμεθα | E23: πορευσομεθα | J23: Substitution - Form | U23: =IF(ISNUMBER(T23),VALUE(MID(_xlfn.FORMULATEXT(T23),SEARCH("-",_xlfn.FORMULATEXT(T23))+1,LEN(_xlfn.FORMULATEXT(T23))-SEARCH("-",_xlfn.FORMULATEXT(T23)))), "") | V23: =IF(ISNUMBER(T23), VALUE(MID(_xlfn.FORMULATEXT(T23), 2, SEARCH("-", _xlfn.FORMULATEXT(T23)) - 2)), "") | AC23: ω-ο | AD23: Yes | AG23: Yes | AJ23: {=_xlfn.IFS(AG23="Yes",1,AG23="No",0,AG23="","")} -> 1
A24: TLev.19.3 | D24: ειπωμεν | E24: ειπαμεν | J24: Substitution - Form | U24: =IF(ISNUMBER(T24),VALUE(MID(_xlfn.FORMULATEXT(T24),SEARCH("-",_xlfn.FORMULATEXT(T24))+1,LEN(_xlfn.FORMULATEXT(T24))-SEARCH("-",_xlfn.FORMULATEXT(T24)))), "") | V24: =IF(ISNUMBER(T24), VALUE(MID(_xlfn.FORMULATEXT(T24), 2, SEARCH("-", _xlfn.FORMULATEXT(T24)) - 2)), "") | AG24: Yes | AJ24: {=_xlfn.IFS(AG24="Yes",1,AG24="No",0,AG24="","")} -> 1
A25: TJud.21.5 | D25: εντρυφηματα υιων | E25: εντρυφηματων υιων | F25: Not a variant: apograph transcript error | I25: Queens firsthand = εντρυφηματα υιων, then corrects εντρυφηματα -> εντρυφηματων | U25: =IF(ISNUMBER(T25),VALUE(MID(_xlfn.FORMULATEXT(T25),SEARCH("-",_xlfn.FORMULATEXT(T25))+1,LEN(_xlfn.FORMULATEXT(T25))-SEARCH("-",_xlfn.FORMULATEXT(T25)))), "") | V25: =IF(ISNUMBER(T25), VALUE(MID(_xlfn.FORMULATEXT(T25), 2, SEARCH("-", _xlfn.FORMULATEXT(T25)) - 2)), "") | AJ25: {=_xlfn.IFS(AG25="Yes",1,AG25="No",0,AG25="","")}
A26: TJud.21.6 | D26: ως θαλασσα | E26: ως η θαλασσα | J26: Addition | L26: 1 | M26: 1 | N26: Article | O26: NA | S26: 2475 | U26: =IF(ISNUMBER(T26),VALUE(MID(_xlfn.FORMULATEXT(T26),SEARCH("-",_xlfn.FORMULATEXT(T26))+1,LEN(_xlfn.FORMULATEXT(T26))-SEARCH("-",_xlfn.FORMULATEXT(T26)))), "") | V26: =IF(ISNUMBER(T26), VALUE(MID(_xlfn.FORMULATEXT(T26), 2, SEARCH("-", _xlfn.FORMULATEXT(T26)) - 2)), "") | AG26: Yes | AJ26: {=_xlfn.IFS(AG26="Yes",1,AG26="No",0,AG26="","")} -> 1
A27: TJud.21.6 | D27: ουτως και | E27: ουτω και | J27: Substitution - Form | U27: =IF(ISNUMBER(T27),VALUE(MID(_xlfn.FORMULATEXT(T27),SEARCH("-",_xlfn.FORMULATEXT(T27))+1,LEN(_xlfn.FORMULATEXT(T27))-SEARCH("-",_xlfn.FORMULATEXT(T27)))), "") | V27: =IF(ISNUMBER(T27), VALUE(MID(_xlfn.FORMULATEXT(T27), 2, SEARCH("-", _xlfn.FORMULATEXT(T27)) - 2)), "") | AG27: No | AJ27: {=_xlfn.IFS(AG27="Yes",1,AG27="No",0,AG27="","")} -> 0
A28: TJud.21.6 | D28: κινδυνευουσιν | E28: κινδυνευσουσιν | J28: Substitution - Form | U28: =IF(ISNUMBER(T28),VALUE(MID(_xlfn.FORMULATEXT(T28),SEARCH("-",_xlfn.FORMULATEXT(T28))+1,LEN(_xlfn.FORMULATEXT(T28))-SEARCH("-",_xlfn.FORMULATEXT(T28)))), "") | V28: =IF(ISNUMBER(T28), VALUE(MID(_xlfn.FORMULATEXT(T28), 2, SEARCH("-", _xlfn.FORMULATEXT(T28)) - 2)), "") | AG28: Yes | AJ28: {=_xlfn.IFS(AG28="Yes",1,AG28="No",0,AG28="","")} -> 1
A29: TJud.21.6 | D29: πλουτισουσιν | E29: πλουτουσιν | J29: Substitution - Form | U29: =IF(ISNUMBER(T29),VALUE(MID(_xlfn.FORMULATEXT(T29),SEARCH("-",_xlfn.FORMULATEXT(T29))+1,LEN(_xlfn.FORMULATEXT(T29))-SEARCH("-",_xlfn.FORMULATEXT(T29)))), "") | V29: =IF(ISNUMBER(T29), VALUE(MID(_xlfn.FORMULATEXT(T29), 2, SEARCH("-", _xlfn.FORMULATEXT(T29)) - 2)), "") | AG29: Yes | AJ29: {=_xlfn.IFS(AG29="Yes",1,AG29="No",0,AG29="","")} -> 1
A30: TJud.21.7 | D30: οτι οι βασιλευοντες | E30: οτι βασιλευοντες | J30: Omission | L30: 1 | M30: 2 | N30: Article | O30: NA | S30: 2475 | U30: =IF(ISNUMBER(T30),VALUE(MID(_xlfn.FORMULATEXT(T30),SEARCH("-",_xlfn.FORMULATEXT(T30))+1,LEN(_xlfn.FORMULATEXT(T30))-SEARCH("-",_xlfn.FORMULATEXT(T30)))), "") | V30: =IF(ISNUMBER(T30), VALUE(MID(_xlfn.FORMULATEXT(T30), 2, SEARCH("-", _xlfn.FORMULATEXT(T30)) - 2)), "") | AG30: Yes | AJ30: {=_xlfn.IFS(AG30="Yes",1,AG30="No",0,AG30="","")} -> 1
A31: TJud.21.7 | D31: καταδουλουσιν | E31: καταδουλωσσιν | F31: Not a variant: apograph transcript error | I31: Queens firsthand = καταδουλουσιν, then corrects καταδουλουσιν -> καταδουλωσσιν | U31: =IF(ISNUMBER(T31),VALUE(MID(_xlfn.FORMULATEXT(T31),SEARCH("-",_xlfn.FORMULATEXT(T31))+1,LEN(_xlfn.FORMULATEXT(T31))-SEARCH("-",_xlfn.FORMULATEXT(T31)))), "") | V31: =IF(ISNUMBER(T31), VALUE(MID(_xlfn.FORMULATEXT(T31), 2, SEARCH("-", _xlfn.FORMULATEXT(T31)) - 2)), "") | AJ31: {=_xlfn.IFS(AG31="Yes",1,AG31="No",0,AG31="","")}
A32: TJud.21.7 | D32: αγρους ποιμνια | E32: αγρους και ποιμνια | J32: Addition | L32: 1 | M32: 3 | N32: Conjunction | O32: Absent | S32: 1701 | U32: =IF(ISNUMBER(T32),VALUE(MID(_xlfn.FORMULATEXT(T32),SEARCH("-",_xlfn.FORMULATEXT(T32))+1,LEN(_xlfn.FORMULATEXT(T32))-SEARCH("-",_xlfn.FORMULATEXT(T32)))), "") | V32: =IF(ISNUMBER(T32), VALUE(MID(_xlfn.FORMULATEXT(T32), 2, SEARCH("-", _xlfn.FORMULATEXT(T32)) - 2)), "") | AG32: Yes | AJ32: {=_xlfn.IFS(AG32="Yes",1,AG32="No",0,AG32="","")} -> 1
A33: TJud.21.7 | D33: (7) αρπασουσι (8) και πολλων σαρκας αδικως κορακας και ιβεις χορτασουσι και προκοψουσιν | E33: (7) αρπαζουσι (8) και προκοψουσιν | H33: Yes | J33: Substitution - Form | U33: =IF(ISNUMBER(T33),VALUE(MID(_xlfn.FORMULATEXT(T33),SEARCH("-",_xlfn.FORMULATEXT(T33))+1,LEN(_xlfn.FORMULATEXT(T33))-SEARCH("-",_xlfn.FORMULATEXT(T33)))), "") | V33: =IF(ISNUMBER(T33), VALUE(MID(_xlfn.FORMULATEXT(T33), 2, SEARCH("-", _xlfn.FORMULATEXT(T33)) - 2)), "") | AG33: Yes | AJ33: {=_xlfn.IFS(AG33="Yes",1,AG33="No",0,AG33="","")} -> 1
A34: TJud.21.8 | D34: (7) αρπασουσι (8) και πολλων σαρκας αδικως κορακας και ιβεις χορτασουσι και προκοψουσιν | E34: (7) αρπαζουσι (8) και προκοψουσιν | H34: Yes | I34: freq = κοραξ | J34: Omission | L34: 8 | M34: 46 | O34: Present | P34: AC:BD | Q34: 10:3 | S34: 1 | U34: =IF(ISNUMBER(T34),VALUE(MID(_xlfn.FORMULATEXT(T34),SEARCH("-",_xlfn.FORMULATEXT(T34))+1,LEN(_xlfn.FORMULATEXT(T34))-SEARCH("-",_xlfn.FORMULATEXT(T34)))), "") | V34: =IF(ISNUMBER(T34), VALUE(MID(_xlfn.FORMULATEXT(T34), 2, SEARCH("-", _xlfn.FORMULATEXT(T34)) - 2)), "") | AG34: No | AJ34: {=_xlfn.IFS(AG34="Yes",1,AG34="No",0,AG34="","")} -> 0
A35: TJud.22.2 | D35: σριον ιηλ | E35: σωτηριον τω ισραηλ | J35: Addition | L35: 1 | M35: 2 | N35: Article | O35: NA | S35: 2475 | U35: =IF(ISNUMBER(T35),VALUE(MID(_xlfn.FORMULATEXT(T35),SEARCH("-",_xlfn.FORMULATEXT(T35))+1,LEN(_xlfn.FORMULATEXT(T35))-SEARCH("-",_xlfn.FORMULATEXT(T35)))), "") | V35: =IF(ISNUMBER(T35), VALUE(MID(_xlfn.FORMULATEXT(T35), 2, SEARCH("-", _xlfn.FORMULATEXT(T35)) - 2)), "") | AG35: Yes | AJ35: {=_xlfn.IFS(AG35="Yes",1,AG35="No",0,AG35="","")} -> 1
A36: TJud.22.2 | D36: παντα τα εθνη | E36: παντα εθνη | J36: Omission | L36: 1 | M36: 2 | N36: Article | O36: NA | R36: Dittography | S36: 2475 | U36: =IF(ISNUMBER(T36),VALUE(MID(_xlfn.FORMULATEXT(T36),SEARCH("-",_xlfn.FORMULATEXT(T36))+1,LEN(_xlfn.FORMULATEXT(T36))-SEARCH("-",_xlfn.FORMULATEXT(T36)))), "") | V36: =IF(ISNUMBER(T36), VALUE(MID(_xlfn.FORMULATEXT(T36), 2, SEARCH("-", _xlfn.FORMULATEXT(T36)) - 2)), "") | AG36: Yes | AJ36: {=_xlfn.IFS(AG36="Yes",1,AG36="No",0,AG36="","")} -> 1
A37: TJud.22.3 | D37: εως του αιωνος | E37: εως αιωνος | I37: phrase εως του αιωνος occurs twice in this verse, apograph omits του both times, therefore not counting as disharmonizing | J37: Omission | L37: 1 | M37: 3 | N37: Article | O37: Absent | S37: 2475 | U37: =IF(ISNUMBER(T37),VALUE(MID(_xlfn.FORMULATEXT(T37),SEARCH("-",_xlfn.FORMULATEXT(T37))+1,LEN(_xlfn.FORMULATEXT(T37))-SEARCH("-",_xlfn.FORMULATEXT(T37)))), "") | V37: =IF(ISNUMBER(T37), VALUE(MID(_xlfn.FORMULATEXT(T37), 2, SEARCH("-", _xlfn.FORMULATEXT(T37)) - 2)), "") | AG37: Yes | AJ37: {=_xlfn.IFS(AG37="Yes",1,AG37="No",0,AG37="","")} -> 1
A38: TJud.22.3 | D38: βασιλειον μου και του σπερματος | E38: βασιλειον μου εκ του σπερματος | J38: Substitution - Word | T38: =79-1701 -> -1622 | U38: =IF(ISNUMBER(T38),VALUE(MID(_xlfn.FORMULATEXT(T38),SEARCH("-",_xlfn.FORMULATEXT(T38))+1,LEN(_xlfn.FORMULATEXT(T38))-SEARCH("-",_xlfn.FORMULATEXT(T38)))), "") -> 1701 | V38: =IF(ISNUMBER(T38), VALUE(MID(_xlfn.FORMULATEXT(T38), 2, SEARCH("-", _xlfn.FORMULATEXT(T38)) - 2)), "") -> 79 | AG38: Yes | AJ38: {=_xlfn.IFS(AG38="Yes",1,AG38="No",0,AG38="","")} -> 1
A39: TJud.22.3 | D39: εως του αιωνος | E39: εως αιωνος | J39: Omission | L39: 1 | M39: 3 | N39: Article | O39: Absent | S39: 2475 | U39: =IF(ISNUMBER(T39),VALUE(MID(_xlfn.FORMULATEXT(T39),SEARCH("-",_xlfn.FORMULATEXT(T39))+1,LEN(_xlfn.FORMULATEXT(T39))-SEARCH("-",_xlfn.FORMULATEXT(T39)))), "") | V39: =IF(ISNUMBER(T39), VALUE(MID(_xlfn.FORMULATEXT(T39), 2, SEARCH("-", _xlfn.FORMULATEXT(T39)) - 2)), "") | AG39: Yes | AJ39: {=_xlfn.IFS(AG39="Yes",1,AG39="No",0,AG39="","")} -> 1
A40: TDan.6.7 | D40: το δε ονομα | E40: το ονομα | J40: Omission | L40: 1 | M40: 2 | N40: Conjunction | O40: NA | S40: 171 | U40: =IF(ISNUMBER(T40),VALUE(MID(_xlfn.FORMULATEXT(T40),SEARCH("-",_xlfn.FORMULATEXT(T40))+1,LEN(_xlfn.FORMULATEXT(T40))-SEARCH("-",_xlfn.FORMULATEXT(T40)))), "") | V40: =IF(ISNUMBER(T40), VALUE(MID(_xlfn.FORMULATEXT(T40), 2, SEARCH("-", _xlfn.FORMULATEXT(T40)) - 2)), "") | AG40: Yes | AJ40: {=_xlfn.IFS(AG40="Yes",1,AG40="No",0,AG40="","")} -> 1
...

Sheet Gen-filters
A1: Verse Ref | B1: Autograph | C1: Apograph | D1: Exclusion Grounds | E1: Corrector Followed | F1: Apograph Corrected | G1: Basic Type | H1: Phrase Length | I1: Words Length | J1: Letters Length | K1: Speech Part Add/Omitted | L1: Visual Cues | M1: Cue Regions | N1: Cue Length | O1: Duplicate Material | P1: AO Word Frequency | Q1: SUB Frequency Difference | R1: SUB_Aut_Freq | S1: SUB_Apog_Freq | T1: Harmonization - Context | U1: Parallel Present | V1: Harmonization - Parallel | W1: Singularity | X1: Secondary | Y1: Minutiae | Z1: Orthographic - General | AA1: Mere Minutiae | AB1: Nonsense | AC1: Review | AD1: Oo.VI.9.8 | AE1: Barocci | AF1: Smith
A2: TLev.3.3 | B2: εκδικησιν εν τοις πνασι | C2: εκδικησιν τοις πνευμασι | G2: Omission | I2: 1 | J2: 2 | K2: Preposition | L2: NA | P2: 613 | AD2: Yes | AE2: Yes | AG2: 1
A3: TLev.3.3 | B3: οι δε εις τον τεταρτον | C3: οι δε εις τεταρτον | G3: Omission | I3: 1 | J3: 3 | K3: Article | L3: Present | M3: BD:CD | N3: 3:3 | P3: 2475 | AD3: Yes | AE3: No | AG3: 1
A4: TLev.3.4 | B4: εν τω ανωτερω | C4: εν ανωτερω | G4: Omission | I4: 1 | J4: 2 | K4: Article | L4: NA | P4: 2475 | AD4: Yes | AE4: No | AG4: 1
A5: TLev.3.8 | B5: εν ω υμνοι αει τω θεω | C5: εν ω αει υμνοι τω θεω | G5: Transposition | AD5: Yes | AE5: Yes | AG5: 1
A6: TLev.3.9 | B6: επιβλεψη κς | C6: επιβλεψη ο κυριος | G6: Addition | I6: 1 | J6: 1 | K6: Article | L6: NA | P6: 2475 | AD6: Yes | AE6: No | AG6: 1
A7: TLev.4.1 | B7: οτι των πετρων | C7: οτε των πετρων | G7: Substitution - Word | Q7: -249 | R7: 280 | S7: 31 | AD7: Yes | AE7: No | AG7: 1
A8: TLev.18.12 | B8: τεκνοις αυτου του πατειν | C8: τεκνοις αυτου πατειν | G8: Omission | I8: 1 | J8: 3 | K8: Article | L8: Present | M8: AB:AC | N8: 3:3 | P8: 2475 | AD8: Yes | AE8: No | AG8: 1
A9: TLev.18.13 | B9: τοις τεκνοις | C9: τοις αγαπητοις τεκνοις | F9: Yes | G9: Addition | I9: 1 | J9: 9 | K9: Adjective | L9: Present | M9: AB:AC:BD:CD | N9: 4:4:4:4 | P9: 4 | AD9: No | AE9: No | AG9: 0
A10: TLev.18.14 | B10: χαρισομαι | C10: χαρησομαι | G10: Substitution - Word | Q10: 7 | R10: 1 | S10: 8 | AD10: No | AE10: No | AG10: 0
A11: TLev.19.1 | B11: η νομον κυ | C11: η τον νομον του κυριου | G11: Addition | I11: 1 | J11: 3 | K11: Article | L11: Absent | P11: 2475 | AD11: Yes | AE11: Yes | AG11: 1
A12: TLev.19.1 | B12: η νομον κυ | C12: η τον νομον του κυριου | G12: Addition | I12: 1 | J12: 3 | K12: Article | L12: Absent | P12: 2475 | AD12: Yes | AE12: No | AG12: 1
A13: TLev.19.1 | B13: εργα βελιαρ | C13: εργα του βελιαρ | G13: Addition | I13: 1 | J13: 3 | K13: Article | L13: Absent | P13: 2475 | AD13: Yes | AE13: Yes | AG13: 1
A14: TLev.19.3 | B14: ειπωμεν | C14: ειπαμεν | G14: Substitution - Form | AD14: Yes | AE14: No | AG14: 1
A15: TJud.21.6 | B15: ως θαλασσα | C15: ως η θαλασσα | G15: Addition | I15: 1 | J15: 1 | K15: Article | L15: NA | P15: 2475 | AD15: Yes | AE15: Yes | AG15: 1
A16: TJud.21.6 | B16: ουτως και | C16: ουτω και | G16: Substitution - Form | AD16: No | AE16: Yes | AG16: 0
A17: TJud.21.6 | B17: κινδυνευουσιν | C17: κινδυνευσουσιν | G17: Substitution - Form | AD17: Yes | AE17: Yes | AG17: 1
A18: TJud.21.6 | B18: πλουτισουσιν | C18: πλουτουσιν | G18: Substitution - Form | AD18: Yes | AE18: Yes | AG18: 1
A19: TJud.21.7 | B19: οτι οι βασιλευοντες | C19: οτι βασιλευοντες | G19: Omission | I19: 1 | J19: 2 | K19: Article | L19: NA | P19: 2475 | AD19: Yes | AE19: Yes | AG19: 1
A20: TJud.21.7 | B20: αγρους ποιμνια | C20: αγρους και ποιμνια | G20: Addition | I20: 1 | J20: 3 | K20: Conjunction | L20: Absent | P20: 1701 | AD20: Yes | AE20: No | AG20: 1
A21: TJud.21.7 | B21: (7) αρπασουσι (8) και πολλων σαρκας αδικως κορακας και ιβεις χορτασουσι και προκοψουσιν | C21: (7) αρπαζουσι (8) και προκοψουσιν | F21: Yes | G21: Substitution - Form | AD21: Yes | AE21: No | AG21: 1
A22: TJud.21.8 | B22: (7) αρπασουσι (8) και πολλων σαρκας αδικως κορακας και ιβεις χορτασουσι και προκοψουσιν | C22: (7) αρπαζουσι (8) και προκοψουσιν | F22: Yes | G22: Omission | I22: 8 | J22: 46 | L22: Present | M22: AC:BD | N22: 10:3 | P22: 1 | AD22: No | AE22: No | AG22: 0
A23: TJud.22.2 | B23: σριον ιηλ | C23: σωτηριον τω ισραηλ | G23: Addition | I23: 1 | J23: 2 | K23: Article | L23: NA | P23: 2475 | AD23: Yes | AE23: No | AG23: 1
A24: TJud.22.2 | B24: παντα τα εθνη | C24: παντα εθνη | G24: Omission | I24: 1 | J24: 2 | K24: Article | L24: NA | O24: Dittography | P24: 2475 | AD24: Yes | AE24: No | AG24: 1
A25: TJud.22.3 | B25: εως του αιωνος | C25: εως αιωνος | G25: Omission | I25: 1 | J25: 3 | K25: Article | L25: Absent | P25: 2475 | AD25: Yes | AE25: Yes | AG25: 1
A26: TJud.22.3 | B26: βασιλειον μου και του σπερματος | C26: βασιλειον μου εκ του σπερματος | G26: Substitution - Word | Q26: -1622 | R26: 1701 | S26: 79 | AD26: Yes | AE26: Yes | AG26: 1
A27: TJud.22.3 | B27: εως του αιωνος | C27: εως αιωνος | G27: Omission | I27: 1 | J27: 3 | K27: Article | L27: Absent | P27: 2475 | AD27: Yes | AE27: Yes | AG27: 1
A28: TDan.6.7 | B28: το δε ονομα | C28: το ονομα | G28: Omission | I28: 1 | J28: 2 | K28: Conjunction | L28: NA | P28: 171 | AD28: Yes | AE28: No | AG28: 1
A29: TDan.6.10 | B29: νομου κυ (11) και θαψατε | C29: νομου του θεου (11) και θαψατε | G29: Addition | I29: 1 | J29: 3 | K29: Article | L29: Absent | P29: 2475 | AD29: Yes | AE29: No | AG29: 1
A30: TDan.6.10 | B30: νομου κυ (11) και θαψατε | C30: νομου του θεου (11) και θαψατε | G30: Substitution - Word | Q30: -118 | R30: 250 | S30: 132 | AD30: Yes | AE30: Yes | AG30: 1
A31: TNaph.1.1 | B31: εν ετει εκατοστω τριακοστω δευτερω της ζωης αυτου | C31: εν ετει ρλ ζωης αυτου | G31: Omission | I31: 1 | J31: 7 | K31: Adjective | L31: Absent | P31: 13 | AD31: Yes | AE31: Yes | AG31: 1
A32: TNaph.1.1 | B32: εν ετει εκατοστω τριακοστω δευτερω της ζωης αυτου | C32: εν ετει ρλ ζωης αυτου | G32: Omission | I32: 1 | J32: 3 | K32: Article | L32: Absent | P32: 2475 | AD32: Yes | AE32: Yes | AG32: 1
A33: TNaph.1.2 | B33: δειπνον αυτος | C33: δειπνον αυτοις | G33: Substitution - Form | AD33: Yes | AE33: Yes | AG33: 1
A34: TNaph.1.3 | B34: μετα το εξυπνισθηναι | C34: μετα του εξυπνισθηναι | G34: Substitution - Form | AD34: Yes | AE34: No | AG34: 1
A35: TNaph.1.6 | B35: εποιησε ραχηλ | C35: εποιησεν η ραχηλ | G35: Addition | I35: 1 | J35: 1 | K35: Article | L35: NA | P35: 2475 | AD35: Yes | AE35: Yes | AG35: 1
A36: TNaph.1.6 | B36: ανθ εαυτης | C36: αντ αυτης | G36: Substitution - Word | Q36: 813 | R36: 17 | S36: 830 | AD36: Yes | AE36: Yes | AG36: 1
A37: TNaph.1.6 | B37: ιακωβ και επι των μηρων ραχηλ ετεκε με δια τουτο εκληθην νεφθαλειμ (7) και ηγαπησε με ραχηλ οτι επι των μηρων αυτης εγεννηθην | C37: ιακωβ και επι των μηρων (7) αυτης εγενηθην | F37: Yes | G37: Omission | I37: 15 | J37: 67 | L37: Present | M37: AC | N37: 12 | P37: 2 | AD37: No | AE37: No | AG37: 0
A38: TNaph.1.7 | B38: κατεφιλει | C38: καταφιλει | F38: Yes | G38: Substitution - Form | AD38: No | AE38: No | AG38: 0
A39: TNaph.1.8 | B39: πασιν ο ιωσηφ | C39: πασιν ιωσηφ | G39: Omission | I39: 1 | J39: 1 | K39: Article | L39: NA | P39: 2475 | AD39: Yes | AE39: Yes | AG39: 1
A40: TNaph.1.9 | B40: και η ραχηλ | C40: και ραχηλ | G40: Omission | I40: 1 | J40: 1 | K40: Article | L40: NA | P40: 2475 | AD40: Yes | AE40: No | AG40: 1
...

Sheet AddOmits
A1: Verse Ref | B1: Autograph | C1: Apograph | D1: Exclusion Grounds | E1: Corrector Followed | F1: Apograph Corrected | G1: Basic Type | H1: Phrase Length | I1: Words Length | J1: Letters Length | K1: Speech Part Add/Omitted | L1: Visual Cues | M1: Cue Regions | N1: Cue Length | O1: Duplicate Material | P1: AO Word Frequency | Q1: Freq-per-10000 | R1: SUB Frequency Difference | S1: SUB_Aut_Freq | T1: SUB_Apog_Freq | U1: Harmonization - Context | V1: Parallel Present | W1: Harmonization - Parallel | X1: Singularity | Y1: Secondary | Z1: Minutiae | AA1: Orthographic - General | AB1: Mere Minutiae | AC1: Nonsense | AD1: Review | AE1: Oo.VI.9.8 | AF1: Barocci | AG1: Smith
A2: TLev.3.3 | B2: εκδικησιν εν τοις πνασι | C2: εκδικησιν τοις πνευμασι | G2: Omission | I2: 1 | J2: 2 | K2: Preposition | L2: NA | P2: 613 | Q2: =IF(ISNUMBER(P2), (P2/$F$95)*10000, "") -> 301.40623 | AE2: Yes | AF2: Yes | AH2: 1
A3: TLev.3.3 | B3: οι δε εις τον τεταρτον | C3: οι δε εις τεταρτον | G3: Omission | I3: 1 | J3: 3 | K3: Article | L3: Present | M3: BD:CD | N3: 3:3 | P3: 2475 | Q3: =IF(ISNUMBER(P3), (P3/$F$95)*10000, "") -> 1216.9338 | AE3: Yes | AF3: No | AH3: 1
A4: TLev.3.4 | B4: εν τω ανωτερω | C4: εν ανωτερω | G4: Omission | I4: 1 | J4: 2 | K4: Article | L4: NA | P4: 2475 | Q4: =IF(ISNUMBER(P4), (P4/$F$95)*10000, "") -> 1216.9338 | AE4: Yes | AF4: No | AH4: 1
A5: TLev.3.9 | B5: επιβλεψη κς | C5: επιβλεψη ο κυριος | G5: Addition | I5: 1 | J5: 1 | K5: Article | L5: NA | P5: 2475 | Q5: =IF(ISNUMBER(P5), (P5/$F$95)*10000, "") -> 1216.9338 | AE5: Yes | AF5: No | AH5: 1
A6: TLev.18.12 | B6: τεκνοις αυτου του πατειν | C6: τεκνοις αυτου πατειν | G6: Omission | I6: 1 | J6: 3 | K6: Article | L6: Present | M6: AB:AC | N6: 3:3 | P6: 2475 | Q6: =IF(ISNUMBER(P6), (P6/$F$95)*10000, "") -> 1216.9338 | AE6: Yes | AF6: No | AH6: 1
A7: TLev.18.13 | B7: τοις τεκνοις | C7: τοις αγαπητοις τεκνοις | F7: Yes | G7: Addition | I7: 1 | J7: 9 | K7: Adjective | L7: Present | M7: AB:AC:BD:CD | N7: 4:4:4:4 | P7: 4 | Q7: =IF(ISNUMBER(P7), (P7/$F$95)*10000, "") -> 1.9667617 | AE7: No | AF7: No | AH7: 0
A8: TLev.19.1 | B8: η νομον κυ | C8: η τον νομον του κυριου | G8: Addition | I8: 1 | J8: 3 | K8: Article | L8: Absent | P8: 2475 | Q8: =IF(ISNUMBER(P8), (P8/$F$95)*10000, "") -> 1216.9338 | AE8: Yes | AF8: Yes | AH8: 1
A9: TLev.19.1 | B9: η νομον κυ | C9: η τον νομον του κυριου | G9: Addition | I9: 1 | J9: 3 | K9: Article | L9: Absent | P9: 2475 | Q9: =IF(ISNUMBER(P9), (P9/$F$95)*10000, "") -> 1216.9338 | AE9: Yes | AF9: No | AH9: 1
A10: TLev.19.1 | B10: εργα βελιαρ | C10: εργα του βελιαρ | G10: Addition | I10: 1 | J10: 3 | K10: Article | L10: Absent | P10: 2475 | Q10: =IF(ISNUMBER(P10), (P10/$F$95)*10000, "") -> 1216.9338 | AE10: Yes | AF10: Yes | AH10: 1
A11: TJud.21.6 | B11: ως θαλασσα | C11: ως η θαλασσα | G11: Addition | I11: 1 | J11: 1 | K11: Article | L11: NA | P11: 2475 | Q11: =IF(ISNUMBER(P11), (P11/$F$95)*10000, "") -> 1216.9338 | AE11: Yes | AF11: Yes | AH11: 1
A12: TJud.21.7 | B12: οτι οι βασιλευοντες | C12: οτι βασιλευοντες | G12: Omission | I12: 1 | J12: 2 | K12: Article | L12: NA | P12: 2475 | Q12: =IF(ISNUMBER(P12), (P12/$F$95)*10000, "") -> 1216.9338 | AE12: Yes | AF12: Yes | AH12: 1
A13: TJud.21.7 | B13: αγρους ποιμνια | C13: αγρους και ποιμνια | G13: Addition | I13: 1 | J13: 3 | K13: Conjunction | L13: Absent | P13: 1701 | Q13: =IF(ISNUMBER(P13), (P13/$F$95)*10000, "") -> 836.36542 | AE13: Yes | AF13: No | AH13: 1
A14: TJud.21.8 | B14: (7) αρπασουσι (8) και πολλων σαρκας αδικως κορακας και ιβεις χορτασουσι και προκοψουσιν | C14: (7) αρπαζουσι (8) και προκοψουσιν | F14: Yes | G14: Omission | I14: 8 | J14: 46 | L14: Present | M14: AC:BD | N14: 10:3 | P14: 1 | Q14: =IF(ISNUMBER(P14), (P14/$F$95)*10000, "") -> 0.49169043 | AE14: No | AF14: No | AH14: 0
A15: TJud.22.2 | B15: σριον ιηλ | C15: σωτηριον τω ισραηλ | G15: Addition | I15: 1 | J15: 2 | K15: Article | L15: NA | P15: 2475 | Q15: =IF(ISNUMBER(P15), (P15/$F$95)*10000, "") -> 1216.9338 | AE15: Yes | AF15: No | AH15: 1
A16: TJud.22.2 | B16: παντα τα εθνη | C16: παντα εθνη | G16: Omission | I16: 1 | J16: 2 | K16: Article | L16: NA | O16: Dittography | P16: 2475 | Q16: =IF(ISNUMBER(P16), (P16/$F$95)*10000, "") -> 1216.9338 | AE16: Yes | AF16: No | AH16: 1
A17: TJud.22.3 | B17: εως του αιωνος | C17: εως αιωνος | G17: Omission | I17: 1 | J17: 3 | K17: Article | L17: Absent | P17: 2475 | Q17: =IF(ISNUMBER(P17), (P17/$F$95)*10000, "") -> 1216.9338 | AE17: Yes | AF17: Yes | AH17: 1
A18: TJud.22.3 | B18: εως του αιωνος | C18: εως αιωνος | G18: Omission | I18: 1 | J18: 3 | K18: Article | L18: Absent | P18: 2475 | Q18: =IF(ISNUMBER(P18), (P18/$F$95)*10000, "") -> 1216.9338 | AE18: Yes | AF18: Yes | AH18: 1
A19: TDan.6.7 | B19: το δε ονομα | C19: το ονομα | G19: Omission | I19: 1 | J19: 2 | K19: Conjunction | L19: NA | P19: 171 | Q19: =IF(ISNUMBER(P19), (P19/$F$95)*10000, "") -> 84.079064 | AE19: Yes | AF19: No | AH19: 1
A20: TDan.6.10 | B20: νομου κυ (11) και θαψατε | C20: νομου του θεου (11) και θαψατε | G20: Addition | I20: 1 | J20: 3 | K20: Article | L20: Absent | P20: 2475 | Q20: =IF(ISNUMBER(P20), (P20/$F$95)*10000, "") -> 1216.9338 | AE20: Yes | AF20: No | AH20: 1
A21: TNaph.1.1 | B21: εν ετει εκατοστω τριακοστω δευτερω της ζωης αυτου | C21: εν ετει ρλ ζωης αυτου | G21: Omission | I21: 1 | J21: 7 | K21: Adjective | L21: Absent | P21: 13 | Q21: =IF(ISNUMBER(P21), (P21/$F$95)*10000, "") -> 6.3919756 | AE21: Yes | AF21: Yes | AH21: 1
A22: TNaph.1.1 | B22: εν ετει εκατοστω τριακοστω δευτερω της ζωης αυτου | C22: εν ετει ρλ ζωης αυτου | G22: Omission | I22: 1 | J22: 3 | K22: Article | L22: Absent | P22: 2475 | Q22: =IF(ISNUMBER(P22), (P22/$F$95)*10000, "") -> 1216.9338 | AE22: Yes | AF22: Yes | AH22: 1
A23: TNaph.1.6 | B23: εποιησε ραχηλ | C23: εποιησεν η ραχηλ | G23: Addition | I23: 1 | J23: 1 | K23: Article | L23: NA | P23: 2475 | Q23: =IF(ISNUMBER(P23), (P23/$F$95)*10000, "") -> 1216.9338 | AE23: Yes | AF23: Yes | AH23: 1
A24: TNaph.1.6 | B24: ιακωβ και επι των μηρων ραχηλ ετεκε με δια τουτο εκληθην νεφθαλειμ (7) και ηγαπησε με ραχηλ οτι επι των μηρων αυτης εγεννηθην | C24: ιακωβ και επι των μηρων (7) αυτης εγενηθην | F24: Yes | G24: Omission | I24: 15 | J24: 67 | L24: Present | M24: AC | N24: 12 | P24: 2 | Q24: =IF(ISNUMBER(P24), (P24/$F$95)*10000, "") -> 0.98338086 | AE24: No | AF24: No | AH24: 0
A25: TNaph.1.8 | B25: πασιν ο ιωσηφ | C25: πασιν ιωσηφ | G25: Omission | I25: 1 | J25: 1 | K25: Article | L25: NA | P25: 2475 | Q25: =IF(ISNUMBER(P25), (P25/$F$95)*10000, "") -> 1216.9338 | AE25: Yes | AF25: Yes | AH25: 1
A26: TNaph.1.9 | B26: και η ραχηλ | C26: και ραχηλ | G26: Omission | I26: 1 | J26: 1 | K26: Article | L26: NA | P26: 2475 | Q26: =IF(ISNUMBER(P26), (P26/$F$95)*10000, "") -> 1216.9338 | AE26: Yes | AF26: No | AH26: 1
A27: TNaph.1.10 | B27: γενους ην αβρααμ | C27: γενους αβρααμ | G27: Omission | I27: 1 | J27: 2 | K27: Verb | L27: NA | P27: 295 | Q27: =IF(ISNUMBER(P27), (P27/$F$95)*10000, "") -> 145.04868 | AE27: Yes | AF27: Yes | AH27: 1
A28: TNaph.1.11 | B28: παιδισκην αυτου εις γυναικα | C28: παιδισκην αυτου γυναικα | G28: Omission | I28: 1 | J28: 3 | K28: Preposition | L28: Absent | P28: 210 | Q28: =IF(ISNUMBER(P28), (P28/$F$95)*10000, "") -> 103.25499 | AE28: Yes | AF28: No | AH28: 1
A29: TNaph.1.12 | B29: (11) ηχμαλωτευθη (12) εξ ης ετεκε | C29: (11) ηχμαλωτευθη (12) και εξης ετεκε | G29: Addition | I29: 1 | J29: 3 | K29: Conjunction | L29: Absent | P29: 1701 | Q29: =IF(ISNUMBER(P29), (P29/$F$95)*10000, "") -> 836.36542 | AE29: Yes | AF29: Yes | AH29: 1
A30: TNaph.2.1 | B30: τοις ποσι μου ως ελαφος | C30: τοις ποσιν ως ελαφος | G30: Omission | I30: 1 | J30: 3 | K30: Pronoun | L30: Absent | P30: 743 | Q30: =IF(ISNUMBER(P30), (P30/$F$95)*10000, "") -> 365.32599 | AE30: Yes | AF30: Yes | AH30: 1
A31: TNaph.2.8 | B31: αισθησεις εν τη κεφαλη και τον τραχηλον συναπτει τη κεφαλη και τριχας | C31: αισθησεις τη κεφαλη και τριχας | G31: Omission | I31: 7 | J31: 32 | L31: Present | M31: AC:BD | N31: 3:12 | Q31: =IF(ISNUMBER(P31), (P31/$F$95)*10000, "") | AE31: No | AF31: No | AH31: 0
A32: TNaph.2.10 | B32: (9) καιρου αυτου (10) οτι εαν ειπης τω οφθαλμω ακουσαι ου δυναται ουτως | C32: (9) καιρου αυτου (10) ου δυναται ουν οτι εαν ειπης τω οφθαλμω ακουσασαι ουτως | G32: Addition | I32: 1 | J32: 3 | K32: Conjunction | L32: Absent | P32: 86 | Q32: =IF(ISNUMBER(P32), (P32/$F$95)*10000, "") -> 42.285377 | AE32: Yes | AF32: Yes | AH32: 1
A33: TNaph.2.10 | B33: ουδε εν σκοτει δυνησεσθε ποιησαι εργα φωτος | C33: ουδε εν σκοτεις ποιειν εργα φωτος | G33: Omission | I33: 1 | J33: 9 | K33: Verb | L33: Absent | P33: 18 | Q33: =IF(ISNUMBER(P33), (P33/$F$95)*10000, "") -> 8.8504278 | AE33: Yes | AF33: No | AH33: 1
A34: TNaph.3.3 | B34: αφεντα τον κν ηλλοιωσαν | C34: αφεντα κυριον κλλοιωσαν | G34: Omission | I34: 1 | J34: 3 | K34: Article | L34: Absent | P34: 2475 | Q34: =IF(ISNUMBER(P34), (P34/$F$95)*10000, "") -> 1216.9338 | AE34: Yes | AF34: Yes | AH34: 1
A35: TNaph.3.4 | B35: υμεις δε μη ουτως | C35: υμεις μη ουτως | G35: Omission | I35: 1 | J35: 2 | K35: Conjunction | L35: NA | P35: 171 | Q35: =IF(ISNUMBER(P35), (P35/$F$95)*10000, "") -> 84.079064 | AE35: Yes | AF35: No | AH35: 1
A36: TNaph.3.4 | B36: και εν θαλασση | C36: και θαλασση | G36: Omission | I36: 1 | J36: 2 | K36: Preposition | L36: NA | P36: 613 | Q36: =IF(ISNUMBER(P36), (P36/$F$95)*10000, "") -> 301.40623 | AE36: Yes | AF36: Yes | AH36: 1
A37: TNaph.3.5 | B37: ους και κατηρασατο | C37: ους κατηρασατο | G37: Omission | I37: 1 | J37: 3 | K37: Conjunction | L37: Absent | P37: 1701 | Q37: =IF(ISNUMBER(P37), (P37/$F$95)*10000, "") -> 836.36542 | AE37: Yes | AF37: Yes | AH37: 1
A38: TNaph.4.1 | B38: καιγε και υμεις | C38: καιγε υμεις | G38: Omission | I38: 1 | J38: 3 | K38: Conjunction | L38: Absent | P38: 1701 | Q38: =IF(ISNUMBER(P38), (P38/$F$95)*10000, "") -> 836.36542 | AE38: Yes | AF38: Yes | AH38: 1
A39: TNaph.4.2 | B39: εως αν αναλωση | C39: εως αναλωση | G39: Omission | I39: 1 | J39: 2 | K39: Particle | L39: NA | P39: 10 | Q39: =IF(ISNUMBER(P39), (P39/$F$95)*10000, "") -> 4.9169043 | AE39: Yes | AF39: No | AH39: 1
A40: TNaph.5.3 | B40: και ο λευι | C40: και λευι | G40: Omission | I40: 1 | J40: 1 | K40: Article | L40: NA | P40: 2475 | Q40: =IF(ISNUMBER(P40), (P40/$F$95)*10000, "") -> 1216.9338 | AE40: Yes | AF40: Yes | AH40: 1
...

Sheet WF_AO_LM
A1: Verse Ref | B1: Autograph | C1: Apograph | D1: Exclusion Grounds | E1: Corrector Followed | F1: Apograph Corrected | G1: Basic Type | H1: Phrase Length | I1: Words Length | J1: Letters Length | K1: Speech Part Add/Omitted | L1: Visual Cues | M1: Cue Regions | N1: Cue Length | O1: Duplicate Material | P1: AO Word Frequency | Q1: Freq-per-10000 | R1: SUB Frequency Difference | S1: SUB_Aut_Freq | T1: SUB_Apog_Freq | U1: Harmonization - Context | V1: Parallel Present | W1: Harmonization - Parallel | X1: Singularity | Y1: Secondary | Z1: Minutiae | AA1: Orthographic - General | AB1: Mere Minutiae | AC1: Nonsense | AD1: Review | AE1: Oo.VI.9.8 | AF1: Barocci | AG1: Smith
A2: TLev.3.3 | B2: εκδικησιν εν τοις πνασι | C2: εκδικησιν τοις πνευμασι | G2: Omission | I2: 1 | J2: 2 | K2: Preposition | L2: NA | P2: 613 | Q2: 301.40623 | AE2: Yes | AF2: Yes | AH2: 1
A3: TLev.3.3 | B3: οι δε εις τον τεταρτον | C3: οι δε εις τεταρτον | G3: Omission | I3: 1 | J3: 3 | K3: Article | L3: Present | M3: BD:CD | N3: 3:3 | P3: 2475 | Q3: 1216.9338 | AE3: Yes | AF3: No | AH3: 1
A4: TLev.3.4 | B4: εν τω ανωτερω | C4: εν ανωτερω | G4: Omission | I4: 1 | J4: 2 | K4: Article | L4: NA | P4: 2475 | Q4: 1216.9338 | AE4: Yes | AF4: No | AH4: 1
A5: TLev.3.9 | B5: επιβλεψη κς | C5: επιβλεψη ο κυριος | G5: Addition | I5: 1 | J5: 1 | K5: Article | L5: NA | P5: 2475 | Q5: 1216.9338 | AE5: Yes | AF5: No | AH5: 1
A6: TLev.18.12 | B6: τεκνοις αυτου του πατειν | C6: τεκνοις αυτου πατειν | G6: Omission | I6: 1 | J6: 3 | K6: Article | L6: Present | M6: AB:AC | N6: 3:3 | P6: 2475 | Q6: 1216.9338 | AE6: Yes | AF6: No | AH6: 1
A7: TLev.19.1 | B7: η νομον κυ | C7: η τον νομον του κυριου | G7: Addition | I7: 1 | J7: 3 | K7: Article | L7: Absent | P7: 2475 | Q7: 1216.9338 | AE7: Yes | AF7: Yes | AH7: 1
A8: TLev.19.1 | B8: η νομον κυ | C8: η τον νομον του κυριου | G8: Addition | I8: 1 | J8: 3 | K8: Article | L8: Absent | P8: 2475 | Q8: 1216.9338 | AE8: Yes | AF8: No | AH8: 1
A9: TLev.19.1 | B9: εργα βελιαρ | C9: εργα του βελιαρ | G9: Addition | I9: 1 | J9: 3 | K9: Article | L9: Absent | P9: 2475 | Q9: 1216.9338 | AE9: Yes | AF9: Yes | AH9: 1
A10: TJud.21.6 | B10: ως θαλασσα | C10: ως η θαλασσα | G10: Addition | I10: 1 | J10: 1 | K10: Article | L10: NA | P10: 2475 | Q10: 1216.9338 | AE10: Yes | AF10: Yes | AH10: 1
A11: TJud.21.7 | B11: οτι οι βασιλευοντες | C11: οτι βασιλευοντες | G11: Omission | I11: 1 | J11: 2 | K11: Article | L11: NA | P11: 2475 | Q11: 1216.9338 | AE11: Yes | AF11: Yes | AH11: 1
A12: TJud.21.7 | B12: αγρους ποιμνια | C12: αγρους και ποιμνια | G12: Addition | I12: 1 | J12: 3 | K12: Conjunction | L12: Absent | P12: 1701 | Q12: 836.36542 | AE12: Yes | AF12: No | AH12: 1
A13: TJud.22.2 | B13: σριον ιηλ | C13: σωτηριον τω ισραηλ | G13: Addition | I13: 1 | J13: 2 | K13: Article | L13: NA | P13: 2475 | Q13: 1216.9338 | AE13: Yes | AF13: No | AH13: 1
A14: TJud.22.2 | B14: παντα τα εθνη | C14: παντα εθνη | G14: Omission | I14: 1 | J14: 2 | K14: Article | L14: NA | O14: Dittography | P14: 2475 | Q14: 1216.9338 | AE14: Yes | AF14: No | AH14: 1
A15: TJud.22.3 | B15: εως του αιωνος | C15: εως αιωνος | G15: Omission | I15: 1 | J15: 3 | K15: Article | L15: Absent | P15: 2475 | Q15: 1216.9338 | AE15: Yes | AF15: Yes | AH15: 1
A16: TJud.22.3 | B16: εως του αιωνος | C16: εως αιωνος | G16: Omission | I16: 1 | J16: 3 | K16: Article | L16: Absent | P16: 2475 | Q16: 1216.9338 | AE16: Yes | AF16: Yes | AH16: 1
A17: TDan.6.7 | B17: το δε ονομα | C17: το ονομα | G17: Omission | I17: 1 | J17: 2 | K17: Conjunction | L17: NA | P17: 171 | Q17: 84.079064 | AE17: Yes | AF17: No | AH17: 1
A18: TDan.6.10 | B18: νομου κυ (11) και θαψατε | C18: νομου του θεου (11) και θαψατε | G18: Addition | I18: 1 | J18: 3 | K18: Article | L18: Absent | P18: 2475 | Q18: 1216.9338 | AE18: Yes | AF18: No | AH18: 1
A19: TNaph.1.1 | B19: εν ετει εκατοστω τριακοστω δευτερω της ζωης αυτου | C19: εν ετει ρλ ζωης αυτου | G19: Omission | I19: 1 | J19: 3 | K19: Article | L19: Absent | P19: 2475 | Q19: 1216.9338 | AE19: Yes | AF19: Yes | AH19: 1
A20: TNaph.1.6 | B20: εποιησε ραχηλ | C20: εποιησεν η ραχηλ | G20: Addition | I20: 1 | J20: 1 | K20: Article | L20: NA | P20: 2475 | Q20: 1216.9338 | AE20: Yes | AF20: Yes | AH20: 1
A21: TNaph.1.8 | B21: πασιν ο ιωσηφ | C21: πασιν ιωσηφ | G21: Omission | I21: 1 | J21: 1 | K21: Article | L21: NA | P21: 2475 | Q21: 1216.9338 | AE21: Yes | AF21: Yes | AH21: 1
A22: TNaph.1.9 | B22: και η ραχηλ | C22: και ραχηλ | G22: Omission | I22: 1 | J22: 1 | K22: Article | L22: NA | P22: 2475 | Q22: 1216.9338 | AE22: Yes | AF22: No | AH22: 1
A23: TNaph.1.11 | B23: παιδισκην αυτου εις γυναικα | C23: παιδισκην αυτου γυναικα | G23: Omission | I23: 1 | J23: 3 | K23: Preposition | L23: Absent | P23: 210 | Q23: 103.25499 | AE23: Yes | AF23: No | AH23: 1
A24: TNaph.1.12 | B24: (11) ηχμαλωτευθη (12) εξ ης ετεκε | C24: (11) ηχμαλωτευθη (12) και εξης ετεκε | G24: Addition | I24: 1 | J24: 3 | K24: Conjunction | L24: Absent | P24: 1701 | Q24: 836.36542 | AE24: Yes | AF24: Yes | AH24: 1
A25: TNaph.2.1 | B25: τοις ποσι μου ως ελαφος | C25: τοις ποσιν ως ελαφος | G25: Omission | I25: 1 | J25: 3 | K25: Pronoun | L25: Absent | P25: 743 | Q25: 365.32599 | AE25: Yes | AF25: Yes | AH25: 1
A26: TNaph.2.10 | B26: (9) καιρου αυτου (10) οτι εαν ειπης τω οφθαλμω ακουσαι ου δυναται ουτως | C26: (9) καιρου αυτου (10) ου δυναται ουν οτι εαν ειπης τω οφθαλμω ακουσασαι ουτως | G26: Addition | I26: 1 | J26: 3 | K26: Conjunction | L26: Absent | P26: 86 | Q26: 42.285377 | AE26: Yes | AF26: Yes | AH26: 1
... A35: TNaph.5.5 | B35: και ιουδας | C35: και ο ιουδας | G35: Addition | I35: 1 | J35: 1 | K35: Article | L35: NA | P35: 2475 | Q35: 1216.9338 | AE35: Yes | AF35: Yes | AH35: 1
D40: Words in corpus (Genesis - Deuteronomy) | E40: 20338
D41: Med-word-freq | E41: =MEDIAN(Q:Q) -> 1216.9338
D44: HF-adds | E44: =COUNTIFS(G:G, "Addition", Q:Q, ">=" & $E$41) -> 9 | F44: just articles
D45: HF-omits | E45: =COUNTIFS(G:G, "Omission", Q:Q, ">=" & $E$41) -> 13
D46: HF-add-ratio | E46: =E44/(E44+E45) -> 0.40909091
D47: LF-adds | E47: =COUNTIFS(G:G, "Addition", Q:Q, "<" & $E$41) -> 3
D48: LF-omits | E48: =COUNTIFS(G:G, "Omission", Q:Q, "<" & $E$41) -> 9
D49: LF-add-ratio | E49: =E47/(E47+E48) -> 0.25
D52: art-adds | E52: =COUNTIFS(G:G, "Addition", K:K, "Article") -> 9
D53: art-omits | E53: =COUNTIFS(G:G, "Omission", K:K, "Article") -> 13
D54: art-add-rate | E54: =COUNTIFS(G:G, "Addition", K:K, "Article")/(COUNTIFS(G:G, "Addition", K:K, "Article") + COUNTIFS(G:G, "Omission", K:K, "Article")) -> 0.40909091

Sheet WF_AO_HM
A1: Verse Ref | B1: Autograph | C1: Apograph | D1: Exclusion Grounds | E1: Corrector Followed | F1: Apograph Corrected | G1: Basic Type | H1: Phrase Length | I1: Words Length | J1: Letters Length | K1: Speech Part Add/Omitted | L1: Visual Cues | M1: Cue Regions | N1: Cue Length | O1: Duplicate Material | P1: AO Word Frequency | Q1: Freq-per-10000 | R1: SUB Frequency Difference | S1: SUB_Aut_Freq | T1: SUB_Apog_Freq | U1: Harmonization - Context | V1: Parallel Present | W1: Harmonization - Parallel | X1: Singularity | Y1: Secondary | Z1: Minutiae | AA1: Orthographic - General | AB1: Mere Minutiae | AC1: Nonsense | AD1: Review | AE1: Oo.VI.9.8 | AF1: Barocci | AG1: Smith
A2: TLev.18.13 | B2: τοις τεκνοις | C2: τοις αγαπητοις τεκνοις | F2: Yes | G2: Addition | I2: 1 | J2: 9 | K2: Adjective | L2: Present | M2: AB:AC:BD:CD | N2: 4:4:4:4 | P2: 4 | Q2: 1.9667617 | AE2: No | AF2: No | AH2: 0
A3: TNaph.1.1 | B3: εν ετει εκατοστω τριακοστω δευτερω της ζωης αυτου | C3: εν ετει ρλ ζωης αυτου | G3: Omission | I3: 1 | J3: 7 | K3: Adjective | L3: Absent | P3: 13 | Q3: 6.3919756 | AE3: Yes | AF3: Yes | AH3: 1
A4: TNaph.1.10 | B4: γενους ην αβρααμ | C4: γενους αβρααμ | G4: Omission | I4: 1 | J4: 2 | K4: Verb | L4: NA | P4: 295 | Q4: 145.04868 | AE4: Yes | AF4: Yes | AH4: 1
A5: TNaph.2.10 | B5: ουδε εν σκοτει δυνησεσθε ποιησαι εργα φωτος | C5: ουδε εν σκοτεις ποιειν εργα φωτος | G5: Omission | I5: 1 | J5: 9 | K5: Verb | L5: Absent | P5: 18 | Q5: 8.8504278 | AE5: Yes | AF5: No | AH5: 1
D8: Words in corpus (Genesis - Deuteronomy) | E8: 20338
D9: Med-word-freq | E9: =MEDIAN(Q:Q) -> 7.6212017
D12: HF-adds | E12: =COUNTIFS(G:G, "Addition", Q:Q, ">=" & $E$9) -> 0 | F12: not enough data
D13: HF-omits | E13: =COUNTIFS(G:G, "Omission", Q:Q, ">=" & $E$9) -> 2
D14: HF-add-ratio | E14: =E12/(E12+E13) -> 0
D15: LF-adds | E15: =COUNTIFS(G:G, "Addition", Q:Q, "<" & $E$9) -> 1
D16: LF-omits | E16: =COUNTIFS(G:G, "Omission", Q:Q, "<" & $E$9) -> 1
D17: LF-add-ratio | E17: =E15/(E15+E16) -> 0.5
D18: AddRatioDiff | E18: =E14-E17 -> -0.5

Sheet WF_SUB
A1: Verse Ref | B1: Autograph | C1: Apograph | D1: Exclusion Grounds | E1: Corrector Followed | F1: Apograph Corrected | G1: Basic Type | H1: Phrase Length | I1: Words Length | J1: Letters Length | K1: Speech Part Add/Omitted | L1: Visual Cues | M1: Cue Regions | N1: Cue Length | O1: Duplicate Material | P1: AO Word Frequency | Q1: SUB Frequency Difference | R1: SUB_Aut_Freq | S1: SUB_Apog_Freq | T1: Aut_P10K_Freq | U1: Apog_P10K_Freq | V1: P10K_Freq_Diff | W1: Harmonization - Context | X1: Parallel Present | Y1: Harmonization - Parallel | Z1: Singularity | AA1: Secondary | AB1: Minutiae | AC1: Orthographic - General | AD1: Mere Minutiae | AE1: Nonsense | AF1: Review | AG1: Oo.VI.9.8 | AH1: Barocci | AI1: Smith
A2: TLev.4.1 | B2: οτι των πετρων | C2: οτε των πετρων | G2: Substitution - Word | Q2: -249 | R2: 280 | S2: 31 | T2: =IF(ISNUMBER(R2), (R2/$E$14)*10000, "") -> 137.67332 | U2: =IF(ISNUMBER(S2), (S2/$E$14)*10000, "") -> 15.242403 | V2: =IF(ISNUMBER(Q2), U2-T2, "") -> -122.43092 | AG2: Yes | AH2: No | AJ2: 1
A3: TLev.18.14 | B3: χαρισομαι | C3: χαρησομαι | G3: Substitution - Word | Q3: 7 | R3: 1 | S3: 8 | T3: =IF(ISNUMBER(R3), (R3/$E$14)*10000, "") -> 0.49169043 | U3: =IF(ISNUMBER(S3), (S3/$E$14)*10000, "") -> 3.9335235 | V3: =IF(ISNUMBER(Q3), U3-T3, "") -> 3.441833 | AG3: No | AH3: No | AJ3: 0
A4: TJud.22.3 | B4: βασιλειον μου και του σπερματος | C4: βασιλειον μου εκ του σπερματος | G4: Substitution - Word | Q4: -1622 | R4: 1701 | S4: 79 | T4: =IF(ISNUMBER(R4), (R4/$E$14)*10000, "") -> 836.36542 | U4: =IF(ISNUMBER(S4), (S4/$E$14)*10000, "") -> 38.843544 | V4: =IF(ISNUMBER(Q4), U4-T4, "") -> -797.52188 | AG4: Yes | AH4: Yes | AJ4: 1
A5: TDan.6.10 | B5: νομου κυ (11) και θαψατε | C5: νομου του θεου (11) και θαψατε | G5: Substitution - Word | Q5: -118 | R5: 250 | S5: 132 | T5: =IF(ISNUMBER(R5), (R5/$E$14)*10000, "") -> 122.92261 | U5: =IF(ISNUMBER(S5), (S5/$E$14)*10000, "") -> 64.903137 | V5: =IF(ISNUMBER(Q5), U5-T5, "") -> -58.019471 | AG5: Yes | AH5: Yes | AJ5: 1
A6: TNaph.1.6 | B6: ανθ εαυτης | C6: αντ αυτης | G6: Substitution - Word | Q6: 813 | R6: 17 | S6: 830 | T6: =IF(ISNUMBER(R6), (R6/$E$14)*10000, "") -> 8.3587373 | U6: =IF(ISNUMBER(S6), (S6/$E$14)*10000, "") -> 408.10306 | V6: =IF(ISNUMBER(Q6), U6-T6, "") -> 399.74432 | AG6: Yes | AH6: Yes | AJ6: 1
A7: TNaph.2.8 | B7: νεφρους | C7: νεφους | F7: Yes | G7: Substitution - Word | Q7: -1 | R7: 1 | S7: 0 | T7: =IF(ISNUMBER(R7), (R7/$E$14)*10000, "") -> 0.49169043 | U7: =IF(ISNUMBER(S7), (S7/$E$14)*10000, "") -> 0 | V7: =IF(ISNUMBER(Q7), U7-T7, "") -> -0.49169043 | AG7: Yes | AH7: No | AJ7: 1
A8: TNaph.3.4 | B8: ποιησαντα ταυτα παντα | C8: ποιησαντα τα παντα | G8: Substitution - Word | Q8: 2325 | R8: 150 | S8: 2475 | T8: =IF(ISNUMBER(R8), (R8/$E$14)*10000, "") -> 73.753565 | U8: =IF(ISNUMBER(S8), (S8/$E$14)*10000, "") -> 1216.9338 | V8: =IF(ISNUMBER(Q8), U8-T8, "") -> 1143.1803 | AG8: Yes | AH8: Yes | AJ8: 1
A9: TNaph.4.1 | B9: οτι ανεγνων | C9: οτι εγνων | G9: Substitution - Word | Q9: 26 | R9: 5 | S9: 31 | T9: =IF(ISNUMBER(R9), (R9/$E$14)*10000, "") -> 2.4584522 | U9: =IF(ISNUMBER(S9), (S9/$E$14)*10000, "") -> 15.242403 | V9: =IF(ISNUMBER(Q9), U9-T9, "") -> 12.783951 | AG9: Yes | AH9: Yes | AJ9: 1
A10: TNaph.5.7 | B10: φθασας γαρ ιωσηφ | C10: φθασας δε ιωσηφ | G10: Substitution - Word | Q10: -15 | R10: 186 | S10: 171 | T10: =IF(ISNUMBER(R10), (R10/$E$14)*10000, "") -> 91.45442 | U10: =IF(ISNUMBER(S10), (S10/$E$14)*10000, "") -> 84.079064 | V10: =IF(ISNUMBER(Q10), U10-T10, "") -> -7.3753565 | AG10: Yes | AH10: Yes | AJ10: 1
A11: TNaph.5.7 | B11: συνανηλθεν αυτω εις υψος (8) και ειδον | C11: συνηλθεν αυτω εις υψος εις υψος (8) και ειδον | G11: Substitution - Word | Q11: 3 | R11: 1 | S11: 4 | T11: =IF(ISNUMBER(R11), (R11/$E$14)*10000, "") -> 0.49169043 | U11: =IF(ISNUMBER(S11), (S11/$E$14)*10000, "") -> 1.9667617 | V11: =IF(ISNUMBER(Q11), U11-T11, "") -> 1.4750713 | AG11: Yes | AH11: Yes | AJ11: 1
D14: Words in corpus (Genesis - Deuteronomy) | E14: 20338
D17: pos | E17: =COUNTIF(Q:Q, ">0") -> 5
D18: neg | E18: =COUNTIF(Q:Q, "<0") -> 5
D19: p = | E19: =_xlfn.BINOM.DIST(MIN(E17,E18),(E17+E18),0.5,TRUE)*2 -> 1.2460938
D21: avg_diff | E21: =AVERAGE(Q:Q) -> 116.9
D22: stdv | E22: =_xlfn.STDEV.S(Q:Q) -> 979.66587
D25: avg_P10K_diff | E25: =AVERAGE(V:V) -> 57.478611
D26: P10K_stdv | E26: =_xlfn.STDEV.S(V:V) -> 481.69233
D29: total_subs | E29: =COUNT(V:V) -> 10
D30: std_dev | E30: =_xlfn.STDEV.P(V:V) -> 456.97347

Sheet Harmonization
A1: Verse Ref | B1: Autograph | C1: Apograph | D1: Exclusion Grounds | E1: Corrector Followed | F1: Apograph Corrected | G1: Detail | H1: Basic Type | I1: Phrase Length | J1: Words Length | K1: Letters Length | L1: Speech Part Add/Omitted | M1: Visual Cues | N1: Cue Regions | O1: Cue Length | P1: Duplicate Material | Q1: AO Word Frequency | R1: SUB Frequency Difference | S1: SUB_Aut_Freq | T1: SUB_Apog_Freq | U1: Harmonization - Context | V1: Harmonization_Direction | W1: Parallel Present | X1: Harmonization - Parallel | Y1: Singularity | Z1: Secondary | AA1: Minutiae | AB1: Orthographic - General | AC1: Mere Minutiae | AD1: Nonsense | AE1: Review | AF1: Oo.VI.9.8 | AG1: Barocci | AH1: Smith
A2: TNaph.2.4 | B2: ουτω και | C2: ουτως και | G2: the phrase ουτω και occurs 6x more in the near context (cf. v. 2), always without the sigma; apograph disharmonizes | H2: Substitution - Form | U2: Disharmonizing | V2: Both | AF2: Yes | AG2: No | AI2: 1
D5: Harmonizations | E5: =COUNTIF(U:U, "Harmonizing") -> 0
D6: Disharmonizations | E6: =COUNTIF(U:U, "Disharmonizing") -> 1
D7: Harm_Ratio | E7: =E5/(E5+E6) -> 0
E10: Directionality
E11: Forward | F11: Backward | G11: Both | H11: Total
D12: Harmonizations | E12: =COUNTIFS($U$2:$U$2,"Harmonizing",$V$2:$V$2,"forward") + COUNTIFS($U$2:$U$2,"Harmonizing",$V$2:$V$2,"both") -> 0 | F12: =COUNTIFS($U$2:$U$2,"Harmonizing",$V$2:$V$2,"backward") + COUNTIFS($U$2:$U$2,"Harmonizing",$V$2:$V$2,"both") -> 0 | G12: =COUNTIFS($U$2:$U$2,"Harmonizing",$V$2:$V$2,"both") -> 0 | H12: =COUNTIFS($U$2:$U$2,"Harmonizing",$V$2:$V$2,"both") + COUNTIFS($U$2:$U$2,"Harmonizing",$V$2:$V$2,"forward") + COUNTIFS($U$2:$U$2,"Harmonizing",$V$2:$V$2,"backward") -> 0
D13: Disharmonizations | E13: =COUNTIFS($U$2:$U$2,"Disharmonizing",$V$2:$V$2,"forward") + COUNTIFS($U$2:$U$2,"Disharmonizing",$V$2:$V$2,"both") -> 1 | F13: =COUNTIFS($U$2:$U$2,"Disharmonizing",$V$2:$V$2,"backward") + COUNTIFS($U$2:$U$2,"Disharmonizing",$V$2:$V$2,"both") -> 1 | G13: =COUNTIFS($U$2:$U$2,"Disharmonizing",$V$2:$V$2,"both") -> 1 | H13: =COUNTIFS($U$2:$U$2,"Disharmonizing",$V$2:$V$2,"both") + COUNTIFS($U$2:$U$2,"Disharmonizing",$V$2:$V$2,"forward") + COUNTIFS($U$2:$U$2,"Disharmonizing",$V$2:$V$2,"backward") -> 1
D14: Harm_Ratio | E14: =E12/(E12+E13) -> 0 | F14: =F12/(F12+F13) -> 0 | G14: =G12/(G12+G13) -> 0 | H14: =H12/(H12+H13) -> 0

Sheet Gen-filters_2
A1: Verse Ref | B1: Autograph | C1: Apograph | D1: Exclusion Grounds | E1: Corrector Followed | F1: Apograph Corrected | G1: Basic Type | H1: Phrase Length | I1: Words Length | J1: Letters Length | K1: Speech Part Add/Omitted | L1: Visual Cues | M1: Cue Regions | N1: Cue Length | O1: Duplicate Material | P1: AO Word Frequency | Q1: SUB Frequency Difference | R1: SUB_Aut_Freq | S1: SUB_Apog_Freq | T1: Harmonization - Context | U1: Parallel Present | V1: Harmonization - Parallel | W1: Singularity | X1: Secondary | Y1: Minutiae | Z1: Orthographic - General | AA1: Mere Minutiae | AB1: Nonsense | AC1: Review | AD1: Oo.VI.9.8 | AE1: Barocci | AF1: Smith
A2: TLev.3.3 | B2: οι δε εις τον τεταρτον | C2: οι δε εις τεταρτον | G2: Omission | I2: 1 | J2: 3 | K2: Article | L2: Present | M2: BD:CD | N2: 3:3 | P2: 2475 | AD2: Yes | AE2: No | AG2: 1
A3: TLev.3.4 | B3: εν τω ανωτερω | C3: εν ανωτερω | G3: Omission | I3: 1 | J3: 2 | K3: Article | L3: NA | P3: 2475 | AD3: Yes | AE3: No | AG3: 1
A4: TLev.3.9 | B4: επιβλεψη κς | C4: επιβλεψη ο κυριος | G4: Addition | I4: 1 | J4: 1 | K4: Article | L4: NA | P4: 2475 | AD4: Yes | AE4: No | AG4: 1
A5: TLev.4.1 | B5: οτι των πετρων | C5: οτε των πετρων | G5: Substitution - Word | Q5: -249 | R5: 280 | S5: 31 | AD5: Yes | AE5: No | AG5: 1
A6: TLev.18.12 | B6: τεκνοις αυτου του πατειν | C6: τεκνοις αυτου πατειν | G6: Omission | I6: 1 | J6: 3 | K6: Article | L6: Present | M6: AB:AC | N6: 3:3 | P6: 2475 | AD6: Yes | AE6: No | AG6: 1
A7: TLev.18.13 | B7: τοις τεκνοις | C7: τοις αγαπητοις τεκνοις | F7: Yes | G7: Addition | I7: 1 | J7: 9 | K7: Adjective | L7: Present | M7: AB:AC:BD:CD | N7: 4:4:4:4 | P7: 4 | AD7: No | AE7: No | AG7: 0
A8: TLev.18.14 | B8: χαρισομαι | C8: χαρησομαι | G8: Substitution - Word | Q8: 7 | R8: 1 | S8: 8 | AD8: No | AE8: No | AG8: 0
A9: TLev.19.1 | B9: η νομον κυ | C9: η τον νομον του κυριου | G9: Addition | I9: 1 | J9: 3 | K9: Article | L9: Absent | P9: 2475 | AD9: Yes | AE9: No | AG9: 1
A10: TLev.19.3 | B10: ειπωμεν | C10: ειπαμεν | G10: Substitution - Form | AD10: Yes | AE10: No | AG10: 1
A11: TJud.21.7 | B11: αγρους ποιμνια | C11: αγρους και ποιμνια | G11: Addition | I11: 1 | J11: 3 | K11: Conjunction | L11: Absent | P11: 1701 | AD11: Yes | AE11: No | AG11: 1
A12: TJud.21.7 | B12: (7) αρπασουσι (8) και πολλων σαρκας αδικως κορακας και ιβεις χορτασουσι και προκοψουσιν | C12: (7) αρπαζουσι (8) και προκοψουσιν | F12: Yes | G12: Substitution - Form | AD12: Yes | AE12: No | AG12: 1
A13: TJud.21.8 | B13: (7) αρπασουσι (8) και πολλων σαρκας αδικως κορακας και ιβεις χορτασουσι και προκοψουσιν | C13: (7) αρπαζουσι (8) και προκοψουσιν | F13: Yes | G13: Omission | I13: 8 | J13: 46 | L13: Present | M13: AC:BD | N13: 10:3 | P13: 1 | AD13: No | AE13: No | AG13: 0
A14: TJud.22.2 | B14: σριον ιηλ | C14: σωτηριον τω ισραηλ | G14: Addition | I14: 1 | J14: 2 | K14: Article | L14: NA | P14: 2475 | AD14: Yes | AE14: No | AG14: 1
A15: TJud.22.2 | B15: παντα τα εθνη | C15: παντα εθνη | G15: Omission | I15: 1 | J15: 2 | K15: Article | L15: NA | O15: Dittography | P15: 2475 | AD15: Yes | AE15: No | AG15: 1
A16: TDan.6.7 | B16: το δε ονομα | C16: το ονομα | G16: Omission | I16: 1 | J16: 2 | K16: Conjunction | L16: NA | P16: 171 | AD16: Yes | AE16: No | AG16: 1
A17: TDan.6.10 | B17: νομου κυ (11) και θαψατε | C17: νομου του θεου (11) και θαψατε | G17: Addition | I17: 1 | J17: 3 | K17: Article | L17: Absent | P17: 2475 | AD17: Yes | AE17: No | AG17: 1
A18: TNaph.1.3 | B18: μετα το εξυπνισθηναι | C18: μετα του εξυπνισθηναι | G18: Substitution - Form | AD18: Yes | AE18: No | AG18: 1
A19: TNaph.1.6 | B19: ιακωβ και επι των μηρων ραχηλ ετεκε με δια τουτο εκληθην νεφθαλειμ (7) και ηγαπησε με ραχηλ οτι επι των μηρων αυτης εγεννηθην | C19: ιακωβ και επι των μηρων (7) αυτης εγενηθην | F19: Yes | G19: Omission | I19: 15 | J19: 67 | L19: Present | M19: AC | N19: 12 | P19: 2 | AD19: No | AE19: No | AG19: 0
A20: TNaph.1.7 | B20: κατεφιλει | C20: καταφιλει | F20: Yes | G20: Substitution - Form | AD20: No | AE20: No | AG20: 0
A21: TNaph.1.9 | B21: και η ραχηλ | C21: και ραχηλ | G21: Omission | I21: 1 | J21: 1 | K21: Article | L21: NA | P21: 2475 | AD21: Yes | AE21: No | AG21: 1
A22: TNaph.1.11 | B22: παιδισκην αυτου εις γυναικα | C22: παιδισκην αυτου γυναικα | G22: Omission | I22: 1 | J22: 3 | K22: Preposition | L22: Absent | P22: 210 | AD22: Yes | AE22: No | AG22: 1
A23: TNaph.2.4 | B23: ουτω και | C23: ουτως και | G23: Substitution - Form | T23: Disharmonizing | AD23: Yes | AE23: No | AG23: 1
A24: TNaph.2.8 | B24: αισθησεις εν τη κεφαλη και τον τραχηλον συναπτει τη κεφαλη και τριχας | C24: αισθησεις τη κεφαλη και τριχας | G24: Omission | I24: 7 | J24: 32 | L24: Present | M24: AC:BD | N24: 3:12 | AD24: No | AE24: No | AG24: 0
A25: TNaph.2.8 | B25: νεφρους | C25: νεφους | F25: Yes | G25: Substitution - Word | Q25: -1 | R25: 1 | S25: 0 | AD25: Yes | AE25: No | AG25: 1
A26: TNaph.2.10 | B26: ουδε εν σκοτει δυνησεσθε ποιησαι εργα φωτος | C26: ουδε εν σκοτεις ποιειν εργα φωτος | G26: Omission | I26: 1 | J26: 9 | K26: Verb | L26: Absent | P26: 18 | AD26: Yes | AE26: No | AG26: 1
A27: TNaph.3.4 | B27: υμεις δε μη ουτως | C27: υμεις μη ουτως | G27: Omission | I27: 1 | J27: 2 | K27: Conjunction | L27: NA | P27: 171 | AD27: Yes | AE27: No | AG27: 1
A28: TNaph.4.2 | B28: εως αν αναλωση | C28: εως αναλωση | G28: Omission | I28: 1 | J28: 2 | K28: Particle | L28: NA | P28: 10 | AD28: Yes | AE28: No | AG28: 1
A29: TNaph.4.4 | B29: επιλαθωνται κυ και | C29: επιλαθωνται κυριον και | G29: Substitution - Form | AD29: Yes | AE29: No | AG29: 1
A30: TNaph.5.4 | B30: του λευι ως ηλιου | C30: του λευι εκρατησε τον ηλιον ως ηλιου | F30: Yes | G30: Addition | I30: 3 | J30: 16 | L30: Absent | O30: Repetition | P30: 9 | AD30: No | AE30: No | AG30: 0
A31: TNaph.5.6 | B31: θελοντες πιασαι αυτον ουκ ηδυνηθημεν | C31: θελοντες αυτον πιασαι ουκ ηδυνηθημεν | G31: Transposition | AD31: Yes | AE31: No | AG31: 1

Sheet AddOmits_2
A1: Verse Ref | B1: Autograph | C1: Apograph | D1: Exclusion Grounds | E1: Corrector Followed | F1: Apograph Corrected | G1: Basic Type | H1: Phrase Length | I1: Words Length | J1: Letters Length | K1: Speech Part Add/Omitted | L1: Visual Cues | M1: Cue Regions | N1: Cue Length | O1: Duplicate Material | P1: AO Word Frequency | Q1: Freq-per-10000 | R1: SUB Frequency Difference | S1: SUB_Aut_Freq | T1: SUB_Apog_Freq | U1: Harmonization - Context | V1: Parallel Present | W1: Harmonization - Parallel | X1: Singularity | Y1: Secondary | Z1: Minutiae | AA1: Orthographic - General | AB1: Mere Minutiae | AC1: Nonsense | AD1: Review | AE1: Oo.VI.9.8 | AF1: Barocci | AG1: Smith
A2: TLev.3.3 | B2: οι δε εις τον τεταρτον | C2: οι δε εις τεταρτον | G2: Omission | I2: 1 | J2: 3 | K2: Article | L2: Present | M2: BD:CD | N2: 3:3 | P2: 2475 | Q2: 1216.9338 | AE2: Yes | AF2: No | AH2: 1
A3: TLev.3.4 | B3: εν τω ανωτερω | C3: εν ανωτερω | G3: Omission | I3: 1 | J3: 2 | K3: Article | L3: NA | P3: 2475 | Q3: 1216.9338 | AE3: Yes | AF3: No | AH3: 1
A4: TLev.3.9 | B4: επιβλεψη κς | C4: επιβλεψη ο κυριος | G4: Addition | I4: 1 | J4: 1 | K4: Article | L4: NA | P4: 2475 | Q4: 1216.9338 | AE4: Yes | AF4: No | AH4: 1
A5: TLev.18.12 | B5: τεκνοις αυτου του πατειν | C5: τεκνοις αυτου πατειν | G5: Omission | I5: 1 | J5: 3 | K5: Article | L5: Present | M5: AB:AC | N5: 3:3 | P5: 2475 | Q5: 1216.9338 | AE5: Yes | AF5: No | AH5: 1
